Workbook

Sheet 目录
B2: 目 录
C3: 填报日期：2026-5-8
B5: 表1：利润（预算口径） | F5: 表9：职场成本明细表
B7: 表2：外勤人力变动表 | F7: 表10：人力成本明细表
B9: 表3：外勤人力架构表 | F9: 表11：应收账款明细表
B11: 表4：保费分析—公司 | F11: 表12：应收利息明细表
B13: 表5：保费分析—产品 | F13: 表13：其他应付款明细表
B15: 表6：保费分析—君康产品 | F15: 表14：应付佣金明细表
B17: 表7：收入明细表 | F17: 表15：其他应收款明细表
B19: 表8：基本法支出 | F19: 表16：日常行政费用明细

Sheet 利润（预算口径）
A1: 2026年4月管理报表 | Q1: 返回目录
A2: 填报单位：盛唐融信保险代理（北京）有限公司 | H2: =目录!C3 -> 填报日期：2026-5-8 | Q2: 单位：万元
A3: 项目 | B3: 本年预算 | C3: 1月 | D3: 2月 | E3: 3月 | F3: 4月 | G3: 5月 | H3: 6月 | I3: 7月 | J3: 8月 | K3: 9月 | L3: 10月 | M3: 11月 | N3: 12月 | O3: 本年累计 | P3: 预算执行比 | Q3: 去年同期 | R3: 同比
A4: 一、新契约收入 | B4: 410.41874 | C4: =收入明细表!C8 -> 2.691245 | D4: =收入明细表!D8 -> 0.461679 | E4: =收入明细表!E8 -> 0.142642 | F4: =收入明细表!F8 -> 0.040415 | G4: =收入明细表!G8 -> 0 | H4: =收入明细表!H8 -> 0 | I4: =收入明细表!I8 -> 0 | J4: =收入明细表!J8 -> 0 | ... N4: =收入明细表!N8 -> 0 | O4: =SUM(C4:N4) -> 3.335981 | P4: =IFERROR(O4/B4,0) -> 0.0081282375 | Q4: 55.922986 | R4: =(O4-Q4)/Q4 -> -0.94034687
A5: 二、弹性销售成本 | B5: =SUM(B6:B7) -> 293.84259 | C5: =SUM(C6:C7) -> 1.929264 | D5: =SUM(D6:D7) -> -0.067674 | E5: =SUM(E6:E7) -> 0 | F5: =SUM(F6:F7) -> 0.023461 | G5: =SUM(G6:G7) -> 0 | H5: =SUM(H6:H7) -> 0 | I5: =SUM(I6:I7) -> 0 | ... N5: =SUM(N6:N7) -> 0 | O5: =SUM(C5:N5) -> 1.885051 | P5: =IFERROR(O5/B5,0) -> 0.0064151728 | Q5: 42.693734 | R5: =(O5-Q5)/Q5 -> -0.95584713
A6: 1、基本法 | B6: 264.97033 | C6: =基本法支出!B11+基本法支出!B12+基本法支出!B13 -> 1.751664 | D6: =基本法支出!C11+基本法支出!C12+基本法支出!C13 -> -0.067674 | E6: =基本法支出!D11+基本法支出!D12+基本法支出!D13 -> 0 | F6: =基本法支出!E11+基本法支出!E12+基本法支出!E13 -> 0.023462 | G6: =基本法支出!F11+基本法支出!F12+基本法支出!F13 -> 0 | H6: =基本法支出!G11+基本法支出!G12+基本法支出!G13 -> 0 | I6: =基本法支出!H11+基本法支出!H12+基本法支出!H13 -> 0 | J6: =基本法支出!I11+基本法支出!I12+基本法支出!I13 -> 0 | ... N6: =基本法支出!M11+基本法支出!M12+基本法支出!M13 -> 0 | O6: =SUM(C6:N6) -> 1.707452 | P6: =IFERROR(O6/B6,0) -> 0.0064439366 | Q6: 37.168134 | R6: =(O6-Q6)/Q6 -> -0.9540614
A7: 2、方案 | B7: 28.872259 | C7: =基本法支出!B14+基本法支出!B15+基本法支出!B16 -> 0.1776 | D7: =基本法支出!C14+基本法支出!C15+基本法支出!C16 -> 0 | E7: =基本法支出!D14+基本法支出!D15+基本法支出!D16 -> 0 | F7: =基本法支出!E14+基本法支出!E15+基本法支出!E16 -> -1e-06 | G7: =基本法支出!F14+基本法支出!F15+基本法支出!F16 -> 0 | H7: =基本法支出!G14+基本法支出!G15+基本法支出!G16 -> 0 | I7: =基本法支出!H14+基本法支出!H15+基本法支出!H16 -> 0 | J7: =基本法支出!I14+基本法支出!I15+基本法支出!I16 -> 0 | ... N7: =基本法支出!M14+基本法支出!M15+基本法支出!M16 -> 0 | O7: =SUM(C7:N7) -> 0.177599 | P7: =IFERROR(O7/B7,0) -> 0.0061511986 | Q7: 5.5256 | R7: =(O7-Q7)/Q7 -> -0.96785888
A8: 三、新契约毛利 | B8: =B4-B5 -> 116.57615 | C8: =C4-C5 -> 0.761981 | D8: =D4-D5 -> 0.529353 | E8: =E4-E5 -> 0.142642 | F8: =F4-F5 -> 0.016954 | G8: =G4-G5 -> 0 | H8: =H4-H5 -> 0 | I8: =I4-I5 -> 0 | ... N8: =N4-N5 -> 0 | O8: =SUM(C8:N8) -> 1.45093 | P8: =IFERROR(O8/B8,0) -> 0.012446199 | Q8: 13.229252 | R8: =(O8-Q8)/Q8 -> -0.89032411
A9: 四、事业部经营成本 | B9: =SUM(B10:B14) -> 99.434311 | C9: =SUM(C10:C14) -> 8.472683 | D9: =SUM(D10:D14) -> 7.645275 | E9: =SUM(E10:E14) -> 7.306744 | F9: =SUM(F10:F14) -> 7.441265 | G9: =SUM(G10:G14) -> 0 | H9: =SUM(H10:H14) -> 0 | I9: =SUM(I10:I14) -> 0 | ... N9: =SUM(N10:N14) -> 0 | O9: =SUM(C9:N9) -> 30.865967 | P9: =IFERROR(O9/B9,0) -> 0.31041566 | Q9: 19.24405 | R9: =(O9-Q9)/Q9 -> 0.60392262
A10: 1、职场成本 | B10: 9.106746 | C10: =基本法支出!B17 -> 1.194006 | D10: =基本法支出!C17 -> 0.978819 | E10: =基本法支出!D17 -> 0.640288 | F10: =基本法支出!E17 -> 0.614809 | G10: =基本法支出!F17 -> 0 | H10: =基本法支出!G17 -> 0 | I10: =基本法支出!H17 -> 0 | J10: =基本法支出!I17 -> 0 | ... N10: =基本法支出!M17 -> 0 | O10: =SUM(C10:N10) -> 3.427922 | P10: =IFERROR(O10/B10,0) -> 0.37641568 | Q10: 0.529702 | R10: =(O10-Q10)/Q10 -> 5.471416
A11: 2、人力成本 | B11: 86.288744 | C11: =基本法支出!B18 -> 6.921186 | D11: =基本法支出!C18 -> 6.621186 | E11: =基本法支出!D18 -> 6.621186 | F11: =基本法支出!E18 -> 6.781186 | G11: =基本法支出!F18 -> 0 | H11: =基本法支出!G18 -> 0 | I11: =基本法支出!H18 -> 0 | J11: =基本法支出!I18 -> 0 | ... N11: =基本法支出!M18 -> 0 | O11: =SUM(C11:N11) -> 26.944744 | P11: =IFERROR(O11/B11,0) -> 0.31226256 | Q11: 4.731516 | R11: =(O11-Q11)/Q11 -> 4.694738
A12: 3、折旧摊销 | B12: 0.638244 | C12: =基本法支出!B19 -> 0.053187 | D12: =基本法支出!C19 -> 0.04527 | E12: =基本法支出!D19 -> 0.04527 | F12: =基本法支出!E19 -> 0.04527 | G12: =基本法支出!F19 -> 0 | H12: =基本法支出!G19 -> 0 | I12: =基本法支出!H19 -> 0 | J12: =基本法支出!I19 -> 0 | ... N12: =基本法支出!M19 -> 0 | O12: =SUM(C12:N12) -> 0.188997 | P12: =IFERROR(O12/B12,0) -> 0.29612029 | Q12: 13.31 | R12: =(O12-Q12)/Q12 -> -0.98580038
A13: 4、税金及附加 | B13: 3.0826638 | C13: =基本法支出!B27 -> 0.0047640096 | D13: =基本法支出!C27 -> 0 | E13: =基本法支出!D27 -> 0 | F13: =基本法支出!E27 -> 0 | G13: =基本法支出!F27 -> 0 | H13: =基本法支出!G27 -> 0 | I13: =基本法支出!H27 -> 0 | J13: =基本法支出!I27 -> 0 | ... N13: =基本法支出!M27 -> 0 | O13: =SUM(C13:N13) -> 0.0047640096 | P13: =IFERROR(O13/B13,0) -> 0.0015454198 | Q13: 0.122162 | R13: =(O13-Q13)/Q13 -> -0.96100252
A14: 5、营业外支出 | B14: 0.317913 | C14: 0.29954 | O14: =SUM(C14:N14) -> 0.29954 | P14: =IFERROR(O14/B14,0) -> 0.94220746 | Q14: 0.55067 | R14: =(O14-Q14)/Q14 -> -0.45604445
A15: 五、新契约利润 | B15: =B8-B9 -> 17.141841 | C15: =C8-C10-C11-C12-C13-C14 -> -7.710702 | D15: =D8-D10-D11-D12-D13 -> -7.115922 | E15: =E8-E10-E11-E12-E13-E14 -> -7.164102 | F15: =F8-F10-F11-F12-F13 -> -7.424311 | G15: =G8-G10-G11-G12-G13 -> 0 | H15: =H8-H10-H11-H12-H13 -> 0 | I15: =I8-I10-I11-I12-I13 -> 0 | J15: =J8-J10-J11-J12-J13 -> 0 | K15: =K8-K10-K11-K12-K13 -> 0 | L15: =L8-L10-L11-L12-L13 -> 0 | M15: =M8-M10-M11-M12-M13 -> 0 | N15: =N8-N10-N11-N12-N13 -> 0 | O15: =SUM(C15:N15) -> -29.415037 | P15: =IFERROR(O15/B15,0) -> -1.7159789 | Q15: -6.014798 | R15: =(O15-Q15)/Q15 -> 3.8904447
A16: 六、事业部续期毛利 | B16: =B17-B18 -> 8.6879647 | C16: =C17-C18 -> -0.043366 | D16: =D17-D18 -> 1.1838068 | E16: =E17-E18 -> 5.441876 | F16: =F17-F18 -> 3.270583 | G16: =G17-G18 -> 0 | H16: =H17-H18 -> 0 | I16: =I17-I18 -> 0 | ... N16: =N17-N18 -> 0 | O16: =SUM(C16:N16) -> 9.8528998 | P16: =O16/B16 -> 1.1340861 | Q16: 26.224167 | R16: =(O16-Q16)/Q16 -> -0.62428169
A17: 1、续期收入 | B17: 17.729004 | C17: =收入明细表!C13 -> 1.542017 | D17: =收入明细表!D13 -> 3.1820268 | E17: =收入明细表!E13 -> 7.051776 | F17: =收入明细表!F13 -> 4.417705 | G17: =收入明细表!G13 -> 0 | H17: =收入明细表!H13 -> 0 | I17: =收入明细表!I13 -> 0 | J17: =收入明细表!J13 -> 0 | ... N17: =收入明细表!N13 -> 0 | O17: =SUM(C17:N17) -> 16.193525 | P17: =O17/B17 -> 0.91339167 | Q17: 42.284585 | R17: =(O17-Q17)/Q17 -> -0.6170348
A18: 2、续期佣金 | B18: 9.0410396 | C18: =基本法支出!B5+基本法支出!B6+基本法支出!B7 -> 1.585383 | D18: =基本法支出!C5+基本法支出!C6+基本法支出!C7 -> 1.99822 | E18: =基本法支出!D5+基本法支出!D6+基本法支出!D7 -> 1.6099 | F18: =基本法支出!E5+基本法支出!E6+基本法支出!E7 -> 1.147122 | G18: =基本法支出!F5+基本法支出!F6+基本法支出!F7 -> 0 | H18: =基本法支出!G5+基本法支出!G6+基本法支出!G7 -> 0 | I18: =基本法支出!H5+基本法支出!H6+基本法支出!H7 -> 0 | J18: =基本法支出!I5+基本法支出!I6+基本法支出!I7 -> 0 | ... N18: =基本法支出!M5+基本法支出!M6+基本法支出!M7 -> 0 | O18: =SUM(C18:N18) -> 6.340625 | P18: =O18/B18 -> 0.70131592 | Q18: 16.060418 | R18: =(O18-Q18)/Q18 -> -0.60520175
A19: 七、事业部整体利润 | B19: =B15+B16 -> 25.829806 | C19: =C15+C16 -> -7.754068 | D19: =D15+D16 -> -5.9321152 | E19: =E15+E16 -> -1.722226 | F19: =F15+F16 -> -4.153728 | G19: =G15+G16 -> 0 | H19: =H15+H16 -> 0 | I19: =I15+I16 -> 0 | ... O19: =O15+O16 -> -19.562137 | P19: =O19/B19 -> -0.75734744 | Q19: 13.229252 | R19: =(O19-Q19)/Q19 -> -2.4787032
A20: 八、存续续期毛利 | B20: =B21-B22-B23 -> 255.18724 | C20: =C21-C22 -> 28.387371 | D20: =D21-D22 -> 16.216628 | E20: =E21-E22-E23 -> 22.739144 | F20: =F21-F22 -> 18.993742 | G20: =G21-G22 -> 0 | H20: =H21-H22-H23 -> 0 | I20: =I21-I22-I23 -> 0 | J20: =J21-J22-J23 -> 0 | K20: =K21-K22-K23 -> 0 | L20: =L21-L22-L23 -> 0 | M20: =M21-M22-M23 -> 0 | N20: =N21-N22 -> 0 | O20: =SUM(C20:N20) -> 86.336885 | P20: =IFERROR(O20/B20,0) -> 0.3383276 | Q20: 49.60815 | R20: =(O20-Q20)/Q20 -> 0.74037705
A21: 1.续期收入 | B21: 327.21419 | C21: =收入明细表!C18 -> 28.387371 | D21: =收入明细表!D18 -> 16.038658 | E21: =收入明细表!E18+E23 -> 24.480537 | F21: =收入明细表!F18 -> 18.993742 | G21: =收入明细表!G18 -> 0 | H21: =收入明细表!H18+H23 -> 0 | I21: =收入明细表!I18+I23 -> 0 | J21: =收入明细表!J18+J23 -> 0 | K21: =收入明细表!K18+K23 -> 0 | L21: =收入明细表!L18+L23 -> 0 | M21: =收入明细表!M18+M23 -> 0 | N21: =收入明细表!N18+N23 -> 0 | O21: =SUM(C21:N21) -> 87.900308 | P21: =IFERROR(O21/B21,0) -> 0.26863232 | Q21: 50.648232 | R21: =(O21-Q21)/Q21 -> 0.73550597
A22: 2.续期佣金 | D22: =基本法支出!C4 -> -0.17797 | O22: =SUM(C22:N22) -> -0.17797 | P22: =IFERROR(O22/B22,0) -> 0 | R22: =(O22-Q22)/Q22 -> #DIV/0!
A23: 3.退保损失 | B23: 72.026951 | E23: =收入明细表!E23 -> 1.741393 | G23: =基本法支出!F4 -> 0 | H23: =收入明细表!H23 -> 0 | I23: =收入明细表!I23 -> 0 | J23: =收入明细表!J23 -> 0 | K23: =收入明细表!K23 -> 0 | L23: =收入明细表!L23 -> 0 | M23: =收入明细表!M23 -> 0 | N23: =收入明细表!N23 -> 0 | O23: =SUM(C23:N23) -> 1.741393 | P23: =IFERROR(O23/B23,0) -> 0.024176964 | R23: =(O23-Q23)/Q23 -> #DIV/0!
A24: 其中：复效利息 | B24: 0.883575 | O24: =SUM(C24:N24) -> 0 | R24: =(O24-Q24)/Q24 -> #DIV/0!
A25: 九、管理费用 | B25: =SUM(B26:B29) -> 292.18087 | C25: =SUM(C26:C29) -> 22.47453 | D25: =SUM(D26:D29) -> 20.586543 | E25: =SUM(E26:E29) -> 20.812519 | F25: =SUM(F26:F29) -> 20.913502 | G25: =SUM(G26:G29) -> 0 | H25: =SUM(H26:H29) -> 0 | I25: =SUM(I26:I29) -> 0 | ... N25: =SUM(N26:N29) -> 0 | O25: =SUM(C25:N25) -> 84.787094 | P25: =IFERROR(O25/B25,0) -> 0.29018701 | Q25: 41.321634 | R25: =(Q25-O25)/Q25 -> -1.0518814
A26: 1.日常经营成本 | B26: 29.618318 | C26: =日常行政费用明细!D22 -> 1.062829 | D26: =日常行政费用明细!E22 -> 0.326128 | E26: =日常行政费用明细!F22 -> 0.263238 | F26: =日常行政费用明细!G22 -> 0.083796 | G26: =日常行政费用明细!H22 -> 0 | H26: =日常行政费用明细!I22 -> 0 | I26: =日常行政费用明细!J22 -> 0 | J26: =日常行政费用明细!K22 -> 0 | ... N26: =日常行政费用明细!O22 -> 0 | O26: =SUM(C26:N26) -> 1.735991 | P26: =IFERROR(O26/B26,0) -> 0.058612072 | Q26: -0.341326 | R26: =(Q26-O26)/Q26 -> 6.0860204
A27: 2.职场成本 | B27: 34.89 | C27: =职场成本!B5 -> 2.909079 | D27: =职场成本!C5 -> 2.627793 | E27: =职场成本!D5 -> 2.996659 | F27: =职场成本!E5 -> 2.777084 | G27: =职场成本!F5 -> 0 | H27: =职场成本!G5 -> 0 | I27: =职场成本!H5 -> 0 | J27: =职场成本!I5 -> 0 | ... N27: =职场成本!M5 -> 0 | O27: =SUM(C27:N27) -> 11.310615 | P27: =IFERROR(O27/B27,0) -> 0.32417928 | Q27: 5.855436 | R27: =(Q27-O27)/Q27 -> -0.93164352
A28: 3.人力成本 | B28: 206.77742 | C28: =人力成本!B11 -> 16.761363 | D28: =人力成本!C11 -> 15.891363 | E28: =人力成本!D11 -> 15.811363 | F28: =人力成本!E11 -> 16.311363 | G28: =人力成本!F11 -> 0 | H28: =人力成本!G11 -> 0 | I28: =人力成本!H11 -> 0 | J28: =人力成本!I11 -> 0 | ... N28: =人力成本!M11 -> 0 | O28: =SUM(C28:N28) -> 64.775452 | P28: =IFERROR(O28/B28,0) -> 0.31326172 | Q28: 32.304962 | R28: =(Q28-O28)/Q28 -> -1.0051239
A29: 4.折旧摊销 | B29: 20.895132 | C29: =1.72956+0.011699 -> 1.741259 | D29: =1.72956+0.011699 -> 1.741259 | E29: =1.72956+0.011699 -> 1.741259 | F29: =1.72956+0.011699 -> 1.741259 | O29: =SUM(C29:N29) -> 6.965036 | P29: =IFERROR(O29/B29,0) -> 0.33333295 | Q29: 3.502562 | R29: =(Q29-O29)/Q29 -> -0.98855466
A30: 十、税金及附加 | B30: 1.9195281 | C30: =基本法支出!B30+0.001 -> 0.23390299 | D30: 0.227859 | E30: 0.15366 | F30: 0.19 | O30: =SUM(C30:N30) -> 0.80542199 | P30: =IFERROR(O30/B30,0) -> 0.41959374 | Q30: 0.289314 | R30: =(Q30-O30)/Q30 -> -1.7839026
A31: 十一、利息收入 | B31: 71.820352 | C31: 6.743865 | D31: 6.01989 | E31: 6.631518 | F31: 6.045122 | O31: =SUM(C31:N31) -> 25.440395 | P31: =IFERROR(O31/B31,0) -> 0.35422264 | Q31: 14.897526 | R31: =(Q31-O31)/Q31 -> -0.70769261
A32: 十二、其他收益 | D32: 0.596874 | O32: =SUM(C32:N32) -> 0.596874 | P32: =IFERROR(O32/B32,0) -> 0 | Q32: 0 | R32: =(Q32-O32)/Q32 -> #DIV/0!
A33: 十三、营业外支出 | E33: 0.012655 | F33: -1.659137 | O33: =SUM(C33:N33) -> -1.646482
A34: 十四、企业所得税 | B34: 15.239659 | E34: 1.856303 | O34: =SUM(C34:N34) -> 1.856303 | P34: =IFERROR(O34/B34,0) -> 0.12180738 | Q34: 0 | R34: =(Q34-O34)/Q34 -> #DIV/0!
A35: 十五、净利润 | B35: =B19+B20-B25-B30+B31-B32-B34 -> 43.497337 | C35: =C15+C16+C20-C25-C30+C31+C32-C34 -> 4.668735 | D35: =D15+D16+D20-D25-D30+D31+D32-D34 -> -3.913125 | E35: =E15+E16+E20-E24-E25-E30+E31-E32-E33-E34 -> 4.813299 | F35: =F15+F16+F20-F25-F30+F31-F32-F33-F34 -> 1.440771 | G35: =G15+G16+G20-G25-G30+G31-G32-G34 -> 0 | H35: =H15+H16+H20-H25-H30+H31-H32-H34 -> 0 | I35: =I15+I16+I20-I25-I30+I31-I32-I34 -> 0 | J35: =J15+J16+J20-J25-J30+J31-J32-J34 -> 0 | K35: =K15+K16+K20-K24-K25-K30+K31-K32-K34 -> 0 | L35: =L15+L16+L20-L25-L30+L31-L32-L34 -> 0 | M35: =M15+M16+M20-M25-M30+M31-M32-M34 -> 0 | N35: =N15+N16+N20-N25-N30+N31-N32-N34 -> 0 | O35: =O15+O16+O20-O24-O25-O30+O31+O32-O33-O34 -> 7.00968 | P35: =IFERROR(O35/B35,0) -> 0.16115193 | Q35: 43.104097 | R35: =(Q35-O35)/Q35 -> 0.83737787
A36: 规模保费 | B36: 862 | C36: ='保费分析--产品'!B18 -> 7.1105 | D36: ='保费分析--产品'!C18 -> 0 | E36: ='保费分析--产品'!D18 -> 0.3247 | F36: ='保费分析--产品'!E18 -> 0 | G36: ='保费分析--产品'!F18 -> 0 | H36: ='保费分析--产品'!G18 -> 0 | I36: ='保费分析--产品'!H18 -> 0 | J36: ='保费分析--产品'!I18 -> 0 | ... N36: ='保费分析--产品'!M18 -> 0 | O36: =SUM(C36:N36) -> 7.4352 | P36: =IFERROR(O36/B36,0) -> 0.008625522 | Q36: 198.742 | R36: =(Q36-O36)/Q36 -> 0.96258868
A37: 新契约标准保费 | B37: 436.224 | C37: ='保费分析-公司'!B16 -> 5.53326 | D37: ='保费分析-公司'!C16 -> 0 | E37: ='保费分析-公司'!D16 -> 0.0257 | F37: ='保费分析-公司'!E16 -> 0 | G37: ='保费分析-公司'!F16 -> 0 | H37: ='保费分析-公司'!G16 -> 0 | I37: ='保费分析-公司'!H16 -> 0 | J37: ='保费分析-公司'!I16 -> 0 | ... N37: ='保费分析-公司'!M16 -> 0 | O37: =SUM(C37:N37) -> 5.55896 | P37: =IFERROR(O37/B37,0) -> 0.012743361 | Q37: 99.8105 | R37: =(Q37-O37)/Q37 -> 0.94430486
A38: 新契约FYB | B38: 164.896 | C38: ='保费分析-公司'!B15 -> 1.216575 | D38: ='保费分析-公司'!C15 -> 0 | E38: ='保费分析-公司'!D15 -> 0.0321 | F38: ='保费分析-公司'!E15 -> 0 | G38: ='保费分析-公司'!F15 -> 0 | H38: ='保费分析-公司'!G15 -> 0 | I38: ='保费分析-公司'!H15 -> 0 | J38: ='保费分析-公司'!I15 -> 0 | ... N38: ='保费分析-公司'!M15 -> 0 | O38: =SUM(C38:N38) -> 1.248675 | P38: =IFERROR(O38/B38,0) -> 0.0075725002 | Q38: 26.7293 | R38: =(Q38-O38)/Q38 -> 0.95328441
A39: 收入小计 | B39: =B40+B31 -> 827.18229 | C39: =C40+C31 -> 39.364498 | D39: =D40+D31 -> 25.702254 | E39: =E40+E31 -> 38.306473 | F39: =F40+F31 -> 29.496984 | G39: =G40+G31 -> 0 | H39: =H40+H31 -> 0 | I39: =I40+I31 -> 0 | ... O39: =O40+O31 -> 132.87021 | P39: =IFERROR(O39/B39,0) -> 0.1606299 | R39: =(Q39-O39)/Q39 -> #DIV/0!
A40: 营业收入 | B40: =B41+B43+B44 -> 755.36194 | C40: =C41+C42 -> 32.620633 | D40: =D41+D42 -> 19.682364 | E40: =E41+E42 -> 31.674955 | F40: =F41+F42 -> 23.451862 | G40: =G41+G42 -> 0 | H40: =H41+H42 -> 0 | I40: =I41+I42 -> 0 | J40: =J41+J42 -> 0 | ... O40: =O41+O42 -> 107.42981 | P40: =IFERROR(O40/B40,0) -> 0.14222296 | R40: =(Q40-O40)/Q40 -> #DIV/0!
...

Sheet 13个月续期保费
A1: 13个月续期保费分析表 | U1: 返回目录
A2: 填报单位：盛唐融信保险代理（北京）有限公司 | K2: =目录!C3 -> 填报日期：2026-5-8 | U2: 单位：万元
A3: 月份 | B3: 应收保费 | C3: 退保 | D3: 实收 | R3: 实收 合计 | S3: 继续率 | T3: 未收保费 | U3: 预期收回 | V3: 预计继续率
D4: 11月 | E4: 12月 | F4: 1月 | G4: 2月 | H4: 3月 | I4: 4月 | J4: 5月 | K4: 6月 | L4: 7月 | M4: 8月 | N4: 9月 | O4: 10月 | P4: 11月 | Q4: 12月
A5: 2019.11 | B5: 1531.52 | C5: 5.58 | D5: 1016.45 | E5: 242.46 | F5: 125.84 | R5: 1384.75 | S5: =IFERROR(R5/B5,0) -> 0.9041671 | T5: =B5-C5-SUM(D5:F5) -> 141.19 | V5: =IFERROR((U5+R5)/B5,0) -> 0.9041671
A6: 2019.12 | B6: 980.69 | C6: 29.5 | E6: 612.14 | F6: 162.78 | G6: 67.52 | R6: =E6+F6+G6 -> 842.44 | S6: =IFERROR(R6/B6,0) -> 0.85902783 | T6: =B6-C6-SUM(E6:G6) -> 108.75 | V6: =IFERROR((U6+R6)/B6,0) -> 0.85902783
A7: 1月 | B7: 1453.5 | C7: 3.3 | F7: 1003.29 | G7: 187.14 | H7: 165.44 | R7: =F7+G7+H7 -> 1355.87 | S7: =IFERROR(R7/B7,0) -> 0.9328311 | T7: =B7-C7-SUM(F7:H7) -> 94.33 | U7: =ROUND(T7*0.8,2) -> 75.46 | V7: =IFERROR((U7+R7)/B7,0) -> 0.98474716
A8: 2月 | B8: 584.36 | G8: 342.47 | H8: 129.39 | R8: =G8+H8+I8 -> 471.86 | S8: =IFERROR(R8/B8,0) -> 0.80748169 | T8: =B8-C8-SUM(G8:H8) -> 112.5 | U8: =ROUND(T8*0.8,2) -> 90 | V8: =IFERROR((U8+R8)/B8,0) -> 0.96149634
A9: 3月 | B9: 1110.71 | H9: 649.81 | R9: =H9 -> 649.81 | S9: =IFERROR(R9/B9,0) -> 0.5850402 | T9: =B9-C9-SUM(F9:J9) -> 460.9 | U9: =ROUND(T9*0.8,2) -> 368.72 | V9: =IFERROR((U9+R9)/B9,0) -> 0.91700804
A10: 4月
A11: 5月
A12: 6月
A13: 7月
A14: 8月
A15: 9月
A16: 10月
A17: 11月
A18: 12月
A19: 合计 | B19: =SUM(B7:B18) -> 3148.57 | C19: =SUM(C5:C18) -> 38.38 | D19: =SUM(D5:D18) -> 1016.45 | E19: =SUM(E5:E18) -> 854.6 | F19: =SUM(F5:F18) -> 1291.91 | G19: =SUM(G5:G18) -> 597.13 | H19: =SUM(H5:H18) -> 944.64 | I19: =SUM(I5:I18) -> 0 | J19: =SUM(J5:J18) -> 0 | ... R19: =SUM(R5:R18) -> 4704.73

Sheet 25个月续期保费
A1: 25个月续期保费分析表 | U1: 返回目录
A2: 填报单位：盛唐融信保险代理（北京）有限公司 | M2: =目录!C3 -> 填报日期：2026-5-8 | U2: 单位：万元
A3: 月份 | B3: 应收保费 | C3: 退保 | D3: 实收 | R3: 实收 合计 | S3: 继续率 | T3: 未收保费 | U3: 预期收回 | V3: 预计继续率
D4: 2019.11 | E4: 2019.12 | F4: 1月 | G4: 2月 | H4: 3月 | I4: 4月 | J4: 5月 | K4: 6月 | L4: 7月 | M4: 8月 | N4: 9月 | O4: 10月 | P4: 11月 | Q4: 12月
A5: 2019.11 | B5: 395.73 | C5: 5.58 | D5: 186.5 | E5: 69.48 | F5: 43.83 | R5: =D5+E5+F5 -> 299.81 | S5: =IFERROR(R5/B5,0) -> 0.75761251 | T5: =B5-C5-SUM(D5:F5) -> 90.34 | V5: =IFERROR((U5+R5)/B5,0) -> 0.75761251
A6: 2019.12 | B6: 830 | C6: 29.5 | E6: 271.93 | F6: 81.7 | G6: 64.94 | R6: =E6+F6+G6 -> 418.57 | S6: =IFERROR(R6/B6,0) -> 0.5043012 | T6: =B6-C6-SUM(E6:G6) -> 381.93 | V6: =IFERROR((U6+R6)/B6,0) -> 0.5043012
A7: 1月 | B7: 1627.59 | C7: 0 | F7: 862.75 | G7: 262.88 | H7: 203.54 | R7: =F7+G7+H7 -> 1329.17 | S7: =IFERROR(R7/B7,0) -> 0.81664916 | T7: =B7-C7-SUM(F7:H7) -> 298.42 | U7: =ROUND(T7*0.8,2) -> 238.74 | V7: =IFERROR((U7+R7)/B7,0) -> 0.96333229
A8: 2月 | B8: 360.16 | G8: 223.59 | H8: 95.86 | R8: =G8+H8 -> 319.45 | S8: =IFERROR(R8/B8,0) -> 0.8869669 | T8: =B8-C8-SUM(G8:H8) -> 40.71 | U8: =ROUND(T8*0.8,2) -> 32.57 | V8: =IFERROR((U8+R8)/B8,0) -> 0.97739893
A9: 3月 | B9: 1152.71 | H9: 647.93 | R9: =H9 -> 647.93 | S9: =IFERROR(R9/B9,0) -> 0.56209281 | T9: =B9-C9-SUM(H9:H9) -> 504.78 | U9: =ROUND(T9*0.8,2) -> 403.82 | V9: =IFERROR((U9+R9)/B9,0) -> 0.91241509
A10: 4月
A11: 5月
A12: 6月
A13: 7月
A14: 8月
A15: 9月
A16: 10月
A17: 11月
A18: 12月
A19: 合计 | B19: =SUM(B7:B18) -> 3140.46 | C19: =SUM(C5:C18) -> 35.08 | D19: =SUM(D5:D18) -> 186.5 | E19: =SUM(E5:E18) -> 341.41 | F19: =SUM(F5:F18) -> 988.28 | G19: =SUM(G5:G18) -> 551.41 | H19: =SUM(H5:H18) -> 947.33 | I19: =SUM(I5:I18) -> 0 | J19: =SUM(J5:J18) -> 0 | ... R19: =SUM(R5:R18) -> 3014.93 | T19: =SUM(T5:T18) -> 1316.18

Sheet 37个月续期保费
A1: 37个月续期保费分析表 | S1: 返回目录
A2: 填报单位：盛唐融信保险代理（北京）有限公司 | K2: =目录!C3 -> 填报日期：2026-5-8 | S2: 单位：万元
A3: 月份 | B3: 应收保费 | C3: 退保 | P3: 实收 合计 | Q3: 继续率 | R3: 未收保费 | S3: 预期收回 | T3: 预计继续率
D4: 1月 | E4: 2月 | F4: 3月 | G4: 4月 | H4: 5月 | I4: 6月 | J4: 7月 | K4: 8月 | L4: 9月 | M4: 10月 | N4: 11月 | O4: 12月
A5: 1月 | B5: 19.36 | D5: 14.42 | E5: 1 | F5: 2.83 | P5: =D5+E5+F5 -> 18.25 | Q5: =IFERROR(P5/B5,0) -> 0.94266529 | R5: =B5-C5-SUM(D5:F5) -> 1.11 | S5: =ROUND(R5*0.8,2) -> 0.89 | T5: =IFERROR((R5+P5)/B5,0) -> 1
A6: 2月 | B6: 31.37 | E6: 20.72 | F6: 4.91 | P6: =E6+F6 -> 25.63 | Q6: =IFERROR(P6/B6,0) -> 0.81702263 | R6: =B6-C6-SUM(D6:F6) -> 5.74 | S6: =ROUND(R6*0.8,2) -> 4.59 | T6: =IFERROR((S6+P6)/B6,0) -> 0.96334077
A7: 3月 | B7: 561.8 | F7: 296.66 | P7: =F7 -> 296.66 | Q7: =IFERROR(P7/B7,0) -> 0.52805269 | R7: =B7-C7-SUM(D7:F7) -> 265.14 | S7: =ROUND(R7*0.8,2) -> 212.11 | T7: =IFERROR((S7+P7)/B7,0) -> 0.90560698
A8: 4月
A9: 5月
A10: 6月
A11: 7月
A12: 8月
A13: 9月
A14: 10月
A15: 11月
A16: 12月
A17: 合计 | B17: =SUM(B5:B16) -> 612.53 | C17: =SUM(C5:C16) -> 0 | D17: =SUM(D5:D16) -> 14.42 | E17: =SUM(E5:E16) -> 21.72 | F17: =SUM(F5:F16) -> 304.4 | G17: =SUM(G5:G16) -> 0 | H17: =SUM(H5:H16) -> 0 | I17: =SUM(I5:I16) -> 0 | ... S17: =SUM(S5:S16) -> 217.59

Sheet Sheet1
C1: 1 | D1: 2 | E1: 3
B2: 会计科目折旧 | C2: 17295.6 | D2: 17295.6 | E2: 1171.28
B3: 会计科目摊销 | C3: 741.58 | D3: 854.74 | E3: 17295.6
B4: 低值易耗摊销 | C4: 1986.49 | D4: 7637.79 | E4: 2214
C5: =SUM(C2:C4) -> 20023.67 | D5: =SUM(D2:D4) -> 25788.13 | E5: =SUM(E2:E4) -> 20680.88

Sheet 外勤人力变动表
A1: 新单外勤人力分析表 | N1: 返回目录
A2: 填报单位：盛唐融信保险代理（北京）有限公司 | H2: =目录!C3 -> 填报日期：2026-5-8 | L2: 单位：人/万元
A3: 项目 | C3: 1月 | D3: 2月 | E3: 3月 | F3: 4月 | G3: 5月 | H3: 6月 | I3: 7月 | J3: 8月 | K3: 9月 | L3: 10月 | M3: 11月 | N3: 12月 | O3: 合计
A4: 在职人力 | B4: 新增人力 | E4: 1 | F4: 1 | O4: =SUM(C4:N4) -> 2
B5: 离职人力 | E5: 2 | O5: =SUM(C5:N5) -> 2
B6: 实际人力 | C6: 97 | D6: =C6+D4-D5 -> 97 | E6: =D6+E4-E5 -> 96 | F6: =E6+F4-F5 -> 97 | G6: =F6+G4-G5 -> 97 | H6: =G6+H4-H5 -> 97 | I6: =H6+I4-I5 -> 97 | J6: =I6+J4-J5 -> 97 | K6: =J6+K4-K5 -> 97 | ... N6: =M6+N4-N5 -> 97
A7: 开单人力 | C7: 2 | E7: 2 | O7: =SUM(C7:N7) -> 4
A8: 绩优人力 | B8: 万元FYB | C8: 2 | O8: =SUM(C8:N8) -> 2
B9: 3万元FYB | O9: =SUM(C9:N9) -> 0
B10: 6万元FYB | O10: =SUM(C10:N10) -> 0
A11: 规模保费 | C11: 7.1105 | E11: 0.2142 | O11: =SUM(C11:N11) -> 7.3247
A12: 期交规模保费 | C12: 7 | O12: =SUM(C12:N12) -> 7
A13: 人均产能 | C13: =IFERROR(C11/C7,0) -> 3.55525 | D13: {=IFERROR(D12/D7,0)} -> 0 | E13: {=IFERROR(E12/E7,0)} -> 0 | F13: {=IFERROR(F12/F7,0)} -> 0 | G13: {=IFERROR(G12/G7,0)} -> 0 | H13: {=IFERROR(H12/H7,0)} -> 0 | I13: {=IFERROR(I12/I7,0)} -> 0 | J13: {=IFERROR(J12/J7,0)} -> 0 | K13: {=IFERROR(K12/K7,0)} -> 0 | ... N13: {=IFERROR(N12/N7,0)} -> 0 | O13: =IFERROR(O11/O7,0) -> 1.831175
A14: 保单件数 | C14: 6 | E14: 2 | O14: =SUM(C14:N14) -> 8
A15: 件均保费 | C15: {=IFERROR(C12/C14,0)} -> 1.1666667 | D15: {=IFERROR(D12/D14,0)} -> 0 | E15: {=IFERROR(E12/E14,0)} -> 0 | F15: {=IFERROR(F12/F14,0)} -> 0 | G15: {=IFERROR(G12/G14,0)} -> 0 | H15: {=IFERROR(H12/H14,0)} -> 0 | I15: {=IFERROR(I12/I14,0)} -> 0 | J15: {=IFERROR(J12/J14,0)} -> 0 | ... O15: {=IFERROR(O12/O14,0)} -> 0.875

Sheet 外勤人力架构表
A1: 新单外勤人力架构表 | E1: 返回目录
A2: 填报单位：盛唐融信保险代理（北京）有限公司 | E2: 单位：人
A3: 机构 | B3: 营销服务区 | C3: 业务总监 | D3: 业务经理 | E3: 业务专员 | F3: 合计
A4: 房山 | B4: 陈大庆部 | C4: 1 | D4: 3 | E4: 4 | F4: =SUM(C4:E4) -> 8
A5: 怀柔 | B5: 孙建建部 | C5: 1 | D5: 6 | E5: 9 | F5: =SUM(C5:E5) -> 16
A6: 房山 | B6: 李书强部 | C6: 1 | D6: 2 | E6: 3 | F6: =SUM(C6:E6) -> 6
A7: 平谷 | B7: 戚海娇部 | C7: 1 | D7: 12 | E7: 54 | F7: =SUM(C7:E7) -> 67
B8: 合计 | C8: =SUM(C4:C7) -> 4 | D8: =SUM(D4:D7) -> 23 | E8: =SUM(E4:E7) -> 70 | F8: =SUM(C8:E8) -> 97

Sheet 保费分析-公司
A1: 新单保费分析表--保险公司 | P1: 返回目录
A2: 填报单位：盛唐融信保险代理（北京）有限公司 | I2: =目录!C3 -> 填报日期：2026-5-8 | S2: 单位：万元
A3: 公司 | B3: 规模保费 | O3: 累计标保 | P3: 累计FYB | Q3: 规保占比 | R3: 标保占比 | S3: FYB占比
B4: 1月 | C4: 2月 | D4: 3月 | E4: 4月 | F4: 5月 | G4: 6月 | H4: 7月 | I4: 8月 | J4: 9月 | K4: 10月 | L4: 11月 | M4: 12月 | N4: 累计
A5: 富泽人寿 | N5: =SUBTOTAL(9,B5:M5) -> 0 | Q5: =N5/$N$13 -> 0 | R5: {=IFERROR(O5/$O$13,0)} -> 0 | S5: {=IFERROR(P5/$O$13,0)} -> 0
A6: 信泰人寿 | N6: =SUBTOTAL(9,B6:M6) -> 0 | Q6: =N6/$N$13 -> 0 | R6: {=IFERROR(O6/$O$13,0)} -> 0 | S6: {=IFERROR(P6/$O$13,0)} -> 0
A7: 复星联合 | B7: 7 | N7: =SUBTOTAL(9,B7:M7) -> 7 | O7: 5.52 | P7: 1.2 | Q7: =N7/$N$13 -> 0.95573578 | R7: =IFERROR(O7/$O$13,0) -> 0.99300221 | S7: {=IFERROR(P7/$O$13,0)} -> 0.21587005
A8: 复星保德信 | N8: =SUBTOTAL(9,B8:M8) -> 0 | Q8: =N8/$N$13 -> 0 | R8: {=IFERROR(O8/$O$13,0)} -> 0 | S8: {=IFERROR(P8/$O$13,0)} -> 0
A9: 富德生命人寿 | N9: =SUBTOTAL(9,B9:M9) -> 0 | Q9: =N9/$N$13 -> 0 | R9: {=IFERROR(O9/$O$13,0)} -> 0 | S9: {=IFERROR(P9/$O$13,0)} -> 0
A10: 爱心人寿 | N10: =SUBTOTAL(9,B10:M10) -> 0 | R10: {=IFERROR(O10/$O$13,0)} -> 0 | S10: {=IFERROR(P10/$O$13,0)} -> 0
A11: 中汇人寿 | B11: 0.11 | D11: 0.2142 | N11: =SUBTOTAL(9,B11:M11) -> 0.3242 | O11: 0.0389 | P11: 0.0487 | Q11: =N11/$N$13 -> 0.04426422 | R11: {=IFERROR(O11/$O$13,0)} -> 0.0069977873 | S11: {=IFERROR(P11/$O$13,0)} -> 0.008760726
A12: 安盛天平 | N12: =SUBTOTAL(9,B12:M12) -> 0 | R12: {=IFERROR(O12/$O$13,0)} -> 0 | S12: {=IFERROR(P12/$O$13,0)} -> 0
A13: 合计 | B13: =SUBTOTAL(9,B5:B12) -> 7.11 | C13: =SUBTOTAL(9,C5:C12) -> 0 | D13: =SUBTOTAL(9,D5:D12) -> 0.2142 | E13: =SUBTOTAL(9,E5:E12) -> 0 | F13: =SUBTOTAL(9,F5:F12) -> 0 | G13: =SUBTOTAL(9,G5:G12) -> 0 | H13: =SUBTOTAL(9,H5:H12) -> 0 | I13: =SUBTOTAL(9,I5:I12) -> 0 | ... M13: =SUBTOTAL(9,M5:M12) -> 0 | N13: =SUM(N5:N12) -> 7.3242 | O13: =SUBTOTAL(9,O5:O12) -> 5.5589 | P13: =SUBTOTAL(9,P5:P12) -> 1.2487 | Q13: =SUM(Q5:Q11) -> 1 | R13: {=IFERROR(O13/$O$13,0)} -> 1 | S13: {=IFERROR(P13/$O$13,0)} -> 0.22463077
A14: 君康占比 | B14: {=IFERROR(B5/B13,0)} -> 0 | C14: {=IFERROR(C5/C13,0)} -> 0 | D14: {=IFERROR(D5/D13,0)} -> 0 | E14: {=IFERROR(E5/E13,0)} -> 0 | F14: {=IFERROR(F5/F13,0)} -> 0 | G14: {=IFERROR(G5/G13,0)} -> 0 | H14: {=IFERROR(H5/H13,0)} -> 0 | I14: {=IFERROR(I5/I13,0)} -> 0 | ... O14: {=IFERROR(O5/O13,0)} -> 0 | P14: =IFERROR(P5/P13,0) -> 0
A15: 盛唐FYB | B15: 1.216575 | D15: 0.0321 | N15: =SUM(B15:M15) -> 1.248675
A16: 君康标 | B16: 5.53326 | D16: 0.0257 | N16: =SUM(B16:M16) -> 5.55896
A44: 公司 | B44: 实际规模保费
B45: 1月 | C45: 2月 | D45: 3月 | E45: 4月 | F45: 5月 | G45: 6月 | H45: 7月 | I45: 8月 | J45: 9月 | K45: 10月 | L45: 11月 | M45: 12月 | N45: 累计
A46: 君康人寿 | I46: 740000 | J46: 520000 | K46: 165000 | L46: 706000 | M46: 3240000 | N46: =SUBTOTAL(9,B46:M46) -> 5371000
A47: 标准保费 | I47: 296000 | J47: 208000 | K47: 54000 | L47: 236026.9
A48: 佣金 | I48: 303760 | J48: 206360 | K48: 50159.1 | L48: 231551.64
J52: =(I46+J46)*0.14 -> 176400 | K52: ='保费分析--产品'!L5*0.02 -> 0
K53: =('保费分析--产品'!K6+'保费分析--产品'!L6)*0.1 -> 0
K54: ='保费分析--产品'!L7*0.12 -> 0
K55: =('保费分析--产品'!K8+'保费分析--产品'!L8)*0.14 -> 0
K56: =4.6*0.14 -> 0.644
K57: =SUM(K52:K56) -> 0.644

Sheet 保费分析--产品
A1: 新单保费分析表--产品结构 | P1: 返回目录
A2: 填报单位：盛唐融信保险代理（北京）有限公司 | I2: =目录!C3 -> 填报日期：2026-5-8 | T2: 单位：万元
A3: 险种 | B3: 规模保费 | O3: 累计标保 | P3: 累计FYB | Q3: 规保占比 | R3: 标保占比 | S3: 标保占比
B4: 1月 | C4: 2月 | D4: 3月 | E4: 4月 | F4: 5月 | G4: 6月 | H4: 7月 | I4: 8月 | J4: 9月 | K4: 10月 | L4: 11月 | M4: 12月 | N4: 累计
A5: 趸交 | B5: 0.1105 | D5: 0.3247 | N5: =SUM(B5:M5) -> 0.4352 | O5: 0.0389 | P5: 0.0487 | Q5: {=IFERROR(N5/$N$18,0)} -> 0.058532386 | R5: {=IFERROR(O5/$O$18,0)} -> 0.0069977873 | S5: {=IFERROR(P5/$P$18,0)} -> 0.039000561
A6: 3年期寿险 | N6: =SUM(B6:M6) -> 0 | Q6: {=IFERROR(N6/$N$18,0)} -> 0 | R6: {=IFERROR(O6/$O$18,0)} -> 0 | S6: {=IFERROR(P6/$P$18,0)} -> 0
A7: 5年期寿险 | N7: =SUM(B7:M7) -> 0 | Q7: {=IFERROR(N7/$N$18,0)} -> 0 | R7: {=IFERROR(O7/$O$18,0)} -> 0 | S7: {=IFERROR(P7/$P$18,0)} -> 0
A8: 6年期寿险 | B8: 6 | N8: =SUM(B8:M8) -> 6 | O8: 4.32 | P8: 0.9 | Q8: {=IFERROR(N8/$N$18,0)} -> 0.80697224 | R8: {=IFERROR(O8/$O$18,0)} -> 0.77713217 | S8: {=IFERROR(P8/$P$18,0)} -> 0.72074958
A9: 8年期寿险 | N9: =SUM(B9:M9) -> 0 | Q9: {=IFERROR(N9/$N$18,0)} -> 0 | R9: {=IFERROR(O9/$O$18,0)} -> 0 | S9: {=IFERROR(P9/$P$18,0)} -> 0
A10: 10年期寿险 | B10: 1 | N10: =SUM(B10:M10) -> 1 | O10: 1.2 | P10: 0.3 | Q10: {=IFERROR(N10/$N$18,0)} -> 0.13449537 | R10: {=IFERROR(O10/$O$18,0)} -> 0.21587005 | S10: {=IFERROR(P10/$P$18,0)} -> 0.24024986
A11: 富德生命14年期 | N11: =SUM(B11:M11) -> 0 | Q11: {=IFERROR(N11/$N$18,0)} -> 0 | R11: {=IFERROR(O11/$O$18,0)} -> 0 | S11: {=IFERROR(P11/$P$18,0)} -> 0
A12: 复星联合康乐一生15年期产品 | N12: =SUM(B12:M12) -> 0 | Q12: {=IFERROR(N12/$N$18,0)} -> 0 | R12: {=IFERROR(O12/$O$18,0)} -> 0 | S12: {=IFERROR(P12/$P$18,0)} -> 0
A13: 18年期 | N13: =SUM(B13:M13) -> 0 | Q13: {=IFERROR(N13/$N$18,0)} -> 0 | R13: {=IFERROR(O13/$O$18,0)} -> 0 | S13: {=IFERROR(P13/$P$18,0)} -> 0
A14: 19年期 | N14: =SUM(B14:M14) -> 0 | Q14: {=IFERROR(N14/$N$18,0)} -> 0 | R14: {=IFERROR(O14/$O$18,0)} -> 0 | S14: {=IFERROR(P14/$P$18,0)} -> 0
A15: 20年重疾险 | N15: =SUM(B15:M15) -> 0 | Q15: {=IFERROR(N15/$N$18,0)} -> 0 | R15: {=IFERROR(O15/$O$18,0)} -> 0 | S15: {=IFERROR(P15/$P$18,0)} -> 0
A16: 24、25年重疾 | N16: =SUM(B16:M16) -> 0 | Q16: {=IFERROR(N16/$N$18,0)} -> 0 | R16: {=IFERROR(O16/$O$18,0)} -> 0 | S16: {=IFERROR(P16/$P$18,0)} -> 0
A17: 30年重疾险 | N17: =SUM(B17:M17) -> 0 | Q17: {=IFERROR(N17/$N$18,0)} -> 0 | R17: {=IFERROR(O17/$O$18,0)} -> 0 | S17: {=IFERROR(P17/$P$18,0)} -> 0
A18: 合计 | B18: =SUM(B5:B17) -> 7.1105 | C18: =SUM(C5:C17) -> 0 | D18: =SUM(D5:D17) -> 0.3247 | E18: =SUM(E5:E17) -> 0 | F18: =SUM(F5:F17) -> 0 | G18: =SUM(G5:G17) -> 0 | H18: =SUM(H5:H17) -> 0 | I18: =SUM(I5:I17) -> 0 | ... S18: =SUM(S5:S17) -> 1

Sheet 保费分析--君康产品
A1: 保费分析表--富泽产品结构 | P1: 返回目录
A2: 填报单位：盛唐融信保险代理（北京）有限公司 | H2: =目录!C3 -> 填报日期：2026-5-8 | R2: 单位：万元
A3: 险种 | B3: 规模保费 | O3: 累计标保 | P3: 累计FYB | R3: 年期占比
B4: 1月 | C4: 2月 | D4: 3月 | E4: 4月 | F4: 5月 | G4: 6月 | H4: 7月 | I4: 8月 | J4: 9月 | K4: 10月 | L4: 11月 | M4: 12月 | N4: 累计
A5: 趸交 | N5: =SUM(B5:M5) -> 0 | R5: =O5/$O$13 -> #DIV/0!
A6: 3年期寿险 | N6: =SUM(B6:M6) -> 0 | R6: =O6/$O$13 -> #DIV/0!
A7: 5年期寿险 | N7: =SUM(B7:M7) -> 0 | R7: =O7/$O$13 -> #DIV/0!
A8: 6年期寿险 | N8: =SUM(B8:M8) -> 0 | R8: =O8/$O$13 -> #DIV/0!
A9: 8年期寿险 | N9: =SUM(B9:M9) -> 0 | R9: =O9/$O$13 -> #DIV/0!
A10: 10年期寿险 | N10: =SUM(B10:M10) -> 0 | R10: =O10/$O$13 -> #DIV/0!
A11: 健康险 | N11: =SUM(B11:M11) -> 0 | R11: =P11/$P$13 -> #DIV/0!
A12: 年金险 | N12: =SUM(B12:M12) -> 0 | Q12: =O12/O13 -> #DIV/0!
A13: 总计 | B13: =SUM(B5:B12) -> 0 | C13: =SUM(C5:C12) -> 0 | D13: =SUM(D5:D12) -> 0 | E13: =SUM(E5:E12) -> 0 | F13: =SUM(F5:F12) -> 0 | G13: =SUM(G5:G12) -> 0 | H13: =SUM(H5:H12) -> 0 | I13: =SUM(I5:I12) -> 0 | ... P13: =SUM(P5:P12) -> 0 | R13: =SUM(R5:R12) -> #DIV/0!

Sheet 收入明细表
A1: 收入明细表 | N1: 返回目录
A2: 填报单位：盛唐融信保险代理（北京）有限公司 | G2: =目录!C3 -> 填报日期：2026-5-8 | N2: 单位：万元
A3: 项目 | C3: 1月 | D3: 2月 | E3: 3月 | F3: 4月 | G3: 5月 | H3: 6月 | I3: 7月 | J3: 8月 | K3: 9月 | L3: 10月 | M3: 11月 | N3: 12月 | O3: 本年累计金额 | P3: 目标 | Q3: 完成率
A4: 首期保费 | B4: 预估当月FYB | C4: ='保费分析-公司'!B15 -> 1.216575 | O4: =SUM(C4:N4) -> 1.216575 | P4: 164.896 | Q4: =O4/P4 -> 0.0073778321
B5: 当月承保标保 | C5: ='保费分析-公司'!B16 -> 5.53326 | O5: =SUM(C5:N5) -> 5.53326 | P5: 436.224 | Q5: =O5/P5 -> 0.012684447
B6: 规模保费 | C6: ='保费分析-公司'!B13 -> 7.11 | O6: =SUM(C6:N6) -> 7.11 | P6: 640 | Q6: =O6/P6 -> 0.011109375
A7: 报表列示主营业务收入 | C7: =C8+C13+C18 -> 32.620633 | D7: =D8+D13+D18 -> 19.682364 | E7: =E8+E13+E18 -> 29.933562 | F7: =F8+F13+F18 -> 23.451862 | G7: =G8+G13+G18 -> 0 | H7: =H8+H13+H18 -> 0 | I7: =I8+I13+I18 -> 0 | J7: =J8+J13+J18 -> 0 | ... N7: =N8+N13+N18 -> 0 | O7: =O8+O18 -> 89.494896 | P7: 654.52 | Q7: =O7/P7 -> 0.13673363
A8: 账面新契约收入 | C8: =C9+C10-C11 -> 2.691245 | D8: =D9+D10-D11 -> 0.461679 | E8: =E9+E10-E11 -> 0.142642 | F8: =F9+F10-F11 -> 0.040415 | G8: =G9+G10-G11 -> 0 | H8: =H9+H10-H11 -> 0 | I8: =I9+I10-I11 -> 0 | J8: =J9+J10-J11 -> 0 | ... O8: =O9+O10-O11 -> 3.335981 | P8: 304.71925 | Q8: =O8/P8 -> 0.01094772
A9: 新契约 收入 | B9: 当月确认 | D9: 3.152924 | E9: 0.142642 | F9: 0.040415 | O9: =SUM(C9:N9) -> 3.335981
B10: 当月暂估 | C10: 2.691245 | O10: =SUM(C10:N10) -> 2.691245
B11: 冲回上月暂估 | D11: 2.691245 | O11: =SUM(C11:N11) -> 2.691245
B12: 确认与暂估差额 | C12: =C9-C11 -> 0 | D12: =D9-D11 -> 0.461679 | E12: =E9-E11 -> 0.142642 | F12: =F9-F11 -> 0.040415 | G12: =G9-G11 -> 0 | H12: =H9-H11 -> 0 | I12: =I9-I11 -> 0 | J12: =J9-J11 -> 0 | ... O12: =O9-O11 -> 0.644736
A13: 事业部账面续期收入 | C13: =C14+C15-C16 -> 1.542017 | D13: =D14+D15-D16 -> 3.1820268 | E13: =E14+E15-E16 -> 7.051776 | F13: =F14+F15-F16 -> 4.417705 | G13: =G14+G15-G16 -> 0 | H13: =H14+H15-H16 -> 0 | I13: =I14+I15-I16 -> 0 | J13: =J14+J15-J16 -> 0 | ... O13: =O14+O15-O16 -> 16.193525 | P13: 17.729004 | Q13: =O13/P13 -> 0.91339167
A14: 续期 收入 | B14: 当月确认 | C14: =ROUND(7013.68/10000/1.06,6) -> 0.661668 | D14: =D31-D9 -> 2.3955128 | E14: =ROUND(82326.88/10000/1.06,6) -> 7.766687 | F14: =ROUND(54171.09/10000/1.06,6) -> 5.11048 | O14: =SUM(C14:N14) -> 15.934348
B15: 当月暂估 | C15: 1.031977 | D15: 1.818491 | E15: 1.10358 | F15: 0.410805 | O15: =SUM(C15:N15) -> 4.364853
B16: 冲回上月暂估 | C16: 0.151628 | D16: 1.031977 | E16: 1.818491 | F16: 1.10358 | O16: =SUM(C16:N16) -> 4.105676
B17: 确认与暂估差额 | C17: =C14-C16 -> 0.51004 | D17: =D14-D16 -> 1.3635358 | E17: =E14-E16 -> 5.948196 | F17: =F14-F16 -> 4.0069 | G17: =G14-G16 -> 0 | H17: =H14-H16 -> 0 | I17: =I14-I16 -> 0 | J17: =J14-J16 -> 0 | ... N17: =N14-N16 -> 0 | O17: =SUM(C17:N17) -> 11.828672
A18: 存续账面续期收入 | C18: =C19+C20-C21-C23 -> 28.387371 | D18: =D19+D20-D21 -> 16.038658 | E18: =E19+E20-E21 -> 22.739144 | F18: =F19+F20-F21 -> 18.993742 | G18: =G19+G20-G21 -> 0 | H18: =H19+H20-H21 -> 0 | I18: =I19+I20-I21 -> 0 | J18: =J19+J20-J21 -> 0 | K18: =K19+K20-K21 -> 0 | ... N18: =N19+N20-N21 -> 0 | O18: =SUM(C18:N18) -> 86.158915 | P18: 290.85706 | Q18: =O18/P18 -> 0.29622425
A19: 续期 收入 | B19: 当月确认 | C19: 33.264408 | D19: =31.865909-D14 -> 29.470396 | E19: =23.359106-E14 -> 15.592419 | F19: =29.565707-F14 -> 24.455227 | O19: =SUM(C19:N19) -> 102.78245
B20: 当月暂估 | C20: 26.244476 | D20: 12.812738 | E20: 19.959463 | F20: 14.497978 | O20: =SUM(C20:N20) -> 73.514655
B21: 冲回上月暂估 | C21: 31.121513 | D21: 26.244476 | E21: 12.812738 | F21: 19.959463 | O21: =SUM(C21:N21) -> 90.13819
B22: 确认与暂估差额 | C22: =C19-C21 -> 2.142895 | O22: =O19-O21 -> 12.64426
B23: 其中退保损失/继续率通算损失 | E23: 1.741393 | O23: =SUM(C23:N23) -> 1.741393
D25: =D19*0.06*0.12 -> 0.21218685 | E25: =E14*0.06*0.12 -> 0.055920146 | F25: =F14*0.06*0.12 -> 0.036795456 | G25: =G14*0.06*0.12 -> 0 | H25: =H14*0.06*0.12 -> 0 | I25: =I14*0.06*0.12 -> 0 | J25: =J14*0.06*0.12 -> 0 | K25: =K14*0.06*0.12 -> 0 | L25: =L14*0.06*0.12 -> 0 | M25: =(M14+M9)*0.06*0.12 -> 0
C27: 7.128603 | D27: 8.239593 | E27: 9.61693 | F27: 9.162125 | G27: 1.748176 | M27: 2.377074 | O27: 2.4651264
C28: =C27/C14 -> 10.773686 | D28: =D27/D14 -> 3.4395947 | E28: =E27/E14 -> 1.2382281 | F28: =F27/F14 -> 1.792811 | G28: =G27/G14 -> #DIV/0! | M28: =M27-M25 -> 2.377074
B29: 事业部续期毛利 | C29: =(C14-C27)/C14 -> -9.7736856 | D29: =(D14-D27)/D14 -> -2.4395947 | E29: =(E14-E27)/E14 -> -0.23822809 | F29: =(F14-F27)/F14 -> -0.79281105 | G29: =(G14-G27)/G14 -> #DIV/0!
D31: =5.881343/1.06 -> 5.5484368

Sheet 基本法支出
A1: 续期基本法支出预算执行表 | O1: 返回目录
A2: 填报单位：盛唐融信保险代理（北京）有限公司 | G2: =目录!C3 -> 填报日期：2026-5-8 | O2: 单位：万元
A3: 项目 | B3: 1月 | C3: 2月 | D3: 3月 | E3: 4月 | F3: 5月 | G3: 6月 | H3: 7月 | I3: 8月 | J3: 9月 | K3: 10月 | L3: 11月 | M3: 12月 | N3: 累计 | O3: 年度预算 | P3: 预算执行率
A4: 佣金支出—首年直佣 | C4: -0.17797 | N4: =SUM(B4:M4) -> -0.17797 | O4: 9.0410396 | P4: =N8/O4 -> 0.68163123
A5: 主营业务成本—事业部续年直佣 | B5: 0.821917 | C5: 2.124786 | D5: 1.309293 | E5: 1.975538 | N5: =SUM(B5:M5) -> 6.231534
A6: 佣金支出—续年暂估冲回 | B6: -0.62 | C6: -1.383466 | D6: -1.2569 | E6: -1.557507 | N6: =SUM(B6:M6) -> -4.817873
A7: 佣金支出—续年暂估 | B7: 1.383466 | C7: 1.2569 | D7: 1.557507 | E7: 0.729091 | N7: =SUM(B7:M7) -> 4.926964
A8: 合计 | B8: =SUM(B4:B7) -> 1.585383 | C8: =SUM(C4:C7) -> 1.82025 | D8: =SUM(D4:D7) -> 1.6099 | E8: =SUM(E4:E7) -> 1.147122 | F8: =SUM(F4:F7) -> 0 | G8: =SUM(G4:G7) -> 0 | H8: =SUM(H4:H7) -> 0 | I8: =SUM(I4:I7) -> 0 | ... N8: =SUM(N4:N7) -> 6.162655 | O8: 27.55 | P8: =N8/O8 -> 0.22368984
A9: 新单成本支出预算执行表
A10: 项目 | B10: 1月 | C10: 2月 | D10: 3月 | E10: 4月 | F10: 5月 | G10: 6月 | H10: 7月 | I10: 8月 | J10: 9月 | K10: 10月 | L10: 11月 | M10: 12月 | N10: 累计 | O10: 年度预算 | P10: 预算执行率
A11: 主营业务成本-基本法 | C11: 1.68399 | E11: 0.023462 | N11: =SUM(B11:M11) -> 1.707452 | O11: 196.72971 | P11: =(N11+N12+N13)/O11 -> 0.008679177
A12: 主营业务成本-冲回基本法暂估 | C12: -1.751664 | N12: =SUM(B12:M12) -> -1.751664
A13: 主营业务成本-基本法暂估 | B13: =1.18318+0.568484 -> 1.751664 | N13: =SUM(B13:M13) -> 1.751664
A14: 主营业务成本-暂估方案 | B14: 0.1776 | N14: =SUM(B14:M14) -> 0.1776 | O14: 21.43648 | P14: =N14/O14 -> 0.0082849423
A15: 主营业务成本-冲回方案暂估 | C15: -0.1776 | E15: -1.379833 | N15: =SUM(B15:M15) -> -1.557433
A16: 主营业务成本-确认方案 | C16: 0.1776 | E16: 1.379832 | N16: =SUM(B16:M16) -> 1.557432
A17: 业务及管理费用-职场成本 | B17: =职场成本!B9+职场成本!B17 -> 1.194006 | C17: =职场成本!C9+职场成本!C17 -> 0.978819 | D17: =职场成本!D9+职场成本!D17 -> 0.640288 | E17: =职场成本!E9+职场成本!E17 -> 0.614809 | F17: =职场成本!F9+职场成本!F17 -> 0 | G17: =职场成本!G9+职场成本!G17 -> 0 | H17: =职场成本!H9+职场成本!H17 -> 0 | I17: =职场成本!I9+职场成本!I17 -> 0 | ... M17: =职场成本!M9+职场成本!M17 -> 0 | N17: =SUM(B17:M17) -> 3.427922 | O17: 9.106746 | P17: =N17/O17 -> 0.37641568
A18: 业务及管理费用-人力成本 | B18: =人力成本!B20 -> 6.921186 | C18: =人力成本!C20 -> 6.621186 | D18: =人力成本!D20 -> 6.621186 | E18: =人力成本!E20 -> 6.781186 | F18: =人力成本!F20 -> 0 | G18: =人力成本!G20 -> 0 | H18: =人力成本!H20 -> 0 | I18: =人力成本!I20 -> 0 | ... M18: =人力成本!M20 -> 0 | N18: =SUM(B18:M18) -> 26.944744 | O18: 81.588744 | P18: =N18/O18 -> 0.33025075
A19: 业务及管理费用-折旧摊销 | B19: 0.053187 | C19: 0.04527 | D19: 0.04527 | E19: 0.04527 | N19: =SUM(B19:M19) -> 0.188997 | O19: 0.638244 | P19: =N19/O19 -> 0.29612029
A20: 业务及管理费用-日常经营 | B20: =B21+B22+B25+B26 -> 0 | N20: =SUM(B20:M20) -> 0 | O20: 0 | P20: {=IFERROR(N20/O20,0)} -> 0
A21: 其中：办公杂费 | N21: =SUM(B21:M21) -> 0 | O21: 0 | P21: =N21/O21 -> #DIV/0!
A22: 其中：招待费 | N22: =SUM(B22:M22) -> 0 | O22: 0 | P22: =N22/O22 -> #DIV/0!
A23: 昌平
A24: 平谷
A25: 其中：宽带费 | N25: =SUM(B25:M25) -> 0 | O25: 0 | P25: =N25/O25 -> #DIV/0!
A26: 其中：会议费用 | N26: =SUM(B26:M26) -> 0 | O26: 0 | P26: =N26/O26 -> #DIV/0!
A27: 业务及管理费用-税金及附加 | B27: =B29 -> 0.0047640096 | N27: =SUM(B27:M27) -> 0.0047640096 | O27: 2.3216274 | P27: =N27/O27 -> 0.002052013
A28: 合计 | B28: =B11+B12+B13+B14+B16+B17+B18+B19+B20+B26+B27 -> 10.102407 | C28: =C11+C12+C13+C14+C16+C17+C18+C19+C20+C26+C27 -> 7.755201 | D28: =D11+D12+D13+D14+D16+D17+D18+D19+D20+D26+D27 -> 7.306744 | E28: =E11+E12+E13+E14+E16+E17+E18+E19+E20+E26+E27 -> 8.844559 | F28: =F11+F12+F13+F14+F16+F17+F18+F19+F20+F26+F27 -> 0 | G28: =G11+G12+G13+G14+G16+G17+G18+G19+G20+G26+G27 -> 0 | H28: =H11+H12+H13+H14+H16+H17+H18+H19+H20+H26+H27 -> 0 | I28: =I11+I12+I13+I14+I16+I17+I18+I19+I20+I26+I27 -> 0 | ... M28: =M11+M12+M13+M14+M16+M17+M18+M19+M20+M26+M27 -> 0 | N28: =SUM(N11:N27) -> 32.451478 | O28: =O11+O14+O17+O18+O19+O20+O27 -> 311.82155 | P28: =N28/O28 -> 0.10407067
A29: 事业部 | B29: =收入明细表!C14*0.06*0.12 -> 0.0047640096
A30: 存续 | B30: =B31-B29 -> 0.23290299
B31: =0.237667 -> 0.237667

Sheet 弹性销售成本
A1: 弹性销售成本预算执行表 | O1: 返回目录
A2: 填报单位：盛唐融信保险代理（北京）有限公司 | H2: =目录!C3 -> 填报日期：2026-5-8 | P2: 单位：万元
A3: 项目 | B3: 1月 | C3: 2月 | D3: 3月 | E3: 4月 | F3: 5月 | G3: 6月 | H3: 7月 | I3: 8月 | J3: 9月 | K3: 10月 | L3: 11月 | M3: 12月 | N3: 累计 | O3: 年度预算 | P3: 预算执行率
A4: 1.业务推动 | N4: =SUM(B4:M4) -> 0 | O4: 744.544 | P4: =(N4+N5)/O4 -> 0
A5: 业务推动暂估 | N5: =SUM(B5:M5) -> 0
A6: 2.组织发展 | N6: =SUM(B6:M6) -> 0 | O6: 151.2 | P6: =(N6+N7)/O6 -> 0
A7: 组织发展暂估 | N7: =SUM(B7:M7) -> 0
A8: 合计 | B8: =SUM(B4:B7) -> 0 | C8: =SUM(C4:C7) -> 0 | D8: =SUM(D4:D7) -> 0 | E8: =SUM(E4:E7) -> 0 | F8: =SUM(F4:F7) -> 0 | G8: =SUM(G4:G7) -> 0 | H8: =SUM(H4:H7) -> 0 | I8: =SUM(I4:I7) -> 0 | ... N8: =SUM(N4:N7) -> 0 | O8: =SUM(O4:O6) -> 895.744 | P8: =(N8+N9)/O8 -> 0

Sheet 附表-竞赛方案
A1: 竞赛方案明细表表 | G1: 返回目录
A2: 填报单位：盛唐融信保险代理（北京）有限公司 | D2: =目录!C3 -> 填报日期：2026-5-8 | G2: 单位：万元
A3: 序号 | B3: 期间 | C3: 方案名称 | D3: 标准 | E3: 奖励 | F3: 实际兑现 | G3: 达成保费FYB
A4: 1
A5: 2
A6: 3
A7: 4
A8: 5
A9: 6
A10: 7
A11: 8
A12: 9
A13: 10
A14: 11
A15: 12
... A25: 22

Sheet 半固定销售成本
A1: 半固定销售成本预算执行表 | O1: 返回目录
A2: 填报单位：盛唐融信保险代理（北京）有限公司 | G2: =目录!C3 -> 填报日期：2026-5-8 | P2: 单位：万元
A3: 项目 | B3: 1月 | C3: 2月 | D3: 3月 | E3: 4月 | F3: 5月 | G3: 6月 | H3: 7月 | I3: 8月 | J3: 9月 | K3: 10月 | L3: 11月 | M3: 12月 | N3: 合计 | O3: 年度预算 | P3: 预算执行率
A4: 一、客户经营 | B4: =SUM(B5:B10) -> 0 | C4: =SUM(C5:C10) -> 0 | D4: =SUM(D5:D10) -> 0 | E4: 0 | F4: =SUM(F5:F10) -> 0 | G4: =SUM(G5:G10) -> 0 | H4: =SUM(H5:H10) -> 0 | I4: =SUM(I5:I10) -> 0 | J4: =SUM(J5:J10) -> 0 | K4: =SUM(K5:K10) -> 0 | L4: =SUM(L5:L10) -> 0 | M4: =SUM(M5:M10) -> 0 | ... O4: =SUM(O5:O10) -> 0 | P4: =IFERROR(N4/O4,0) -> 0
A5: 1.产说会 | B5: 0 | C5: 0 | D5: 0 | E5: 0 | F5: 0 | G5: 0 | H5: 0 | I5: 0 | J5: 0 | K5: 0 | L5: 0 | M5: 0 | N5: =SUM(B5:M5) -> 0 | O5: 0 | P5: =IFERROR(N5/O5,0) -> 0
A6: 2.司服方案 | B6: 0 | C6: 0 | D6: 0 | E6: 0 | F6: 0 | G6: 0 | H6: 0 | I6: 0 | J6: 0 | K6: 0 | L6: 0 | M6: 0 | N6: =SUM(B6:M6) -> 0 | O6: 0 | P6: =IFERROR(N6/O6,0) -> 0
A7: 3.司徽方案 | B7: 0 | C7: 0 | D7: 0 | E7: 0 | F7: 0 | G7: 0 | H7: 0 | I7: 0 | J7: 0 | K7: 0 | L7: 0 | M7: 0 | N7: =SUM(B7:M7) -> 0 | O7: 0 | P7: =IFERROR(N7/O7,0) -> 0
A8: 4.经营活动 | B8: 0 | C8: 0 | D8: 0 | E8: 0 | F8: 0 | G8: 0 | H8: 0 | I8: 0 | J8: 0 | K8: 0 | L8: 0 | M8: 0 | N8: =SUM(B8:M8) -> 0 | O8: 0 | P8: =IFERROR(N8/O8,0) -> 0
A9: 5.会议支出 | B9: 0 | C9: 0 | D9: 0 | E9: 0 | F9: 0 | G9: 0 | H9: 0 | I9: 0 | J9: 0 | K9: 0 | L9: 0 | M9: 0 | N9: =SUM(B9:M9) -> 0 | O9: 0 | P9: =IFERROR(N9/O9,0) -> 0
A10: 6.其他 | B10: 0 | C10: 0 | D10: 0 | E10: 0 | F10: 0 | G10: 0 | H10: 0 | I10: 0 | J10: 0 | K10: 0 | L10: 0 | M10: 0 | N10: =SUM(B10:M10) -> 0 | O10: 0 | P10: =IFERROR(N10/O10,0) -> 0
A11: 二、队伍经营 | B11: 0 | C11: =SUM(C12:C16) -> 0 | D11: =SUM(D12:D16) -> 0 | E11: =SUM(E12:E16) -> 0 | F11: 0 | G11: 0 | H11: =SUM(H12:H16) -> 0 | I11: =SUM(I12:I16) -> 0 | J11: 0 | K11: 0 | L11: =SUM(L12:L16) -> 0 | M11: 0 | N11: =SUM(B11:M11) -> 0 | O11: =SUM(O12:O16) -> 0 | P11: =IFERROR(N11/O11,0) -> 0
A12: 1.专项计划 | B12: 0 | C12: 0 | D12: 0 | E12: 0 | F12: 0 | G12: 0 | H12: 0 | I12: 0 | J12: 0 | K12: 0 | L12: 0 | M12: 0 | N12: =SUM(B12:M12) -> 0 | O12: 0 | P12: =IFERROR(N12/O12,0) -> 0
A13: 2.特殊聘才 | B13: 0 | C13: 0 | D13: 0 | E13: 0 | F13: 0 | G13: 0 | H13: 0 | I13: 0 | J13: 0 | K13: 0 | L13: 0 | M13: 0 | N13: =SUM(B13:M13) -> 0 | O13: 0 | P13: =IFERROR(N13/O13,0) -> 0
A14: 3.其他方案 | B14: 0 | C14: 0 | D14: 0 | E14: 0 | F14: 0 | G14: 0 | H14: 0 | I14: 0 | J14: 0 | K14: 0 | L14: 0 | M14: 0 | N14: =SUM(B14:M14) -> 0 | O14: 0 | P14: =IFERROR(N14/O14,0) -> 0
A15: 4.会议费 | B15: 0 | C15: 0 | D15: 0 | E15: 0 | F15: 0 | G15: 0 | H15: 0 | I15: 0 | J15: 0 | K15: 0 | L15: 0 | M15: 0 | N15: =SUM(B15:M15) -> 0 | O15: 0 | P15: =IFERROR(N15/O15,0) -> 0
A16: 5.招聘相关费用 | B16: 0 | C16: 0 | D16: 0 | E16: 0 | F16: 0 | G16: 0 | H16: 0 | I16: 0 | J16: 0 | K16: 0 | L16: 0 | M16: 0 | N16: =SUM(B16:M16) -> 0 | O16: 0 | P16: =IFERROR(N16/O16,0) -> 0
A17: 合计 | B17: =B4+B11 -> 0 | C17: =C4+C11 -> 0 | D17: =D4+D11 -> 0 | E17: =E4+E11 -> 0 | F17: =F4+F11 -> 0 | G17: =G4+G11 -> 0 | H17: =H4+H11 -> 0 | I17: =I4+I11 -> 0 | ... O17: =O4+O11 -> 0 | P17: =IFERROR(N17/O17,0) -> 0

Sheet 职场成本
A1: 职场成本预算执行表 | M1: 返回目录
A2: 填报单位：盛唐融信保险代理（北京）有限公司 | G2: =目录!C3 -> 填报日期：2026-5-8 | N2: 单位：万元
A3: 项目 | B3: 1月 | C3: 2月 | D3: 3月 | E3: 4月 | F3: 5月 | G3: 6月 | H3: 7月 | I3: 8月 | J3: 9月 | K3: 10月 | L3: 11月 | M3: 12月 | N3: 累计
A4: 汇总 | B4: =B5+B9+B17 -> 4.103085 | C4: =C5+C9+C17 -> 3.606612 | D4: =D5+D9+D17 -> 3.636947 | E4: =E5+E9+E17 -> 3.391893 | F4: =F5+F9+F17 -> 0 | G4: =G5+G9+G17 -> 0 | H4: =H5+H9+H17 -> 0 | I4: =I5+I9+I17 -> 0 | ... M4: =M5+M9+M17 -> 0 | N4: =SUM(B4:M4) -> 14.738537
A5: 1.万达广场10号楼905.906室（10060） | B5: =B6+B7+B8 -> 2.909079 | C5: =C6+C7+C8 -> 2.627793 | D5: =D6+D7+D8 -> 2.996659 | E5: =E6+E7+E8 -> 2.777084 | F5: =F6+F7+F8 -> 0 | G5: =G6+G7+G8 -> 0 | H5: =H6+H7+H8 -> 0 | I5: =I6+I7+I8 -> 0 | ... L5: =L6+L7+L8 -> 0 | M5: =M6++M7+M8 -> 0 | N5: =N6+N7+N8 -> 11.310615 | O5: 0.3441
A6: 1.1使用权资产折旧 | B6: 2.829976 | C6: 2.556107 | D6: 2.829976 | E6: 2.738686 | N6: =SUM(B6:M6) -> 10.954745 | O6: =1-O5 -> 0.6559
A7: 1.2水电费 | D7: 0.1 | N7: =SUM(B7:M7) -> 0.1
A8: 1.3利息支出 | B8: 0.079103 | C8: 0.071686 | D8: 0.066683 | E8: 0.038398 | N8: =SUM(B8:M8) -> 0.25587
A9: 2.怀柔职场（92.3平米）（10056/10066） | B9: =SUM(B10:B16) -> 0.64168 | C9: =SUM(C10:C16) -> 0.941819 | D9: =SUM(D10:D16) -> 0.640288 | E9: =SUM(E10:E16) -> 0.614809 | F9: =SUM(F10:F16) -> 0 | G9: =SUM(G10:G16) -> 0 | H9: =SUM(H10:H16) -> 0 | I9: =SUM(I10:I16) -> 0 | ... N9: =SUM(N10:N16) -> 2.838596
A10: 1.1使用权资产折旧 | B10: 0.627284 | C10: 0.566579 | D10: 0.627284 | E10: 0.607049 | N10: =SUM(B10:M10) -> 2.428196
A11: 1.2利息支出 | B11: 0.014396 | C11: 0.011706 | D11: 0.013004 | E11: 0.00776 | N11: =SUM(B11:M11) -> 0.046866
A12: 1.3税费及中介费 | N12: =SUM(B12:M12) -> 0
A13: 1.4物业费 | C13: 0.086634 | N13: =SUM(B13:M13) -> 0.086634
A14: 1.5水电费 | N14: =SUM(B14:M14) -> 0
A15: 1.6取暖费 | C15: 0.2769 | N15: =SUM(B15:M15) -> 0.2769
A16: 1.7装修费 | N16: =SUM(B16:M16) -> 0
A17: 3.昌平职场（100平米）（10062） | B17: =SUM(B18:B24) -> 0.552326 | C17: =SUM(C18:C24) -> 0.037 | D17: =SUM(D18:D24) -> 0 | E17: =SUM(E18:E24) -> 0 | F17: =SUM(F18:F24) -> 0 | G17: =SUM(G18:G24) -> 0 | H17: =SUM(H18:H24) -> 0 | I17: =SUM(I18:I24) -> 0 | ... N17: =SUM(N18:N24) -> 0.589326
A18: 1.1使用权资产折旧 | B18: 0.552326 | N18: =SUM(B18:M18) -> 0.552326
A19: 1.2利息支出 | N19: =SUM(B19:M19) -> 0
A20: 1.3税费及中介费 | N20: =SUM(B20:M20) -> 0
A21: 1.4物业费 | N21: =SUM(B21:M21) -> 0
A22: 1.5水电费 | C22: 0.037 | N22: =SUM(B22:M22) -> 0.037
A23: 1.6取暖费 | N23: =SUM(B23:M23) -> 0
A24: 1.7装修费 | N24: =SUM(B24:M24) -> 0
A28: 机构 | B28: 1月 | C28: 2月 | D28: 3月 | E28: 4月 | F28: 5月 | G28: 6月 | H28: 7月 | I28: 8月 | J28: 9月 | K28: 10月 | L28: 11月 | M28: 12月 | N28: 累计
A29: 昌平 | B29: =SUM(B30:B34) -> 0.552326 | C29: =SUM(C30:C34) -> 0.037 | D29: =SUM(D30:D34) -> 0 | E29: =SUM(E30:E34) -> 0 | F29: =SUM(F30:F34) -> 0 | G29: =SUM(G30:G34) -> 0 | H29: =SUM(H30:H34) -> 0 | I29: =SUM(I30:I34) -> 0 | ... N29: =SUM(N30:N34) -> 0.589326
A30: 房租 | B30: =B18+B19+B20 -> 0.552326 | C30: =C18+C19+C20 -> 0 | D30: =D18+D19+D20 -> 0 | E30: =E18+E19+E20 -> 0 | F30: =F18+F19+F20 -> 0 | G30: =G18+G19+G20 -> 0 | H30: =H18+H19+H20 -> 0 | I30: =I18+I19+I20 -> 0 | ... M30: =M18+M19+M20 -> 0 | N30: =SUM(B30:M30) -> 0.552326
A31: 物业费 | B31: =B21 -> 0 | C31: =C21 -> 0 | D31: =D21 -> 0 | E31: =E21 -> 0 | F31: =F21 -> 0 | G31: =G21 -> 0 | H31: =H21 -> 0 | I31: =I21 -> 0 | ... M31: =M21 -> 0 | N31: =SUM(B31:M31) -> 0
A32: 电费 | B32: =B22 -> 0 | C32: =C22 -> 0.037 | D32: =D22 -> 0 | E32: =E22 -> 0 | F32: =F22 -> 0 | G32: =G22 -> 0 | H32: =H22 -> 0 | I32: =I22 -> 0 | ... M32: =M22 -> 0 | N32: =SUM(B32:M32) -> 0.037
A33: 取暖费 | B33: =B23 -> 0 | C33: =C23 -> 0 | D33: =D23 -> 0 | E33: =E23 -> 0 | F33: =F23 -> 0 | G33: =G23 -> 0 | H33: =H23 -> 0 | I33: =I23 -> 0 | ... M33: =M23 -> 0 | N33: =SUM(B33:M33) -> 0
A34: 装修费 | B34: =B24 -> 0 | C34: =C24 -> 0 | D34: =D24 -> 0 | E34: =E24 -> 0 | F34: =F24 -> 0 | G34: =G24 -> 0 | H34: =H24 -> 0 | I34: =I24 -> 0 | ... M34: =M24 -> 0 | N34: =SUM(B34:M34) -> 0
A35: 怀柔 | B35: =SUM(B36:B40) -> 0.64168 | C35: =SUM(C36:C40) -> 0.941819 | D35: =SUM(D36:D40) -> 0.640288 | E35: =SUM(E36:E40) -> 0.614809 | F35: =SUM(F36:F40) -> 0 | G35: =SUM(G36:G40) -> 0 | H35: =SUM(H36:H40) -> 0 | I35: =SUM(I36:I40) -> 0 | ... N35: =SUM(N36:N40) -> 2.838596
A36: 房租 | B36: =B10+B11+B12 -> 0.64168 | C36: =C10+C11+C12 -> 0.578285 | D36: =D10+D11+D12 -> 0.640288 | E36: =E10+E11+E12 -> 0.614809 | F36: =F10+F11+F12 -> 0 | G36: =G10+G11+G12 -> 0 | H36: =H10+H11+H12 -> 0 | I36: =I10+I11+I12 -> 0 | ... M36: =M10+M11+M12 -> 0 | N36: =SUM(B36:M36) -> 2.475062
A37: 物业费 | B37: =B13 -> 0 | C37: =C13 -> 0.086634 | D37: =D13 -> 0 | E37: =E13 -> 0 | F37: =F13 -> 0 | G37: =G13 -> 0 | H37: =H13 -> 0 | I37: =I13 -> 0 | ... M37: =M13 -> 0 | N37: =SUM(B37:M37) -> 0.086634
A38: 电费 | B38: =B14 -> 0 | C38: =C14 -> 0 | D38: =D14 -> 0 | E38: =E14 -> 0 | F38: =F14 -> 0 | G38: =G14 -> 0 | H38: =H14 -> 0 | I38: =I14 -> 0 | ... M38: =M14 -> 0 | N38: =SUM(B38:M38) -> 0
A39: 取暖费 | B39: =B15 -> 0 | C39: =C15 -> 0.2769 | D39: =D15 -> 0 | E39: =E15 -> 0 | F39: =F15 -> 0 | G39: =G15 -> 0 | H39: =H15 -> 0 | I39: =I15 -> 0 | ... M39: =M15 -> 0 | N39: =SUM(B39:M39) -> 0.2769
A40: 装修费 | B40: =B16 -> 0 | C40: =C16 -> 0 | D40: =D16 -> 0 | E40: =E16 -> 0 | F40: =F16 -> 0 | G40: =G16 -> 0 | H40: =H16 -> 0 | I40: =I16 -> 0 | ... M40: =M16 -> 0 | N40: =SUM(B40:M40) -> 0
A42: 昌平房屋租赁成本 | B42: =B29 -> 0.552326 | C42: =C29 -> 0.037 | D42: =D29 -> 0 | E42: =E29 -> 0 | F42: =F29 -> 0 | G42: =G29 -> 0 | H42: =H29 -> 0 | I42: =I29 -> 0 | ... N42: =N29 -> 0.589326
A43: 怀柔房屋租赁成本 | B43: =B35 -> 0.64168 | C43: =C35 -> 0.941819 | D43: =D35 -> 0.640288 | E43: =E35 -> 0.614809 | F43: =F35 -> 0 | G43: =G35 -> 0 | H43: =H35 -> 0 | I43: =I36 -> 0 | J43: =J36 -> 0 | K43: =K36 -> 0 | L43: =L36 -> 0 | M43: =M36 -> 0 | N43: =N36 -> 2.475062
A44: 合计 | B44: =SUM(B42:B43) -> 1.194006 | C44: =SUM(C42:C43) -> 0.978819 | D44: =SUM(D42:D43) -> 0.640288 | E44: =SUM(E42:E43) -> 0.614809 | F44: =SUM(F42:F43) -> 0 | G44: =SUM(G42:G43) -> 0 | H44: =SUM(H42:H43) -> 0 | I44: =SUM(I42:I43) -> 0 | ... N44: =SUM(N42:N43) -> 3.064388
...

Sheet 人力成本
A1: 人力成本预算执行表 | O1: 返回目录
A2: 填报单位：盛唐融信保险代理（北京）有限公司 | H2: =目录!C3 -> 填报日期：2026-5-8 | P2: 单位：万元
A3: 项目 | B3: 1月 | C3: 2月 | D3: 3月 | E3: 4月 | F3: 5月 | G3: 6月 | H3: 7月 | I3: 8月 | J3: 9月 | K3: 10月 | L3: 11月 | M3: 12月 | N3: 合计 | O3: 年度预算 | P3: 预算执行率
A4: 1.固定工资 | B4: 11.691625 | C4: 11.691625 | D4: 11.691625 | E4: 11.691625 | N4: =SUM(B4:M4) -> 46.7665 | O4: 140.2995 | P4: =IFERROR(N4/O4,0) -> 0.33333333
A5: 2.年奖 | N5: =SUM(B5:M5) -> 0 | P5: =IFERROR(N5/O5,0) -> 0
A6: 3.社会统筹保险 | B6: 2.687738 | C6: 2.687738 | D6: 2.687738 | E6: 2.687738 | N6: =SUM(B6:M6) -> 10.750952 | O6: 33.140058 | P6: =IFERROR(N6/O6,0) -> 0.32440957
A7: 4.住房公积金 | B7: 1.217 | C7: 1.217 | D7: 1.217 | E7: 1.217 | N7: =SUM(B7:M7) -> 4.868 | O7: 15.0066 | P7: =IFERROR(N7/O7,0) -> 0.3243906
A8: 5.员工福利 | B8: 0.95 | C8: 0.08 | E8: 0.5 | N8: =SUM(B8:M8) -> 1.53 | O8: 2.53 | P8: =IFERROR(N8/O8,0) -> 0.60474308
A9: 6.补充医疗 | N9: =SUM(B9:M9) -> 0 | O9: 1.52964 | P9: =IFERROR(N9/O9,0) -> 0
A10: 7.餐补及通讯补助 | B10: 0.215 | C10: 0.215 | D10: 0.215 | E10: 0.215 | N10: =SUM(B10:M10) -> 0.86 | O10: 2.58 | P10: =IFERROR(N10/O10,0) -> 0.33333333
A11: 合计 | B11: =SUM(B4:B10) -> 16.761363 | C11: =SUM(C4:C10) -> 15.891363 | D11: =SUM(D4:D10) -> 15.811363 | E11: =SUM(E4:E10) -> 16.311363 | F11: =SUM(F4:F10) -> 0 | G11: =SUM(G4:G10) -> 0 | H11: =SUM(H4:H10) -> 0 | I11: =SUM(I4:I10) -> 0 | ... O11: =SUM(O4:O10) -> 195.0858 | P11: =IFERROR(N11/O11,0) -> 0.33203571
A12: 项目 | B12: 1月 | C12: 2月 | D12: 3月 | E12: 4月 | F12: 5月 | G12: 6月 | H12: 7月 | I12: 8月 | J12: 9月 | K12: 10月 | L12: 11月 | M12: 12月 | N12: 合计 | O12: 年度预算 | P12: 预算执行率
A13: 1.固定工资 | B13: 4.7 | C13: 4.7 | D13: 4.7 | E13: 4.7 | N13: =SUM(B13:M13) -> 18.8 | O13: 56.4 | P13: =IFERROR(N13/O13,0) -> 0.33333333
A14: 2.年奖 | N14: =SUM(B14:M14) -> 0 | P14: =IFERROR(N14/O14,0) -> 0
A15: 3.社会统筹保险 | B15: 1.301786 | C15: 1.301786 | D15: 1.301786 | E15: 1.301786 | N15: =SUM(B15:M15) -> 5.207144 | O15: 16.297344 | P15: =IFERROR(N15/O15,0) -> 0.31950875
A16: 4.住房公积金 | B16: 0.5894 | C16: 0.5894 | D16: 0.5894 | E16: 0.5894 | N16: =SUM(B16:M16) -> 2.3576 | O16: 7.3794 | P16: =IFERROR(N16/O16,0) -> 0.31948397
A17: 5.员工福利 | B17: 0.3 | E17: 0.16 | N17: =SUM(B17:M17) -> 0.46 | O17: 0.78 | P17: =IFERROR(N17/O17,0) -> 0.58974359
A18: 6.补充医疗 | N18: =SUM(B18:M18) -> 0 | O18: 0.372 | P18: =IFERROR(N18/O18,0) -> 0
A19: 7.通讯补助 | B19: 0.03 | C19: 0.03 | D19: 0.03 | E19: 0.03 | N19: =SUM(B19:M19) -> 0.12 | O19: 0.36 | P19: =IFERROR(N19/O19,0) -> 0.33333333
A20: 合计 | B20: =SUM(B13:B19) -> 6.921186 | C20: =SUM(C13:C19) -> 6.621186 | D20: =SUM(D13:D19) -> 6.621186 | E20: =SUM(E13:E19) -> 6.781186 | F20: =SUM(F13:F19) -> 0 | G20: =SUM(G13:G19) -> 0 | H20: =SUM(H13:H19) -> 0 | I20: =SUM(I13:I19) -> 0 | ... O20: =SUM(O13:O19) -> 81.588744 | P20: =IFERROR(N20/O20,0) -> 0.33025075
A21: 补充资料
A22: 在职人数 | B22: 8 | C22: 8 | D22: 8 | E22: 8 | F22: 8 | G22: 8 | H22: 8 | I22: 8 | J22: 8 | K22: 8 | L22: 8 | M22: 8
A23: 合计 | B23: =B11+B20 -> 23.682549 | C23: =C11+C20 -> 22.512549 | D23: =D11+D20 -> 22.432549 | E23: =E11+E20 -> 23.092549 | F23: =F11+F20 -> 0 | G23: =G11+G20 -> 0 | H23: =H11+H20 -> 0 | I23: =I11+I20 -> 0 | ... O23: =O11+O20 -> 276.67454 | P23: =N23/O23 -> 0.33150934

Sheet 附表-职场情况
A1: 房租物业费明细表 | H1: 返回目录
A2: 填报单位：盛唐融信保险代理（北京）有限公司 年度：2019年 单位：元
A3: 职场 | B3: 平米数 | C3: 日租金/平 | D3: 月租金 | E3: 月物业费/平 | F3: 月物业费 | G3: 合计 | H3: 备注
A4: 310 | B4: 469.52 | C4: 7.85 | D4: =B4*C4*365/12 -> 112107.68 | E4: 35 | F4: =B4*E4 -> 16433.2 | G4: =D4+F4 -> 128540.88
A5: 408 | B5: 385.06 | C5: 7.97 | D5: =B5*C5*365/12 -> 93346.566 | E5: 35 | F5: =B5*E5 -> 13477.1 | G5: =D5+F5 -> 106823.67
A6: 4层 | B6: 2273.15 | C6: 7.97 | D6: =B6*C6*365/12 -> 551058.92 | E6: 35 | F6: =B6*E6 -> 79560.25 | G6: =D6+F6 -> 630619.17 | H6: 403/404/405/406/409/410/411
A7: 密云 | B7: 245 | C7: 1.5 | D7: 11178.12 | E7: 30.5 | F7: 7452.08 | G7: =D7+F7 -> 18630.2 | H7: 2.5元/平/天（1.5元租金，1元物业费）
A8: 新机构 | D8: 12101.13 | F8: 16410.7 | G8: =D8+F8 -> 28511.83 | H8: 预估
A9: 月合计 | D9: =SUM(D4:D8) -> 779792.42 | F9: =SUM(F4:F8) -> 133333.33 | G9: =D9+F9 -> 913125.75
A10: 年合计 | D10: =D9*12 -> 9357509 | F10: =F9*12 -> 1600000 | G10: =ROUND((D10+F10)/10000,0) -> 1096 | H10: 万元
A12: 注：月租金=日租金*平米数*365天/12

Sheet 应收账款明细表
A1: 应收账款明细表 | E1: 返回目录
A2: 填报单位：盛唐融信保险代理（北京）有限公司 | C2: =目录!C3 -> 填报日期：2026-5-8 | E2: 单位：元
A3: 明细 | B3: 期初余额 | C3: 本期借方 | D3: 本期贷方 | E3: 期末余额
A4: 中英人寿保险有限公司北京分公司 | B4: 23139.21 | C4: 19981.34 | D4: 23108.37 | E4: 20012.18
A5: 中国人民健康保险股份有限公司北京分公司 | B5: 67 | C5: 214.15 | D5: 67 | E5: 214.15
A6: 泰康人寿保险有限责任公司北京分公司 | B6: 3982.17 | C6: 6252.36 | D6: 3982.17 | E6: 6252.36
A7: 暂估 | B7: 210630.43 | C7: -61542.6 | D7: 0 | E7: 149087.83
A8: 富德生命人寿保险股份有限公司北京分公司 | B8: 580.1 | C8: 1252.71 | D8: 580.1 | E8: 1252.71
A9: 光大永明人寿保险有限公司北京分公司 | B9: 476.5 | C9: 1580.95 | D9: 476.5 | E9: 1580.95
A10: 信泰人寿保险股份有限公司北京分公司 | B10: 0 | C10: 18426.86 | D10: 4194.04 | E10: 14232.82
A11: 卡富斯保险经纪有限公司 | B11: 1471.14 | C11: 3821.02 | D11: 1471.14 | E11: 3821.02
A12: 中汇人寿保险股份有限公司 | B12: 1953.2 | C12: 2540.8 | D12: 1953.2 | E12: 2540.8
A18: 合计 | B18: =SUM(B4:B17) -> 242299.75 | C18: =SUM(C4:C17) -> -7472.41 | D18: =SUM(D4:D17) -> 35832.52 | E18: =SUM(E4:E17) -> 198994.82

Sheet 应收利息明细表
A1: 应收利息明细表 | F1: 返回目录
A2: 填报单位：盛唐融信保险代理（北京）有限公司 | D2: =目录!C3 -> 填报日期：2026-5-8 | F2: 单位：元
A3: 明细 | B3: 存款金额 | C3: 期初余额 | D3: 本期借方 | E3: 本期贷方 | F3: 期末余额
A4: 广发银行（7天通知存款） | B4: 5191964.3 | C4: 105475.11 | D4: 1664.27 | E4: 105475.11 | F4: 1664.27
A5: 中信银行（基本户1年期） | B5: 35000000 | C5: 64438.36 | D5: 40273.97 | E5: 0 | F5: 104712.33
A6: 光大银行（托管户3年期） | B6: 10000000 | C6: 109315.05 | D6: 14383.56 | E6: 0 | F6: 123698.61
A7: 合计 | B7: =SUM(B4:B6) -> 50191964 | C7: =SUM(C4:C6) -> 279228.52 | D7: =SUM(D4:D6) -> 56321.8 | E7: =SUM(E4:E6) -> 105475.11 | F7: =SUM(F4:F6) -> 230075.21

Sheet 其他应付款明细
A1: 其他应付款明细表 | G1: 返回目录
A2: 填报单位：盛唐融信保险代理（北京）有限公司 | C2: =目录!C3 -> 填报日期：2026-5-8 | G2: 单位：元
A3: 科目 | B3: 明细 | C3: 期初余额 | D3: 本期借方 | E3: 本期贷方 | F3: 期末余额 | G3: 用途
A4: 其他应付款-个人部分-公积金 | B4: 缺省 | C4: -18064 | F4: =C4-D4+E4 -> -18064
A5: 其他应付款-租赁费 | B5: 租赁费 | D5: 18750 | F5: =C5-D5+E5 -> -18750
A6: 其他应付款-其他 | B6: 预提监管费 | C6: 42120.64 | F6: =C6-D6+E6 -> 42120.64
A7: 其他应付款-其他 | B7: 天职事务所 | C7: 9000 | F7: =C7-D7+E7 -> 9000
A8: 合计 | C8: =SUM(C4:C7) -> 33056.64 | D8: =SUM(D4:D7) -> 18750 | E8: =SUM(E4:E7) -> 0 | F8: =SUM(F4:F7) -> 14306.64

Sheet 应付佣金
A1: 应付佣金明细表 | C1: 返回目录
A2: 填报单位：盛唐融信保险代理（北京）有限公司 | C2: 单位：元
A3: 明细 | B3: 期末余额 | C3: 用途
A4: 应付佣金（暂估） | B4: 1685.27 | C4: 年初预估差额
A5: 应付佣金-缓发佣金 | B5: 234990.57
A6: 合计 | B6: =SUM(B4:B5) -> 236675.84

Sheet 其他应收款
A1: 其他应收款及预付款明细表 | F1: 返回目录
A2: 填报单位：盛唐融信保险代理（北京）有限公司 | C2: =应收账款明细表!C2 -> 填报日期：2026-5-8 | F2: 单位：元
A3: 明细 | B3: 期初余额 | C3: 本期借方 | D3: 本期贷方 | E3: 期末余额 | F3: 会计科目及用途
A4: 应收代理人佣金 | B4: 74145.18 | E4: =B4+C4-D4 -> 74145.18 | F4: 其他应收款-其他（计提损失）
A5: 平谷培训室押金 | B5: 5000 | D5: 5000 | E5: =B5+C5-D5 -> 0 | F5: 其他应收款-押金
A6: 第一分公司怀柔职场押金 | B6: 7500 | E6: =B6+C6-D6 -> 7500 | F6: 其他应收款-预付账款
A7: 2025年年审预付款 | D7: 9000 | E7: =B7-C7+D7 -> 9000 | F7: 其他应收款-预付账款
A8: 本部905、906房租押金 | B8: 57400 | E8: =B8+C8-D8 -> 57400 | F8: 其他应收款-押金
A9: 赵志勇 | B9: 149900 | E9: =B9+C9-D9 -> 149900 | F9: 其他应收款-员工借款（计提损失）
A10: 合计 | B10: =SUM(B4:B9) -> 293945.18 | C10: =SUM(C4:C9) -> 0 | D10: =SUM(D4:D9) -> 14000 | E10: =SUM(E4:E9) -> 297945.18

Sheet 日常行政费用明细
A1: 日常行政费用执行情况 | Q1: 返回目录
A2: 填报单位：盛唐融信保险代理（北京）有限公司 | F2: =目录!C3 -> 填报日期：2026-5-8 | Q2: 单位：万元
A3: 会计科目 | B3: 费用项目 | C3: 年初预算 | D3: 1月实际执行 | E3: 2月实际执行 | F3: 3月实际执行 | G3: 4月实际执行 | H3: 5月实际执行 | I3: 6月实际执行 | J3: 7月实际执行 | K3: 8月实际执行 | L3: 9月实际执行 | M3: 10月实际执行 | N3: 11月实际执行 | O3: 12月实际执行 | P3: 合计 | Q3: 预算执行率
A4: 职业保险费 | B4: 职业保险费 | C4: 0.943396 | D4: 0.943396 | P4: =SUM(D4:O4) -> 0.943396 | Q4: =IFERROR(P4/C4,0) -> 1
A5: 监管费 | B5: 监管费 | C5: 4.2453221 | P5: =SUM(D5:O5) -> 0 | Q5: =IFERROR(P5/C5,0) -> 0
A6: 行业协会会费 | B6: 行业协会会费 | C6: 0.3 | P6: =SUM(D6:O6) -> 0 | Q6: =IFERROR(P6/C6,0) -> 0
A7: 保洁费 | B7: 保洁费 | C7: 0.1 | P7: =SUM(D7:O7) -> 0 | Q7: =IFERROR(P7/C7,0) -> 0
A8: 电话费 | B8: 电话费 | C8: 0.15314 | E8: 0.023315 | G8: 0.01628 | P8: =SUM(D8:O8) -> 0.039595 | Q8: =IFERROR(P8/C8,0) -> 0.25855426
A9: 网络专线费 | B9: 网络专线费 | C9: 0.5 | P9: =SUM(D9:O9) -> 0 | Q9: =IFERROR(P9/C9,0) -> 0
A10: 外部审计费用 | B10: 外部审计费用 | C10: 3 | P10: =SUM(D10:O10) -> 0 | Q10: =IFERROR(P10/C10,0) -> 0
A11: 银行结算费 | B11: 银行结算费 | C11: 0.22704 | D11: 0.01923 | E11: 0.008349 | F11: 0.085377 | G11: -0.179388 | P11: =SUM(D11:O11) -> -0.066432 | Q11: =IFERROR(P11/C11,0) -> -0.29260042
A12: 业务招待费 | B12: 业务招待费 | C12: 0.8 | D12: 0.0353 | E12: 0.1 | F12: 0.03 | G12: 0.0379 | P12: =SUM(D12:O12) -> 0.2032 | Q12: =IFERROR(P12/C12,0) -> 0.254
A13: 本埠差旅费 | B13: 本埠差旅费 | C13: 0.06 | D13: 0.0068 | G13: 0.005 | P13: =SUM(D13:O13) -> 0.0118 | Q13: =IFERROR(P13/C13,0) -> 0.19666667
A14: 外埠差旅费 | B14: 外埠差旅费 | C14: 0 | P14: =SUM(D14:O14) -> 0 | Q14: =IFERROR(P14/C14,0) -> 0
A15: 电子耗材 | B15: 电子耗材 | C15: 0.052676 | P15: =SUM(D15:O15) -> 0 | Q15: =IFERROR(P15/C15,0) -> 0
A16: 邮电通讯费 | B16: 快递费 | C16: 1.199174 | D16: 0.058103 | E16: 0.106604 | F16: 0.067006 | G16: 0.072104 | P16: =SUM(D16:O16) -> 0.303817 | Q16: =IFERROR(P16/C16,0) -> 0.25335523
A17: 公杂费 | B17: 公杂费 | C17: 0.808324 | E17: =0.034275+0.053585 -> 0.08786 | F17: 0.080855 | G17: 0.1319 | P17: =SUM(D17:O17) -> 0.300615 | Q17: =IFERROR(P17/C17,0) -> 0.37189914
A18: 办公用品 | B18: 办公用品 | C18: 0.078303 | P18: =SUM(D18:O18) -> 0 | Q18: =IFERROR(P18/C18,0) -> 0
A19: 技术服务费 | B19: 技术服务费 | C19: 14.150943 | P19: =SUM(D19:O19) -> 0 | Q19: =IFERROR(P19/C19,0) -> 0
A20: 品宣 | B20: 客户活动品牌宣传 | C20: 0 | P20: =SUM(D20:O20) -> 0 | Q20: =IFERROR(P20/C20,0) -> 0
A21: 其他 | B21: 暂估 | C21: 3 | P21: =SUM(D21:O21) -> 0 | Q21: =IFERROR(P21/C21,0) -> 0
A22: 合计 | C22: =SUM(C4:C21) -> 29.618318 | D22: =SUM(D4:D21) -> 1.062829 | E22: =SUM(E4:E21) -> 0.326128 | F22: =SUM(F4:F21) -> 0.263238 | G22: =SUM(G4:G21) -> 0.083796 | H22: =SUM(H4:H21) -> 0 | I22: =SUM(I4:I21) -> 0 | J22: =SUM(J4:J21) -> 0 | ... P22: =SUM(P4:P21) -> 1.735991 | Q22: =P22/C22 -> 0.058612072

Sheet 续期规模保费
A1: 续期规模保费 | P1: 返回目录
A2: 项目 | B2: 预算金额 | C2: 1月 | D2: 2月 | E2: 3月 | F2: 4月 | G2: 5月 | H2: 6月 | I2: 7月 | J2: 8月 | K2: 9月 | L2: 10月 | M2: 11月 | N2: 12月 | O2: 合计 | P2: 预算执行率
A3: 事业部续期规模保费 | B3: 1186.3158 | C3: 253.46045 | D3: 103.1159 | E3: 221.1255 | F3: 53.28264 | O3: =SUM(C3:N3) -> 630.98448 | P3: =O3/B3 -> 0.53188577
A4: 存续续期规模保费 | B4: 19642.846 | C4: 1804.8657 | D4: 997.92181 | E4: 1298.6574 | F4: 916.21903 | O4: =SUM(C4:N4) -> 5017.6639 | P4: =O4/B4 -> 0.25544485
A5: 小计 | B5: =SUM(B3:B4) -> 20829.162 | C5: =SUM(C3:C4) -> 2058.3262 | D5: =SUM(D3:D4) -> 1101.0377 | E5: =SUM(E3:E4) -> 1519.7829 | F5: =SUM(F3:F4) -> 969.50167 | G5: =SUM(G3:G4) -> 0 | H5: =SUM(H3:H4) -> 0 | I5: =SUM(I3:I4) -> 0 | ... N5: =SUM(N3:N4) -> 0 | O5: =SUM(C5:N5) -> 5648.6484 | P5: =O5/B5 -> 0.27118942

Sheet 退保损失
A1: 盛唐融信2026年退保汇总 | I1: 盛唐融信2025年退保汇总 | M1: 2024年退保损失汇总
A2: 保司 | B2: 退保总额 | C2: 占比 | I2: 保司 | J2: 退保总额 | K2: 占比 | M2: 保司 | N2: 性质 | O2: 小计 | P2: 占比
C3: =B3/$J$10 -> 0 | I3: 君康 | J3: 326739.85 | K3: =J3/$J$10 -> 0.58872155 | M3: 复星保德信 | N3: 协议退保 | O3: 9910.35 | P3: 0.018528743
C4: =B4/$J$10 -> 0 | I4: 爱心 | J4: 30848.46 | K4: =J4/$J$10 -> 0.055582915 | M4: 爱心人寿 | N4: 协议退保 | O4: 2852.27 | P4: 0.2390785
C5: =B5/$J$10 -> 0 | I5: 泰康 | J5: 5000 | K5: =J5/$J$10 -> 0.0090090259 | M5: 爱心人寿 | N5: 继续率损失 | O5: 125022.11
C6: =B6/$J$10 -> 0 | I6: 长城 | J6: 158058.99 | K6: =J6/$J$10 -> 0.28479151 | M6: 君康人寿 | N6: 协议退保 | O6: 323404.65 | P6: 0.60464885
C7: =B7/$J$10 -> 0 | I7: 恒安 | J7: 8960 | K7: =J7/$J$10 -> 0.016144174 | M7: 长城人寿 | N7: 继续率损失 | O7: 73674.2 | P7: 0.13774391
C8: =B8/$J$10 -> 0 | I8: 信泰 | J8: 488.68 | K8: =J8/$J$10 -> 0.00088050615 | M8: 合计 | O8: =SUM(O3:O7) -> 534863.58 | P8: =SUM(P3:P7) -> 1
C9: =B9/$J$10 -> 0 | I9: 中英 | J9: 24902.98 | K9: =J9/$J$10 -> 0.044870318
A10: 合计 | B10: =SUM(B3:B9) -> 0 | C10: =B10/$J$10 -> 0 | I10: 合计 | J10: =SUM(J3:J9) -> 554998.96 | K10: =J10/$J$10 -> 1
I12: 项目 | J12: 退保总额 | K12: 占比
I13: 继续率退保损失 | J13: 1922.44 | K13: =J13/$J$16 -> 0.0034638623
I14: 协议退保损失 | J14: 544240.77 | K14: =J14/$J$16 -> 0.98061584
I15: 利息赔偿损失 | J15: 8835.75 | K15: =J15/$J$16 -> 0.0159203
I16: 合计 | J16: =SUM(J13:J15) -> 554998.96 | K16: =J16/$J$16 -> 1

Sheet 应交税金
A1: 应交税金明细表 | F1: 返回目录
A2: 填报单位：盛唐融信保险代理（北京）有限公司 | C2: =应收账款明细表!C2 -> 填报日期：2026-5-8 | F2: 单位：元
A3: 明细 | B3: 期初余额 | C3: 本期借方 | D3: 本期贷方 | E3: 期末余额 | F3: 用途
A4: 应交税费-应交增值税-代扣代缴 | B4: =E4-D4 -> 1371790.9 | D4: 1085.15 | E4: 1372876.1
A5: 应交税费-城市维护建设税-代扣代缴 | B5: =E5-D5 -> 48012.69 | D5: 37.98 | E5: 48050.67
A6: 应交税费-教育费附加-代扣代缴 | B6: =E6-D6 -> 20576.9 | D6: 16.28 | E6: 20593.18
A7: 应交税费-地方教育税附加-代扣代缴 | B7: =E7-D7 -> 13718 | D7: 10.85 | E7: 13728.85
E8: =B8+C8-D8 -> 0
A10: 合计 | B10: =SUM(B4:B9) -> 1454098.5 | C10: =SUM(C4:C9) -> 0 | D10: =SUM(D4:D9) -> 1150.26 | E10: =SUM(E4:E9) -> 1455248.8
