Workbook

Sheet 指标统计
A1: 上海君康联杰企业管理有限公司2026年经营指标统计表
A2: 指标 | B2: 项目 | C2: 2026年预算 | D2: 2026年执行情况 | P2: 2026年实际 | Q2: 执行率 | R2: 指标说明
D3: 1月 | E3: 2月 | F3: 3月 | G3: 4月 | H3: 5月 | I3: 6月 | J3: 7月 | K3: 8月 | L3: 9月 | M3: 10月 | N3: 11月 | O3: 12月
A4: 经营指标 | B4: 营业收入 | C4: =预算执行汇总!B4 -> 0 | D4: {=预算执行汇总!C4:N4} -> 0 | E4: 0 | F4: 0 | G4: 0 | H4: 0 | I4: 0 | J4: 0 | K4: 0 | L4: 0 | M4: 0 | N4: 0 | O4: 0 | P4: =SUM(D4:O4) -> 0 | Q4: =IFERROR((P4-C4)/ABS(C4)+1,) -> 0
B5: EBITDA/GOP/扣非净利润 | C5: =预算执行汇总!B18 -> -257.58 | D5: =预算执行汇总!C18 -> -7.7495 | E5: -3.6 | F5: -9.03 | G5: -7.76 | P5: =SUM(D5:O5) -> -28.1395 | Q5: =IFERROR(P5/C5,) -> 0.10924567 | R5: EBITDA（商写适用）/GOP（酒店适用）/扣非净利润（保险中介适用）
B6: 经营活动净现金流 | C6: -230.07 | D6: -10.35 | E6: -4.57 | F6: 4.52 | G6: -6.63 | P6: =SUM(D6:O6) -> -17.03 | Q6: =IFERROR(P6/C6,) -> 0.07402095
A7: 财务指标 | B7: 经营支出小计 | C7: {=预算执行汇总!B5:B12} -> 173.68 | D7: {=预算执行汇总!C5:N12} -> 3.5245 | E7: 3.6045 | F7: 9.03 | G7: 3.53 | H7: 0 | I7: 0 | J7: 0 | K7: 0 | L7: 0 | M7: 0 | N7: 0 | O7: 0 | P7: =SUM(D7:O7) -> 19.689 | Q7: =IFERROR(P7/C7,) -> 0.11336366
B8: 固定费用 | C8: 173.68 | D8: 3.5245 | E8: 3.6045 | F8: 9.03 | G8: 3.53 | H8: 0 | I8: 0 | J8: 0 | K8: 0 | L8: 0 | M8: 0 | N8: 0 | O8: 0 | P8: =SUM(D8:O8) -> 19.689 | Q8: =IFERROR(P8/C8,) -> 0.11336366
B9: 人力费用 | C9: 42.48 | D9: 3.5245 | E9: 3.6045 | F9: 3.35 | G9: 3.41 | H9: 0 | I9: 0 | J9: 0 | K9: 0 | L9: 0 | M9: 0 | N9: 0 | O9: 0 | P9: =SUM(D9:O9) -> 13.889 | Q9: =IFERROR(P9/C9,) -> 0.32695386
B10: 日常费用 | C10: 131.2 | D10: 0 | E10: 0 | F10: 5.68 | G10: 0.12 | H10: 0 | I10: 0 | J10: 0 | K10: 0 | L10: 0 | M10: 0 | N10: 0 | O10: 0 | P10: =SUM(D10:O10) -> 5.8 | Q10: =IFERROR(P10/C10,) -> 0.044207317
B11: 变动费用 | C11: 0 | D11: 0 | E11: 0 | F11: 0 | G11: 0 | H11: 0 | I11: 0 | J11: 0 | K11: 0 | L11: 0 | M11: 0 | N11: 0 | O11: 0 | P11: =SUM(D11:O11) -> 0 | Q11: =IFERROR(P11/C11,) -> 0
B12: 经营变动费用 | C12: 0 | D12: 0 | E12: 0 | F12: 0 | G12: 0 | H12: 0 | I12: 0 | J12: 0 | K12: 0 | L12: 0 | M12: 0 | N12: 0 | O12: 0 | P12: =SUM(D12:O12) -> 0 | Q12: =IFERROR(P12/C12,) -> 0
B13: 营业成本 | C13: 0 | D13: 0 | E13: 0 | F13: 0 | G13: 0 | H13: 0 | I13: 0 | J13: 0 | K13: 0 | L13: 0 | M13: 0 | N13: 0 | O13: 0 | P13: =SUM(D13:O13) -> 0 | Q13: =IFERROR(P13/C13,) -> 0
B14: 资本性支出 | C14: 0 | D14: 0 | E14: 0 | F14: 0 | G14: 0 | H14: 0 | I14: 0 | J14: 0 | K14: 0 | L14: 0 | M14: 0 | N14: 0 | O14: 0 | P14: =SUM(D14:O14) -> 0 | Q14: =IFERROR(P14/C14,) -> 0
A15: 业务指标 | B15: 期末出租率/月均入住率 | P15: =IFERROR(AVERAGE(D15:O15),) -> 0 | Q15: =IFERROR(P15/C15,) -> 0 | R15: 期末出租率(商写适用)/月均入住率(酒店适用)
B16: 回款率 | P16: =IFERROR(AVERAGE(D16:O16),) -> 0 | Q16: =IFERROR(P16/C16,) -> 0 | R16: 商写及酒店适用
B17: OTA网络评价 | P17: {=IFERROR(INDEX(D17:O17,0,MATCH(9.99999999999999E+307,D17:O17)),)} -> 0 | Q17: =IFERROR(P17/C17,) -> 0 | R17: 酒店适用
B18: 期交规保 | P18: {=IFERROR(INDEX(D18:O18,0,MATCH(9.99999999999999E+307,D18:O18)),)} -> 0 | Q18: =IFERROR(P18/C18,) -> 0 | R18: 保险中介适用
B19: 13月继续率 | P19: {=IFERROR(INDEX(D19:O19,0,MATCH(9.99999999999999E+307,D19:O19)),)} -> 0 | Q19: =IFERROR(P19/C19,) -> 0 | R19: 保险中介适用
B20: 25月继续率 | P20: {=IFERROR(INDEX(D20:O20,0,MATCH(9.99999999999999E+307,D20:O20)),)} -> 0 | Q20: =IFERROR(P20/C20,) -> 0 | R20: 保险中介适用
A21: 备注 | B21: EBITDA=营业收入-固定费用-变动费用-税金及附加
B22: GOP=营业收入-固定费用-变动费用-财务费用（不含利息费用）
B23: 需填列单元格

Sheet 预算执行汇总
A1: 上海君康联杰企业管理有限公司2026年预算执行情况汇总表
A2: 项目 | B2: 2026年预算 | C2: 2026年执行情况 | O2: 2026年实际 | P2: 执行率
C3: 1月 | D3: 2月 | E3: 3月 | F3: 4月 | G3: 5月 | H3: 6月 | I3: 7月 | J3: 8月 | K3: 9月 | L3: 10月 | M3: 11月 | N3: 12月
A4: 营业收入 | B4: 0 | C4: 0 | D4: 0 | E4: 0 | F4: 0 | G4: 0 | H4: 0 | I4: 0 | J4: 0 | K4: 0 | L4: 0 | M4: 0 | N4: 0 | O4: =SUM(C4:N4) -> 0 | P4: =IFERROR(O4/B4,) -> 0
A5: 经营支出小计 | B5: =B6+B9 -> 173.68 | C5: =C6+C9 -> 3.5245 | D5: =D6+D9 -> 3.6045 | E5: =E6+E9 -> 9.03 | F5: =F6+F9 -> 3.53 | G5: =G6+G9 -> 0 | H5: =H6+H9 -> 0 | I5: =I6+I9 -> 0 | ... N5: =N6+N9 -> 0 | O5: =SUM(C5:N5) -> 19.689 | P5: =IFERROR(O5/B5,) -> 0.11336366
A6: 固定费用 | B6: =费用预算执行明细!B4 -> 173.68 | C6: =费用预算执行明细!C4 -> 3.5245 | D6: =费用预算执行明细!D4 -> 3.6045 | E6: =费用预算执行明细!E4 -> 9.03 | F6: =费用预算执行明细!F4 -> 3.53 | G6: =费用预算执行明细!G4 -> 0 | H6: =费用预算执行明细!H4 -> 0 | I6: =费用预算执行明细!I4 -> 0 | ... N6: =费用预算执行明细!N4 -> 0 | O6: =SUM(C6:N6) -> 19.689 | P6: =IFERROR(O6/B6,) -> 0.11336366
A7: 人力费用 | B7: =费用预算执行明细!B5 -> 42.48 | C7: =费用预算执行明细!C5 -> 3.5245 | D7: =费用预算执行明细!D5 -> 3.6045 | E7: =费用预算执行明细!E5 -> 3.35 | F7: =费用预算执行明细!F5 -> 3.41 | G7: =费用预算执行明细!G5 -> 0 | H7: =费用预算执行明细!H5 -> 0 | I7: =费用预算执行明细!I5 -> 0 | ... N7: =费用预算执行明细!N5 -> 0 | O7: =SUM(C7:N7) -> 13.889 | P7: =IFERROR(O7/B7,) -> 0.32695386
A8: 日常费用 | B8: =费用预算执行明细!B12 -> 131.2 | C8: =费用预算执行明细!C12 -> 0 | D8: =费用预算执行明细!D12 -> 0 | E8: =费用预算执行明细!E12 -> 5.68 | F8: =费用预算执行明细!F12 -> 0.12 | G8: =费用预算执行明细!G12 -> 0 | H8: =费用预算执行明细!H12 -> 0 | I8: =费用预算执行明细!I12 -> 0 | ... N8: =费用预算执行明细!N12 -> 0 | O8: =SUM(C8:N8) -> 5.8 | P8: =IFERROR(O8/B8,) -> 0.044207317
A9: 变动费用 | C9: =费用预算执行明细!C44 -> 0 | D9: =费用预算执行明细!D44 -> 0 | E9: =费用预算执行明细!E44 -> 0 | F9: =费用预算执行明细!F44 -> 0 | G9: =费用预算执行明细!G44 -> 0 | H9: =费用预算执行明细!H44 -> 0 | I9: =费用预算执行明细!I44 -> 0 | J9: =费用预算执行明细!J44 -> 0 | ... N9: =费用预算执行明细!N44 -> 0 | O9: =SUM(C9:N9) -> 0 | P9: =IFERROR(O9/B9,) -> 0
A10: 经营变动费用支出 | C10: =费用预算执行明细!C45 -> 0 | D10: =费用预算执行明细!D45 -> 0 | E10: =费用预算执行明细!E45 -> 0 | F10: =费用预算执行明细!F45 -> 0 | G10: =费用预算执行明细!G45 -> 0 | H10: =费用预算执行明细!H45 -> 0 | I10: =费用预算执行明细!I45 -> 0 | J10: =费用预算执行明细!J45 -> 0 | ... N10: =费用预算执行明细!N45 -> 0 | O10: =SUM(C10:N10) -> 0 | P10: =IFERROR(O10/B10,) -> 0
A11: 营业成本支出 | C11: =费用预算执行明细!C78 -> 0 | D11: =费用预算执行明细!D78 -> 0 | E11: =费用预算执行明细!E78 -> 0 | F11: =费用预算执行明细!F78 -> 0 | G11: =费用预算执行明细!G78 -> 0 | H11: =费用预算执行明细!H78 -> 0 | I11: =费用预算执行明细!I78 -> 0 | J11: =费用预算执行明细!J78 -> 0 | ... N11: =费用预算执行明细!N78 -> 0 | O11: =SUM(C11:N11) -> 0 | P11: =IFERROR(O11/B11,) -> 0
A12: 资本性支出 | O12: =SUM(C12:N12) -> 0 | P12: =IFERROR(O12/B12,) -> 0
A13: 折旧摊销 | B13: 0 | O13: =SUM(C13:N13) -> 0 | P13: =IFERROR(O13/B13,) -> 0
A14: 财务费用 | B14: -34.6 | C14: 0.02 | D14: 0.32 | E14: -14.34 | F14: 0 | O14: =SUM(C14:N14) -> -14 | P14: =IFERROR(O14/B14,) -> 0.40462428
A15: 税金及附加 | B15: 83.9 | C15: 4.225 | D15: 0 | E15: 0 | F15: 4.23 | O15: =SUM(C15:N15) -> 8.455 | P15: =IFERROR(O15/B15,) -> 0.10077473
A16: 变动费用率 | C16: =IFERROR(C9/C4,) -> 0 | D16: =IFERROR(D9/D4,) -> 0 | E16: =IFERROR(E9/E4,) -> 0 | F16: =IFERROR(F9/F4,) -> 0 | G16: =IFERROR(G9/G4,) -> 0 | H16: =IFERROR(H9/H4,) -> 0 | I16: =IFERROR(I9/I4,) -> 0 | J16: =IFERROR(J9/J4,) -> 0 | ... O16: =IFERROR(O9/O4,) -> 0 | P16: =IFERROR(O16/B16,) -> 0
A18: EBITDA | B18: =B4-B6-B9-B15 -> -257.58 | C18: =C4-C6-C9-C15 -> -7.7495 | D18: =D4-D6-D9-D15 -> -3.6045 | E18: =E4-E6-E9-E15 -> -9.03 | F18: =F4-F6-F9-F15 -> -7.76 | G18: =G4-G6-G9-G15 -> 0 | H18: =H4-H6-H9-H15 -> 0 | I18: =I4-I6-I9-I15 -> 0 | ... O18: =O4-O6-O9-O15 -> -28.144 | P18: =IFERROR(O18/B18,) -> 0.10926314
A19: GOP | B19: =B4-B6-B9-B14 -> -139.08 | C19: =C4-C6-C9-C14 -> -3.5445 | D19: =D4-D6-D9-D14 -> -3.9245 | E19: =E4-E6-E9-E14 -> 5.31 | F19: =F4-F6-F9-F14 -> -3.53 | G19: =G4-G6-G9-G14 -> 0 | H19: =H4-H6-H9-H14 -> 0 | I19: =I4-I6-I9-I14 -> 0 | ... O19: =O4-O6-O9-O14 -> -5.689 | P19: =IFERROR(O19/B19,) -> 0.040904515
A21: 备注 | B21: EBITDA=营业收入-固定费用-变动费用-税金及附加
B22: GOP=营业收入-固定费用-变动费用-财务费用（不含利息费用）
B23: 需填列单元格

Sheet 费用预算执行明细
A1: 上海君康联杰企业管理有限公司2026年预算执行情况明细表
A2: 项目 | B2: 2026年预算 | C2: 2026年预算执行情况 | O2: 2026年实际 | P2: 执行率
C3: 1月 | D3: 2月 | E3: 3月 | F3: 4月 | G3: 5月 | H3: 6月 | I3: 7月 | J3: 8月 | K3: 9月 | L3: 10月 | M3: 11月 | N3: 12月
A4: 固定费用 | B4: =B5+B12 -> 173.68 | C4: =C5+C12 -> 3.5245 | D4: =D5+D12 -> 3.6045 | E4: =E5+E12 -> 9.03 | F4: =F5+F12 -> 3.53 | G4: =G5+G12 -> 0 | H4: =H5+H12 -> 0 | I4: =I5+I12 -> 0 | ... N4: =N5+N12 -> 0 | O4: =SUM(C4:N4) -> 19.689 | P4: =IFERROR(O4/B4,) -> 0.11336366
A5: 人力费用合计 | B5: =SUM(B6:B11) -> 42.48 | C5: =SUM(C6:C11) -> 3.5245 | D5: =SUM(D6:D11) -> 3.6045 | E5: =SUM(E6:E11) -> 3.35 | F5: =SUM(F6:F11) -> 3.41 | G5: =SUM(G6:G11) -> 0 | H5: =SUM(H6:H11) -> 0 | I5: =SUM(I6:I11) -> 0 | ... N5: =SUM(N6:N11) -> 0 | O5: =SUM(C5:N5) -> 13.889 | P5: =IFERROR(O5/B5,) -> 0.32695386
A6: 固定工资 | B6: 31.08 | C6: 2.64 | D6: 2.72 | E6: 2.47 | F6: 2.53 | O6: =SUM(C6:N6) -> 10.36 | P6: =IFERROR(O6/B6,) -> 0.33333333
A7: 绩效工资 | O7: =SUM(C7:N7) -> 0 | P7: =IFERROR(O7/B7,) -> 0
A8: 奖金 | O8: =SUM(C8:N8) -> 0 | P8: =IFERROR(O8/B8,) -> 0
A9: 福利费 | O9: =SUM(C9:N9) -> 0 | P9: =IFERROR(O9/B9,) -> 0
A10: 社会保险费 | B10: 9 | C10: 0.6945 | D10: 0.6945 | E10: 0.69 | F10: 0.69 | O10: =SUM(C10:N10) -> 2.769 | P10: =IFERROR(O10/B10,) -> 0.30766667
A11: 住房公积金 | B11: 2.4 | C11: 0.19 | D11: 0.19 | E11: 0.19 | F11: 0.19 | O11: =SUM(C11:N11) -> 0.76 | P11: =IFERROR(O11/B11,) -> 0.31666667
A12: 固定费用支出合计 | B12: =SUM(B13:B43) -> 131.2 | C12: =SUM(C13:C43) -> 0 | D12: =SUM(D13:D43) -> 0 | E12: =SUM(E13:E43) -> 5.68 | F12: =SUM(F13:F43) -> 0.12 | G12: =SUM(G13:G43) -> 0 | H12: =SUM(H13:H43) -> 0 | I12: =SUM(I13:I43) -> 0 | ... N12: =SUM(N13:N43) -> 0 | O12: =SUM(C12:N12) -> 5.8 | P12: =IFERROR(O12/B12,) -> 0.044207317
A13: 邮寄费 | O13: =SUM(C13:N13) -> 0 | P13: =IFERROR(O13/B13,) -> 0
A14: 差旅费 | B14: 1 | C14: 0 | D14: 0 | E14: 0 | F14: 0 | O14: =SUM(C14:N14) -> 0 | P14: =IFERROR(O14/B14,) -> 0
A15: 业务招待费 | B15: 4 | C15: 0 | D15: 0 | E15: 0 | F15: 0.12 | O15: =SUM(C15:N15) -> 0.12 | P15: =IFERROR(O15/B15,) -> 0.03
A16: 汽车费 | O16: =SUM(C16:N16) -> 0 | P16: =IFERROR(O16/B16,) -> 0
A17: 低值易耗品及修理费 | O17: =SUM(C17:N17) -> 0 | P17: =IFERROR(O17/B17,) -> 0
A18: 信息系统费 | O18: =SUM(C18:N18) -> 0 | P18: =IFERROR(O18/B18,) -> 0
A19: 通讯费 | O19: =SUM(C19:N19) -> 0 | P19: =IFERROR(O19/B19,) -> 0
A20: 交通费 | B20: 0.1 | C20: 0 | D20: 0 | E20: 0 | F20: 0 | O20: =SUM(C20:N20) -> 0 | P20: =IFERROR(O20/B20,) -> 0
A21: 办公费 | B21: 0.1 | C21: 0 | D21: 0 | E21: 0.01 | F21: 0 | O21: =SUM(C21:N21) -> 0.01 | P21: =IFERROR(O21/B21,) -> 0.1
A22: 会议费 | B22: 3 | C22: 0 | D22: 0 | E22: 0 | F22: 0 | O22: =SUM(C22:N22) -> 0 | P22: =IFERROR(O22/B22,) -> 0
A23: 水电费 | O23: =SUM(C23:N23) -> 0 | P23: =IFERROR(O23/B23,) -> 0
A24: 招聘费 | O24: =SUM(C24:N24) -> 0 | P24: =IFERROR(O24/B24,) -> 0
A25: 展览费 | O25: =SUM(C25:N25) -> 0 | P25: =IFERROR(O25/B25,) -> 0
A26: 广告宣传费 | O26: =SUM(C26:N26) -> 0 | P26: =IFERROR(O26/B26,) -> 0
A27: 咨询服务费 | B27: 13 | C27: 0 | D27: 0 | E27: 5.67 | F27: 0 | O27: =SUM(C27:N27) -> 5.67 | P27: =IFERROR(O27/B27,) -> 0.43615385
A28: 法律诉讼费 | B28: 110 | C28: 0 | D28: 0 | E28: 0 | F28: 0 | O28: =SUM(C28:N28) -> 0 | P28: =IFERROR(O28/B28,) -> 0
A29: 工作餐费 | O29: =SUM(C29:N29) -> 0 | P29: =IFERROR(O29/B29,) -> 0
A30: 报关及代理费 | O30: =SUM(C30:N30) -> 0 | P30: =IFERROR(O30/B30,) -> 0
A31: 研究开发费 | O31: =SUM(C31:N31) -> 0 | P31: =IFERROR(O31/B31,) -> 0
A32: 质检认证费 | O32: =SUM(C32:N32) -> 0 | P32: =IFERROR(O32/B32,) -> 0
A33: 排污费 | O33: =SUM(C33:N33) -> 0 | P33: =IFERROR(O33/B33,) -> 0
A34: 社保服务费 | O34: =SUM(C34:N34) -> 0 | P34: =IFERROR(O34/B34,) -> 0
A35: 劳动保护费 | O35: =SUM(C35:N35) -> 0 | P35: =IFERROR(O35/B35,) -> 0
A36: 残疾人就业保障金 | O36: =SUM(C36:N36) -> 0 | P36: =IFERROR(O36/B36,) -> 0
A37: 财产保险费 | O37: =SUM(C37:N37) -> 0 | P37: =IFERROR(O37/B37,) -> 0
A38: 房租及物业费 | O38: =SUM(C38:N38) -> 0 | P38: =IFERROR(O38/B38,) -> 0
A39: 开办费 | O39: =SUM(C39:N39) -> 0 | P39: =IFERROR(O39/B39,) -> 0
A40: 存货盘存 | O40: =SUM(C40:N40) -> 0 | P40: =IFERROR(O40/B40,) -> 0
...

Sheet 开发支出预算执行明细
A1: 上海君康联杰企业管理有限公司2026年预算执行情况明细表
A2: 项目 | B2: 2026年预算 | C2: 2026年预算执行情况 | O2: 2026年实际 | P2: 执行率
C3: 1月 | D3: 2月 | E3: 3月 | F3: 4月 | G3: 5月 | H3: 6月 | I3: 7月 | J3: 8月 | K3: 9月 | L3: 10月 | M3: 11月 | N3: 12月
A4: 变动费用支出合计 | B4: =SUM(B5:B8) -> 2590.23 | C4: =SUM(C5:C8) -> 0 | D4: =SUM(D5:D8) -> 0.48 | E4: =SUM(E5:E8) -> 0.97 | F4: =SUM(F5:F8) -> 0.38 | G4: =SUM(G5:G8) -> 0 | H4: =SUM(H5:H8) -> 0 | I4: =SUM(I5:I8) -> 0 | ... N4: =SUM(N5:N8) -> 0 | O4: =SUM(C4:N4) -> 1.83 | P4: =O4/B4 -> 0.00070650097
A5: 水电费 | B5: 10 | C5: 0 | D5: 0.48 | E5: 0.97 | F5: 0.38 | O5: =SUM(C5:N5) -> 1.83 | P5: =O5/B5 -> 0.183
A6: 安保费用 | B6: 200 | C6: 0 | D6: 0 | E6: 0 | F6: 0 | O6: =SUM(C6:N6) -> 0 | P6: =O6/B6 -> 0
A7: 维护清理费用 | B7: 200 | C7: 0 | D7: 0 | E7: 0 | F7: 0 | O7: =SUM(C7:N7) -> 0 | P7: =O7/B7 -> 0
A8: 以前年度合同支出 | B8: 2180.23 | C8: 0 | D8: 0 | E8: 0 | F8: 0 | O8: =SUM(C8:N8) -> 0 | P8: =O8/B8 -> 0
B11: 需填列

Sheet 资本性支出计划与执行
A1: 上海君康联杰企业管理有限公司2026年资本性支出执行情况明细表
A2: 资产类别 | B2: 资产类型 | C2: 资产名称 | D2: 数量 | E2: 单价 | F2: 金额 | G2: 2026年预算 | H2: 2026年实际
A3: 固定资产 | B3: 家具用具 | H3: =F3 -> 0
H4: =F4 -> 0
H5: =F5 -> 0
H6: =F6 -> 0
H7: =F7 -> 0
H8: =F8 -> 0
H9: =F9 -> 0
H10: =F10 -> 0
H11: =F11 -> 0
H12: =F12 -> 0
A15: 资本性支出合计 | G15: =SUM(G3:G14) -> 0 | H15: =SUM(H3:H14) -> 0
A17: 需填列
