Workbook

Sheet 指标统计
A1: 瑞尔酒店公司2026年经营指标统计表
A2: 指标 | B2: 项目 | C2: 2026年预算 | D2: 2026年执行情况 | P2: 2026年实际 | Q2: 执行率 | R2: 指标说明
D3: 1月 | E3: 2月 | F3: 3月 | G3: 4月 | H3: 5月 | I3: 6月 | J3: 7月 | K3: 8月 | L3: 9月 | M3: 10月 | N3: 11月 | O3: 12月
A4: 经营指标 | B4: 营业收入 | C4: =预算执行汇总!B4 -> 1454.9973 | D4: {=预算执行汇总!C4:N4} -> 78.97726 | E4: 63.822824 | F4: 80.56083 | G4: 96.956248 | H4: 0 | I4: 0 | J4: 0 | K4: 0 | L4: 0 | M4: 0 | N4: 0 | O4: 0 | P4: =SUM(D4:O4) -> 320.31716 | Q4: =IFERROR((P4-C4)/ABS(C4)+1,) -> 0.22014967
B5: EBITDA/GOP/扣非净利润 | C5: =预算执行汇总!B19 -> -55.516737 | D5: =预算执行汇总!C19 -> -52.776259 | E5: =预算执行汇总!D19 -> -38.670642 | F5: =预算执行汇总!E19 -> -1.727057 | G5: =预算执行汇总!F19 -> -13.573026 | H5: =预算执行汇总!G19 -> 0 | I5: =预算执行汇总!H19 -> 0 | J5: =预算执行汇总!I19 -> 0 | ... O5: =预算执行汇总!N19 -> 0 | P5: =SUM(D5:O5) -> -106.74698 | Q5: =IFERROR(P5/C5,) -> 1.9227892 | R5: EBITDA（商写适用）/GOP（酒店适用）/扣非净利润（保险中介适用）
B6: 经营活动净现金流 | C6: -178.55007 | D6: -59.297686 | E6: -47.233397 | F6: -17.259462 | G6: -90.647837 | P6: =SUM(D6:O6) -> -214.43838 | Q6: =IFERROR(P6/C6,) -> 1.2009986
A7: 财务指标 | B7: 经营支出小计 | C7: {=预算执行汇总!B5:B12} -> 1518.434 | D7: {=预算执行汇总!C5:N12} -> 131.62255 | E7: 102.38878 | F7: 82.703909 | G7: 110.36911 | H7: 0 | I7: 0 | J7: 0 | K7: 0 | L7: 0 | M7: 0 | N7: 0 | O7: 0 | P7: =SUM(D7:O7) -> 427.08434 | Q7: =IFERROR(P7/C7,) -> 0.28126632
B8: 固定费用 | C8: 793.4447 | D8: 82.740795 | E8: 54.661567 | F8: 41.604384 | G8: 62.007687 | H8: 0 | I8: 0 | J8: 0 | K8: 0 | L8: 0 | M8: 0 | N8: 0 | O8: 0 | P8: =SUM(D8:O8) -> 241.01443 | Q8: =IFERROR(P8/C8,) -> 0.30375706
B9: 人力费用 | C9: 693.56 | D9: 77.910641 | E9: 52.070162 | F9: 46.482044 | G9: 47.60297 | H9: 0 | I9: 0 | J9: 0 | K9: 0 | L9: 0 | M9: 0 | N9: 0 | O9: 0 | P9: =SUM(D9:O9) -> 224.06582 | Q9: =IFERROR(P9/C9,) -> 0.32306623
B10: 日常费用 | C10: 99.8847 | D10: 4.830154 | E10: 2.591405 | F10: -4.87766 | G10: 14.404717 | H10: 0 | I10: 0 | J10: 0 | K10: 0 | L10: 0 | M10: 0 | N10: 0 | O10: 0 | P10: =SUM(D10:O10) -> 16.948616 | Q10: =IFERROR(P10/C10,) -> 0.1696818
B11: 变动费用 | C11: 724.9893 | D11: 48.881752 | E11: 47.727211 | F11: 41.099525 | G11: 48.361423 | H11: 0 | I11: 0 | J11: 0 | K11: 0 | L11: 0 | M11: 0 | N11: 0 | O11: 0 | P11: =SUM(D11:O11) -> 186.06991 | Q11: =IFERROR(P11/C11,) -> 0.25665194
B12: 经营变动费用 | C12: 225.42 | D12: 14.661237 | E12: 17.69237 | F12: 15.084433 | G12: 20.184048 | H12: 0 | I12: 0 | J12: 0 | K12: 0 | L12: 0 | M12: 0 | N12: 0 | O12: 0 | P12: =SUM(D12:O12) -> 67.622088 | Q12: =IFERROR(P12/C12,) -> 0.29998265
B13: 营业成本 | C13: 499.5693 | D13: 34.220515 | E13: 30.034841 | F13: 26.015092 | G13: 28.177375 | H13: 0 | I13: 0 | J13: 0 | K13: 0 | L13: 0 | M13: 0 | N13: 0 | O13: 0 | P13: =SUM(D13:O13) -> 118.44782 | Q13: =IFERROR(P13/C13,) -> 0.23709988
B14: 资本性支出 | C14: 153.94 | D14: 0 | E14: 0 | F14: 0 | G14: 0 | H14: 0 | I14: 0 | J14: 0 | K14: 0 | L14: 0 | M14: 0 | N14: 0 | O14: 0 | P14: =SUM(D14:O14) -> 0 | Q14: =IFERROR(P14/C14,) -> 0
A15: 业务指标 | B15: 期末出租率/月均入住率 | C15: 0.71 | D15: 0.41286389 | E15: 0.31946864 | F15: 0.59343037 | G15: 0.74512195 | P15: =IFERROR(AVERAGE(D15:O15),) -> 0.51772121 | Q15: =IFERROR(P15/C15,) -> 0.72918481 | R15: 期末出租率(商写适用)/月均入住率(酒店适用)
B16: 回款率 | C16: 0.98 | D16: 0.97824235 | E16: 0.94651203 | F16: 0.89600247 | G16: 0.91666599 | P16: =IFERROR(AVERAGE(D16:O16),) -> 0.93435571 | Q16: =IFERROR(P16/C16,) -> 0.95342419 | R16: 商写及酒店适用
B17: OTA网络评价 | C17: 4.7 | D17: 4.7 | E17: 4.7 | F17: 4.7 | G17: 4.7 | P17: {=IFERROR(INDEX(D17:O17,0,MATCH(9.99999999999999E+307,D17:O17)),)} -> 4.7 | Q17: =IFERROR(P17/C17,) -> 1 | R17: 酒店适用
B18: 期交规保 | P18: {=IFERROR(INDEX(D18:O18,0,MATCH(9.99999999999999E+307,D18:O18)),)} -> 0 | Q18: =IFERROR(P18/C18,) -> 0 | R18: 保险中介适用
B19: 13月继续率 | P19: {=IFERROR(INDEX(D19:O19,0,MATCH(9.99999999999999E+307,D19:O19)),)} -> 0 | Q19: =IFERROR(P19/C19,) -> 0 | R19: 保险中介适用
B20: 25月继续率 | P20: {=IFERROR(INDEX(D20:O20,0,MATCH(9.99999999999999E+307,D20:O20)),)} -> 0 | Q20: =IFERROR(P20/C20,) -> 0 | R20: 保险中介适用
A21: 备注 | B21: EBITDA=营业收入-固定费用-变动费用-税金及附加
B22: GOP=营业收入-固定费用-变动费用-财务费用（不含利息费用）
B23: 需填列单元格

Sheet 预算执行汇总
A1: 瑞尔酒店公司2026年预算执行情况汇总表
A2: 项目 | B2: 2026年预算 | C2: 2026年执行情况 | O2: 2026年实际 | P2: 执行率
C3: 1月 | D3: 2月 | E3: 3月 | F3: 4月 | G3: 5月 | H3: 6月 | I3: 7月 | J3: 8月 | K3: 9月 | L3: 10月 | M3: 11月 | N3: 12月
A4: 营业收入 | B4: 1454.9973 | C4: 78.97726 | D4: 63.822824 | E4: 80.56083 | F4: 96.956248 | O4: =SUM(C4:N4) -> 320.31716 | P4: =IFERROR(O4/B4,) -> 0.22014967
A5: 经营支出小计 | B5: =B6+B9 -> 1518.434 | C5: =C6+C9 -> 131.62255 | D5: =D6+D9 -> 102.38878 | E5: =E6+E9 -> 82.703909 | F5: =F6+F9 -> 110.36911 | G5: =G6+G9 -> 0 | H5: =H6+H9 -> 0 | I5: =I6+I9 -> 0 | ... N5: =N6+N9 -> 0 | O5: =SUM(C5:N5) -> 427.08434 | P5: =IFERROR(O5/B5,) -> 0.28126632
A6: 固定费用 | B6: =费用预算执行明细!B4 -> 793.4447 | C6: =费用预算执行明细!C4 -> 82.740795 | D6: =费用预算执行明细!D4 -> 54.661567 | E6: =费用预算执行明细!E4 -> 41.604384 | F6: =费用预算执行明细!F4 -> 62.007687 | G6: =费用预算执行明细!G4 -> 0 | H6: =费用预算执行明细!H4 -> 0 | I6: =费用预算执行明细!I4 -> 0 | ... N6: =费用预算执行明细!N4 -> 0 | O6: =SUM(C6:N6) -> 241.01443 | P6: =IFERROR(O6/B6,) -> 0.30375706
A7: 人力费用 | B7: =费用预算执行明细!B5 -> 693.56 | C7: =费用预算执行明细!C5 -> 77.910641 | D7: =费用预算执行明细!D5 -> 52.070162 | E7: =费用预算执行明细!E5 -> 46.482044 | F7: =费用预算执行明细!F5 -> 47.60297 | G7: =费用预算执行明细!G5 -> 0 | H7: =费用预算执行明细!H5 -> 0 | I7: =费用预算执行明细!I5 -> 0 | ... N7: =费用预算执行明细!N5 -> 0 | O7: =SUM(C7:N7) -> 224.06582 | P7: =IFERROR(O7/B7,) -> 0.32306623
A8: 日常费用 | B8: =费用预算执行明细!B13 -> 99.8847 | C8: =费用预算执行明细!C13 -> 4.830154 | D8: =费用预算执行明细!D13 -> 2.591405 | E8: =费用预算执行明细!E13 -> -4.87766 | F8: =费用预算执行明细!F13 -> 14.404717 | G8: =费用预算执行明细!G13 -> 0 | H8: =费用预算执行明细!H13 -> 0 | I8: =费用预算执行明细!I13 -> 0 | ... N8: =费用预算执行明细!N13 -> 0 | O8: =SUM(C8:N8) -> 16.948616 | P8: =IFERROR(O8/B8,) -> 0.1696818
A9: 变动费用 | B9: =费用预算执行明细!B46 -> 724.9893 | C9: =费用预算执行明细!C46 -> 48.881752 | D9: =费用预算执行明细!D46 -> 47.727211 | E9: =费用预算执行明细!E46 -> 41.099525 | F9: =费用预算执行明细!F46 -> 48.361423 | G9: =费用预算执行明细!G46 -> 0 | H9: =费用预算执行明细!H46 -> 0 | I9: =费用预算执行明细!I46 -> 0 | ... N9: =费用预算执行明细!N46 -> 0 | O9: =SUM(C9:N9) -> 186.06991 | P9: =IFERROR(O9/B9,) -> 0.25665194
A10: 经营变动费用支出 | B10: =费用预算执行明细!B47 -> 225.42 | C10: =费用预算执行明细!C47 -> 14.661237 | D10: =费用预算执行明细!D47 -> 17.69237 | E10: =费用预算执行明细!E47 -> 15.084433 | F10: =费用预算执行明细!F47 -> 20.184048 | G10: =费用预算执行明细!G47 -> 0 | H10: =费用预算执行明细!H47 -> 0 | I10: =费用预算执行明细!I47 -> 0 | ... N10: =费用预算执行明细!N47 -> 0 | O10: =SUM(C10:N10) -> 67.622088 | P10: =IFERROR(O10/B10,) -> 0.29998265
A11: 营业成本支出 | B11: =费用预算执行明细!B82 -> 499.5693 | C11: =费用预算执行明细!C82 -> 34.220515 | D11: =费用预算执行明细!D82 -> 30.034841 | E11: =费用预算执行明细!E82 -> 26.015092 | F11: =费用预算执行明细!F82 -> 28.177375 | G11: =费用预算执行明细!G82 -> 0 | H11: =费用预算执行明细!H82 -> 0 | I11: =费用预算执行明细!I82 -> 0 | ... N11: =费用预算执行明细!N82 -> 0 | O11: =SUM(C11:N11) -> 118.44782 | P11: =IFERROR(O11/B11,) -> 0.23709988
A12: 资本性支出 | B12: 153.94 | C12: 0 | D12: 0 | E12: 0 | F12: 0 | O12: =SUM(C12:N12) -> 0 | P12: =IFERROR(O12/B12,) -> 0
A13: 折旧摊销 | B13: 774.79 | C13: 64.720281 | D13: 64.716896 | E13: 64.716896 | F13: 64.716896 | O13: =SUM(C13:N13) -> 258.87097 | P13: =IFERROR(O13/B13,) -> 0.33411759
A14: 财务费用 | B14: -0.92 | C14: 0.130972 | D14: 0.104688 | E14: -0.416022 | F14: 0.160164 | O14: =SUM(C14:N14) -> -0.020198 | P14: =IFERROR(O14/B14,) -> 0.021954348
A15: 税金及附加 | B15: 179.7629 | C15: 0.10334 | D15: 0 | E15: 0.27608 | F15: 87.951979 | O15: =SUM(C15:N15) -> 88.331399 | P15: =IFERROR(O15/B15,) -> 0.49137726
A16: 变动费用率 | B16: =IFERROR(B9/B4,) -> 0.49827537 | C16: =IFERROR(C9/C4,) -> 0.61893451 | D16: =IFERROR(D9/D4,) -> 0.74780788 | E16: =IFERROR(E9/E4,) -> 0.5101676 | F16: =IFERROR(F9/F4,) -> 0.49879635 | G16: =IFERROR(G9/G4,) -> 0 | H16: =IFERROR(H9/H4,) -> 0 | I16: =IFERROR(I9/I4,) -> 0 | ... O16: =IFERROR(O9/O4,) -> 0.58089273
A18: EBITDA | B18: =B4-B6-B9-B15+3.6+7 -> -232.59963 | C18: =C4-C6-C9-C15 -> -52.748627 | D18: =D4-D6-D9-D15 -> -38.565954 | E18: =E4-E6-E9-E15 -> -2.419159 | F18: =F4-F6-F9-F15 -> -101.36484 | G18: =G4-G6-G9-G15 -> 0 | H18: =H4-H6-H9-H15 -> 0 | I18: =I4-I6-I9-I15 -> 0 | J18: =J4-J6-J9-J15 -> 0 | ... O18: =O4-O6-O9-O15 -> -195.09858 | P18: =IFERROR(O18/B18,) -> 0.83877424
A19: GOP | B19: =B4-B6-B9-B14+7 -> -55.516737 | C19: =C4-C6-C9-C14 -> -52.776259 | D19: =D4-D6-D9-D14 -> -38.670642 | E19: =E4-E6-E9-E14 -> -1.727057 | F19: =F4-F6-F9-F14 -> -13.573026 | G19: =G4-G6-G9-G14 -> 0 | H19: =H4-H6-H9-H14 -> 0 | I19: =I4-I6-I9-I14 -> 0 | J19: =J4-J6-J9-J14 -> 0 | ... O19: =O4-O6-O9-O14 -> -106.74698 | P19: =IFERROR(O19/B19,) -> 1.9227892
A21: 备注 | B21: EBITDA=营业收入-固定费用-变动费用-税金及附加
B22: GOP=营业收入-固定费用-变动费用-财务费用（不含利息费用）
B23: 需填列单元格

Sheet 费用预算执行明细
A1: 瑞尔酒店公司2026年预算执行情况明细表
A2: 项目 | B2: 2026年预算 | C2: 2026年预算执行情况 | O2: 2026年实际 | P2: 执行率
C3: 1月 | D3: 2月 | E3: 3月 | F3: 4月 | G3: 5月 | H3: 6月 | I3: 7月 | J3: 8月 | K3: 9月 | L3: 10月 | M3: 11月 | N3: 12月
A4: 固定费用 | B4: =B5+B13 -> 793.4447 | C4: =C5+C13 -> 82.740795 | D4: =D5+D13 -> 54.661567 | E4: =E5+E13 -> 41.604384 | F4: =F5+F13 -> 62.007687 | G4: =G5+G13 -> 0 | H4: =H5+H13 -> 0 | I4: =I5+I13 -> 0 | ... N4: =N5+N13 -> 0 | O4: =SUM(C4:N4) -> 241.01443 | P4: =IFERROR(O4/B4,) -> 0.30375706
A5: 人力费用合计 | B5: =SUM(B6:B12) -> 693.56 | C5: =SUM(C6:C12) -> 77.910641 | D5: =SUM(D6:D12) -> 52.070162 | E5: =SUM(E6:E12) -> 46.482044 | F5: =SUM(F6:F12) -> 47.60297 | G5: =SUM(G6:G12) -> 0 | H5: =SUM(H6:H12) -> 0 | I5: =SUM(I6:I12) -> 0 | ... N5: =SUM(N6:N12) -> 0 | O5: =SUM(C5:N5) -> 224.06582 | P5: =IFERROR(O5/B5,) -> 0.32306623
A6: 固定工资 | B6: 465.96 | C6: =66.785925-0.89-1.4448 -> 64.451125 | D6: =40.420825-0.806632-1.4468 -> 38.167393 | E6: =36.487796-1.6156-1.4468 -> 33.425396 | F6: =36.251258-1.273628-1.4858 -> 33.49183 | O6: =SUM(C6:N6) -> 169.53574 | P6: =IFERROR(O6/B6,) -> 0.36384184
A7: 绩效工资 | O7: =SUM(C7:N7) -> 0 | P7: =IFERROR(O7/B7,) -> 0
A8: 奖金 | O8: =SUM(C8:N8) -> 0 | P8: =IFERROR(O8/B8,) -> 0
A9: 福利费 | B9: 29.24 | C9: =0.121742+1.4448 -> 1.566542 | D9: =0.451528+1.4468+0.52432 -> 2.422648 | E9: =0.18266+1.4468 -> 1.62946 | F9: =0.143183+1.4858+1.52211 -> 3.151093 | O9: =SUM(C9:N9) -> 8.769743 | P9: =IFERROR(O9/B9,) -> 0.29992281
A10: 五险一金 | B10: 154.52 | C10: =8.664917+0.6186 -> 9.283517 | D10: =8.386482+0.5686 -> 8.955082 | E10: =8.275993+0.5686 -> 8.844593 | F10: =8.281991+0.5786 -> 8.860591 | O10: =SUM(C10:N10) -> 35.943783 | P10: =IFERROR(O10/B10,) -> 0.23261573
A11: 招聘费 | B11: 0.4 | O11: =SUM(C11:N11) -> 0 | P11: =IFERROR(O11/B11,) -> 0
A12: 其他人力费用 | B12: 43.44 | C12: =0.110609+2.498848 -> 2.609457 | D12: =0.111046+2.413993 -> 2.525039 | E12: =0.086346+2.496249 -> 2.582595 | F12: =0.093912+2.005544 -> 2.099456 | O12: =SUM(C12:N12) -> 9.816547 | P12: =IFERROR(O12/B12,) -> 0.22597944
A13: 固定费用支出合计 | B13: =SUM(B14:B45) -> 99.8847 | C13: =SUM(C14:C45) -> 4.830154 | D13: =SUM(D14:D45) -> 2.591405 | E13: =SUM(E14:E45) -> -4.87766 | F13: =SUM(F14:F45) -> 14.404717 | G13: =SUM(G14:G45) -> 0 | H13: =SUM(H14:H45) -> 0 | I13: =SUM(I14:I45) -> 0 | ... N13: =SUM(N14:N45) -> 0 | O13: =SUM(C13:N13) -> 16.948616 | P13: =IFERROR(O13/B13,) -> 0.1696818
A14: 邮寄费 | B14: 0.12 | D14: 0.0056 | O14: =SUM(C14:N14) -> 0.0056 | P14: =IFERROR(O14/B14,) -> 0.046666667
A15: 差旅费 | B15: 5.6 | O15: =SUM(C15:N15) -> 0 | P15: =IFERROR(O15/B15,) -> 0
A16: 业务招待费 | B16: 3.4 | E16: 0.0478 | O16: =SUM(C16:N16) -> 0.0478 | P16: =IFERROR(O16/B16,) -> 0.014058824
A17: 汽车费 | O17: =SUM(C17:N17) -> 0 | P17: =IFERROR(O17/B17,) -> 0
A18: 低值易耗品 | B18: 7.54 | C18: 0.7254 | D18: -0.083453 | O18: =SUM(C18:N18) -> 0.641947 | P18: =IFERROR(O18/B18,) -> 0.085138859
A19: 设备修理费 | B19: 20.5487 | C19: =1.554545-0.078322 -> 1.476223 | D19: 0.030165 | E19: =0.754717-7.749436 -> -6.994719 | F19: =9.639696-0.1265-0.038208 -> 9.474988 | O19: =SUM(C19:N19) -> 3.986657 | P19: =IFERROR(O19/B19,) -> 0.19401018
A20: 信息系统费 | B20: 1.256 | D20: 0.703517 | F20: 0.18 | O20: =SUM(C20:N20) -> 0.883517 | P20: =IFERROR(O20/B20,) -> 0.7034371
A21: 通讯费 | B21: 15.6 | C21: 1.213084 | D21: 1.3 | E21: 1.1933 | F21: 2.387377 | O21: =SUM(C21:N21) -> 6.093761 | P21: =IFERROR(O21/B21,) -> 0.39062571
A22: 交通费 | B22: 0.05 | D22: 0.003937 | F22: 0.008292 | O22: =SUM(C22:N22) -> 0.012229 | P22: =IFERROR(O22/B22,) -> 0.24458
A23: 办公费 | B23: 4.5 | C23: =0.049505+0.288968 -> 0.338473 | D23: 0.028843 | E23: =0.012583+0.112866 -> 0.125449 | F23: =0.099822+0.038069 -> 0.137891 | O23: =SUM(C23:N23) -> 0.630656 | P23: =IFERROR(O23/B23,) -> 0.14014578
A24: 会议费 | O24: =SUM(C24:N24) -> 0 | P24: =IFERROR(O24/B24,) -> 0
A25: 水电费 | O25: =SUM(C25:N25) -> 0 | P25: =IFERROR(O25/B25,) -> 0
A26: 展览费 | O26: =SUM(C26:N26) -> 0 | P26: =IFERROR(O26/B26,) -> 0
A27: 广告宣传费 | B27: 1 | O27: =SUM(C27:N27) -> 0 | P27: =IFERROR(O27/B27,) -> 0
A28: 咨询服务费 | B28: 7 | C28: 0.315313 | O28: =SUM(C28:N28) -> 0.315313 | P28: =IFERROR(O28/B28,) -> 0.045044714
A29: 法律诉讼费 | B29: 1 | O29: =SUM(C29:N29) -> 0 | P29: =IFERROR(O29/B29,) -> 0
A30: 工作餐费 | O30: =SUM(C30:N30) -> 0 | P30: =IFERROR(O30/B30,) -> 0
A31: 报关及代理费 | O31: =SUM(C31:N31) -> 0 | P31: =IFERROR(O31/B31,) -> 0
A32: 研究开发费 | O32: =SUM(C32:N32) -> 0 | P32: =IFERROR(O32/B32,) -> 0
A33: 质检认证费 | B33: 7.63 | F33: 1.521887 | O33: =SUM(C33:N33) -> 1.521887 | P33: =IFERROR(O33/B33,) -> 0.19946094
A34: 排污费 | O34: =SUM(C34:N34) -> 0 | P34: =IFERROR(O34/B34,) -> 0
A35: 社保服务费 | O35: =SUM(C35:N35) -> 0 | P35: =IFERROR(O35/B35,) -> 0
A36: 劳动保护费 | O36: =SUM(C36:N36) -> 0 | P36: =IFERROR(O36/B36,) -> 0
A37: 残疾人就业保障金 | B37: 7 | O37: =SUM(C37:N37) -> 0 | P37: =IFERROR(O37/B37,) -> 0
A38: 财产保险费 | B38: 6.55 | O38: =SUM(C38:N38) -> 0 | P38: =IFERROR(O38/B38,) -> 0
A39: 房租及物业费 | O39: =SUM(C39:N39) -> 0 | P39: =IFERROR(O39/B39,) -> 0
A40: 开办费 | O40: =SUM(C40:N40) -> 0 | P40: =IFERROR(O40/B40,) -> 0
...

Sheet 资本性支出计划与执行
A1: 瑞尔酒店公司2026年资本性支出执行情况明细表
A2: 资产类别 | B2: 资产类型 | C2: 资产名称 | D2: 数量 | E2: 单价 | F2: 金额 | G2: 2026年预算 | H2: 2026年实际
A3: 固定资产 | B3: 家具用具 | C3: 包房点歌系统（含音响、话筒） | D3: 2 | E3: 0.8 | F3: =D3*E3 -> 1.6 | G3: 1.6
C4: 包房岩板茶台（含椅子） | D4: 2 | E4: 0.25 | F4: =D4*E4 -> 0.5 | G4: 0.5
C5: 厨房制冷设备（冰柜） | D5: 6 | E5: 0.25 | F5: =D5*E5 -> 1.5 | G5: 1.5
C6: 吸尘器 | D6: 3 | E6: 0.15 | F6: =D6*E6 -> 0.45 | G6: 0.45
C7: 惠普打印机 | D7: 2 | E7: 0.25 | F7: =D7*E7 -> 0.5 | G7: 0.25
C8: 电脑 | D8: 1 | E8: 0.2 | F8: =D8*E8 -> 0.2 | G8: 0.2
A9: 其他长期支出 | B9: 长期待摊费用 | C9: 客房6-7楼部份翻新整改 | D9: 31间 | E9: 2.8 | F9: 95 | G9: 95
C10: 两江厅 | D10: 530平米 | E10: 0.0755 | F10: 40 | G10: 40
C11: 3楼护墙板 | D11: 110平米 | E11: 0.028 | F11: 3 | G11: 3
C12: 电梯钢绳 | D12: 2200米 | E12: 0.0011 | F12: 3.2 | G12: 3.2
C13: 电梯维修 | D13: 1台 | E13: 3.74 | F13: 3.74 | G13: 3.74
C14: 草坪婚礼场地 | D14: 1 | E14: 4.5 | F14: 4.5 | G14: 4.5
A15: 资本性支出合计 | G15: =SUM(G3:G14) -> 153.94 | H15: =SUM(H3:H8) -> 0
A17: 需填列
