Workbook

Sheet 指标统计
A1: 北京伯豪瑞廷酒店有限责任公司2026年经营指标统计表
A2: 指标 | B2: 项目 | C2: 2026年预算 | D2: 2026年执行情况 | P2: 2026年实际 | Q2: 执行率 | R2: 指标说明
D3: 1月 | E3: 2月 | F3: 3月 | G3: 4月 | H3: 5月 | I3: 6月 | J3: 7月 | K3: 8月 | L3: 9月 | M3: 10月 | N3: 11月 | O3: 12月
A4: 经营指标 | B4: 营业收入 | C4: =预算执行汇总!B4 -> 7677.2 | D4: {=预算执行汇总!C4:N4} -> 557.51 | E4: 405.76 | F4: 524.09 | G4: 614.99 | H4: 0 | I4: 0 | J4: 0 | K4: 0 | L4: 0 | M4: 0 | N4: 0 | O4: 0 | P4: =SUM(D4:O4) -> 2102.35 | Q4: =IFERROR((P4-C4)/ABS(C4)+1,) -> 0.27384333
B5: EBITDA/GOP/扣非净利润 | C5: =预算执行汇总!B19 -> 3025.121 | D5: =+预算执行汇总!C19 -> 200.8924 | E5: =+预算执行汇总!D19 -> 69.875 | F5: =+预算执行汇总!E19 -> 196.984 | G5: =+预算执行汇总!F19 -> 278.191 | H5: =+预算执行汇总!G19 -> 0 | I5: =+预算执行汇总!H19 -> 0 | J5: =+预算执行汇总!I19 -> 0 | K5: =+预算执行汇总!J19 -> 0 | ... O5: =+预算执行汇总!N19 -> 0 | P5: =SUM(D5:O5) -> 745.9424 | Q5: =IFERROR(P5/C5,) -> 0.24658267 | R5: EBITDA（商写适用）/GOP（酒店适用）/扣非净利润（保险中介适用）
B6: 经营活动净现金流 | C6: 1573.1 | D6: 17.26 | E6: 25.62 | F6: 207.69 | G6: -186.61 | P6: =SUM(D6:O6) -> 63.96 | Q6: =IFERROR(P6/C6,) -> 0.040658572
A7: 财务指标 | B7: 经营支出小计 | C7: {=预算执行汇总!B5:B12} -> 4678.459 | D7: {=预算执行汇总!C5:N12} -> 359.0376 | E7: 338.005 | F7: 331.676 | G7: 338.939 | H7: 0 | I7: 0 | J7: 0 | K7: 0 | L7: 0 | M7: 0 | N7: 0 | O7: 0 | P7: =SUM(D7:O7) -> 1367.6576 | Q7: =IFERROR(P7/C7,) -> 0.29233079
B8: 固定费用 | C8: 2812.403 | D8: 196.84 | E8: 206.46 | F8: 208.23 | G8: 203.97 | H8: 0 | I8: 0 | J8: 0 | K8: 0 | L8: 0 | M8: 0 | N8: 0 | O8: 0 | P8: =SUM(D8:O8) -> 815.5 | Q8: =IFERROR(P8/C8,) -> 0.28996556
B9: 人力费用 | C9: 2148.44 | D9: 167.97 | E9: 178.3 | F9: 163.82 | G9: 164.77 | H9: 0 | I9: 0 | J9: 0 | K9: 0 | L9: 0 | M9: 0 | N9: 0 | O9: 0 | P9: =SUM(D9:O9) -> 674.86 | Q9: =IFERROR(P9/C9,) -> 0.31411629
B10: 日常费用 | C10: 663.963 | D10: 28.87 | E10: 28.16 | F10: 44.41 | G10: 39.2 | H10: 0 | I10: 0 | J10: 0 | K10: 0 | L10: 0 | M10: 0 | N10: 0 | O10: 0 | P10: =SUM(D10:O10) -> 140.64 | Q10: =IFERROR(P10/C10,) -> 0.21181903
B11: 变动费用 | C11: 1866.056 | D11: 162.1976 | E11: 131.545 | F11: 123.446 | G11: 134.969 | H11: 0 | I11: 0 | J11: 0 | K11: 0 | L11: 0 | M11: 0 | N11: 0 | O11: 0 | P11: =SUM(D11:O11) -> 552.1576 | Q11: =IFERROR(P11/C11,) -> 0.29589551
B12: 经营变动费用 | C12: 596.646 | D12: 51.0976 | E12: 43.375 | F12: 51.276 | G12: 55.939 | H12: 0 | I12: 0 | J12: 0 | K12: 0 | L12: 0 | M12: 0 | N12: 0 | O12: 0 | P12: =SUM(D12:O12) -> 201.6876 | Q12: =IFERROR(P12/C12,) -> 0.33803562
B13: 营业成本 | C13: 1269.41 | D13: 111.1 | E13: 88.17 | F13: 72.17 | G13: 79.03 | H13: 0 | I13: 0 | J13: 0 | K13: 0 | L13: 0 | M13: 0 | N13: 0 | O13: 0 | P13: =SUM(D13:O13) -> 350.47 | Q13: =IFERROR(P13/C13,) -> 0.27608889
B14: 资本性支出 | C14: 294.5 | D14: 0 | E14: 0 | F14: 0 | G14: 0 | H14: 0 | I14: 0 | J14: 0 | K14: 0 | L14: 0 | M14: 0 | N14: 0 | O14: 0 | P14: =SUM(D14:O14) -> 0 | Q14: =IFERROR(P14/C14,) -> 0
A15: 业务指标 | B15: 期末出租率/月均入住率 | C15: 0.8203 | D15: 0.6527 | E15: 0.5493 | F15: 0.7096 | G15: 0.877 | P15: 0.6998 | Q15: =IFERROR(P15/C15,) -> 0.85310252 | R15: 期末出租率(商写适用)/月均入住率(酒店适用)
B16: 回款率 | C16: 0.842 | D16: 0.7759 | E16: 0.7279 | F16: 0.7701 | G16: 0.9935 | P16: =IFERROR(AVERAGE(D16:O16),) -> 0.81685 | Q16: =IFERROR(P16/C16,) -> 0.97013064 | R16: 商写及酒店适用
B17: OTA网络评价 | C17: 4.7 | D17: 4.68 | E17: 4.67 | F17: 4.69 | G17: 4.67 | P17: {=IFERROR(INDEX(D17:O17,0,MATCH(9.99999999999999E+307,D17:O17)),)} -> 4.67 | Q17: =IFERROR(P17/C17,) -> 0.99361702 | R17: 酒店适用
B18: 期交规保 | P18: {=IFERROR(INDEX(D18:O18,0,MATCH(9.99999999999999E+307,D18:O18)),)} -> 0 | Q18: =IFERROR(P18/C18,) -> 0 | R18: 保险中介适用
B19: 13月继续率 | P19: {=IFERROR(INDEX(D19:O19,0,MATCH(9.99999999999999E+307,D19:O19)),)} -> 0 | Q19: =IFERROR(P19/C19,) -> 0 | R19: 保险中介适用
B20: 25月继续率 | P20: {=IFERROR(INDEX(D20:O20,0,MATCH(9.99999999999999E+307,D20:O20)),)} -> 0 | Q20: =IFERROR(P20/C20,) -> 0 | R20: 保险中介适用
A21: 备注 | B21: EBITDA=营业收入-固定费用-变动费用-税金及附加
B22: GOP=营业收入-固定费用-变动费用-财务费用（不含利息费用）
B23: 需填列单元格

Sheet 预算执行汇总
A1: 北京伯豪瑞廷酒店有限责任公司2026年预算执行情况汇总表
A2: 项目 | B2: 2026年预算 | C2: 2026年执行情况 | O2: 2026年实际 | P2: 执行率
C3: 1月 | D3: 2月 | E3: 3月 | F3: 4月 | G3: 5月 | H3: 6月 | I3: 7月 | J3: 8月 | K3: 9月 | L3: 10月 | M3: 11月 | N3: 12月
A4: 营业收入 | B4: 7677.2 | C4: 557.51 | D4: 405.76 | E4: 524.09 | F4: 614.99 | O4: =SUM(C4:N4) -> 2102.35 | P4: =IFERROR(O4/B4,) -> 0.27384333
A5: 经营支出小计 | B5: =+B6+B9 -> 4678.459 | C5: =C6+C9 -> 359.0376 | D5: =D6+D9 -> 338.005 | E5: =E6+E9 -> 331.676 | F5: =F6+F9 -> 338.939 | G5: =G6+G9 -> 0 | H5: =H6+H9 -> 0 | I5: =I6+I9 -> 0 | J5: =J6+J9 -> 0 | ... N5: =N6+N9 -> 0 | O5: =SUM(C5:N5) -> 1367.6576 | P5: =IFERROR(O5/B5,) -> 0.29233079
A6: 固定费用 | B6: =费用预算执行明细!B4 -> 2812.403 | C6: =费用预算执行明细!C4 -> 196.84 | D6: =费用预算执行明细!D4 -> 206.46 | E6: =费用预算执行明细!E4 -> 208.23 | F6: =费用预算执行明细!F4 -> 203.97 | G6: =费用预算执行明细!G4 -> 0 | H6: =费用预算执行明细!H4 -> 0 | I6: =费用预算执行明细!I4 -> 0 | ... N6: =费用预算执行明细!N4 -> 0 | O6: =SUM(C6:N6) -> 815.5 | P6: =IFERROR(O6/B6,) -> 0.28996556
A7: 人力费用 | B7: =费用预算执行明细!B5 -> 2148.44 | C7: =费用预算执行明细!C5 -> 167.97 | D7: =费用预算执行明细!D5 -> 178.3 | E7: =费用预算执行明细!E5 -> 163.82 | F7: =费用预算执行明细!F5 -> 164.77 | G7: =费用预算执行明细!G5 -> 0 | H7: =费用预算执行明细!H5 -> 0 | I7: =费用预算执行明细!I5 -> 0 | ... N7: =费用预算执行明细!N5 -> 0 | O7: =SUM(C7:N7) -> 674.86 | P7: =IFERROR(O7/B7,) -> 0.31411629
A8: 日常费用 | B8: =费用预算执行明细!B15 -> 663.963 | C8: =费用预算执行明细!C15 -> 28.87 | D8: =费用预算执行明细!D15 -> 28.16 | E8: =费用预算执行明细!E15 -> 44.41 | F8: =费用预算执行明细!F15 -> 39.2 | G8: =费用预算执行明细!G15 -> 0 | H8: =费用预算执行明细!H15 -> 0 | I8: =费用预算执行明细!I15 -> 0 | ... N8: =费用预算执行明细!N15 -> 0 | O8: =SUM(C8:N8) -> 140.64 | P8: =IFERROR(O8/B8,) -> 0.21181903
A9: 变动费用 | B9: =费用预算执行明细!B43 -> 1866.056 | C9: =费用预算执行明细!C43 -> 162.1976 | D9: =费用预算执行明细!D43 -> 131.545 | E9: =费用预算执行明细!E43 -> 123.446 | F9: =费用预算执行明细!F43 -> 134.969 | G9: =费用预算执行明细!G43 -> 0 | H9: =费用预算执行明细!H43 -> 0 | I9: =费用预算执行明细!I43 -> 0 | ... N9: =费用预算执行明细!N43 -> 0 | O9: =SUM(C9:N9) -> 552.1576 | P9: =IFERROR(O9/B9,) -> 0.29589551
A10: 经营变动费用支出 | B10: =费用预算执行明细!B44 -> 596.646 | C10: =费用预算执行明细!C44 -> 51.0976 | D10: =费用预算执行明细!D44 -> 43.375 | E10: =费用预算执行明细!E44 -> 51.276 | F10: =费用预算执行明细!F44 -> 55.939 | G10: =费用预算执行明细!G44 -> 0 | H10: =费用预算执行明细!H44 -> 0 | I10: =费用预算执行明细!I44 -> 0 | ... N10: =费用预算执行明细!N44 -> 0 | O10: =SUM(C10:N10) -> 201.6876 | P10: =IFERROR(O10/B10,) -> 0.33803562
A11: 营业成本支出 | B11: =费用预算执行明细!B69 -> 1269.41 | C11: =费用预算执行明细!C69 -> 111.1 | D11: =费用预算执行明细!D69 -> 88.17 | E11: =费用预算执行明细!E69 -> 72.17 | F11: =费用预算执行明细!F69 -> 79.03 | G11: =费用预算执行明细!G69 -> 0 | H11: =费用预算执行明细!H69 -> 0 | I11: =费用预算执行明细!I69 -> 0 | ... N11: =费用预算执行明细!N69 -> 0 | O11: =SUM(C11:N11) -> 350.47 | P11: =IFERROR(O11/B11,) -> 0.27608889
A12: 资本性支出 | B12: =资本性支出计划与执行!G37/10000 -> 294.5 | C12: 0 | D12: 0 | E12: 0 | F12: 0 | O12: =SUM(C12:N12) -> 0 | P12: =IFERROR(O12/B12,) -> 0
A13: 折旧摊销 | B13: 2917.5 | C13: 240.74 | D13: 240.73 | E13: 240.73 | F13: 240.74 | O13: =SUM(C13:N13) -> 962.94 | P13: =IFERROR(O13/B13,) -> 0.33005656
A14: 财务费用 | B14: -26.38 | C14: -2.42 | D14: -2.12 | E14: -4.57 | F14: -2.14 | O14: =SUM(C14:N14) -> -11.25 | P14: =IFERROR(O14/B14,) -> 0.42645944
A15: 税金及附加 | B15: 1005.19 | C15: 83.27 | D15: 82.37 | E15: 83.38 | F15: 83.98 | O15: =SUM(C15:N15) -> 333 | P15: =IFERROR(O15/B15,) -> 0.33128065
A16: 变动费用率 | B16: =IFERROR(B9/B4,) -> 0.24306466 | C16: =IFERROR(C9/C4,) -> 0.29093218 | D16: =IFERROR(D9/D4,) -> 0.3241941 | E16: =IFERROR(E9/E4,) -> 0.23554351 | F16: =IFERROR(F9/F4,) -> 0.21946536 | G16: =IFERROR(G9/G4,) -> 0 | H16: =IFERROR(H9/H4,) -> 0 | I16: =IFERROR(I9/I4,) -> 0 | ... O16: =IFERROR(O9/O4,) -> 0.26263829
A18: EBITDA | B18: =B4-B6-B9-B15 -> 1993.551 | C18: =C4-C6-C9-C15 -> 115.2024 | D18: =D4-D6-D9-D15 -> -14.615 | E18: =E4-E6-E9-E15 -> 109.034 | F18: =F4-F6-F9-F15 -> 192.071 | G18: =G4-G6-G9-G15 -> 0 | H18: =H4-H6-H9-H15 -> 0 | I18: =I4-I6-I9-I15 -> 0 | ... O18: =O4-O6-O9-O15 -> 401.6924 | P18: =IFERROR(O18/B18,) -> 0.20149592
A19: GOP | B19: =B4-B6-B9-B14 -> 3025.121 | C19: =C4-C6-C9-C14 -> 200.8924 | D19: =D4-D6-D9-D14 -> 69.875 | E19: =E4-E6-E9-E14 -> 196.984 | F19: =F4-F6-F9-F14 -> 278.191 | G19: =G4-G6-G9-G14 -> 0 | H19: =H4-H6-H9-H14 -> 0 | I19: =I4-I6-I9-I14 -> 0 | ... O19: =O4-O6-O9-O14 -> 745.9424 | P19: =IFERROR(O19/B19,) -> 0.24658267
A21: 备注 | B21: EBITDA=营业收入-固定费用-变动费用-税金及附加
B22: GOP=营业收入-固定费用-变动费用-财务费用（不含利息费用）
B23: 需填列单元格

Sheet 费用预算执行明细
A1: 北京伯豪瑞廷酒店有限责任公司2026年预算执行情况明细表
A2: 项目 | B2: 2026年预算 | C2: 2026年预算执行情况 | O2: 2026年实际 | P2: 执行率
C3: 1月 | D3: 2月 | E3: 3月 | F3: 4月 | G3: 5月 | H3: 6月 | I3: 7月 | J3: 8月 | K3: 9月 | L3: 10月 | M3: 11月 | N3: 12月
A4: 固定费用 | B4: =+B5+B15 -> 2812.403 | C4: =+C5+C15 -> 196.84 | D4: =+D5+D15 -> 206.46 | E4: =+E5+E15 -> 208.23 | F4: =+F5+F15 -> 203.97 | G4: =+G5+G15 -> 0 | H4: =+H5+H15 -> 0 | I4: =+I5+I15 -> 0 | ... N4: =+N5+N15 -> 0 | O4: =SUM(C4:N4) -> 815.5 | P4: =IFERROR(O4/B4,) -> 0.28996556
A5: 人力费用支出合计 | B5: =SUM(B6:B14) -> 2148.44 | C5: =SUM(C6:C14) -> 167.97 | D5: =SUM(D6:D14) -> 178.3 | E5: =SUM(E6:E14) -> 163.82 | F5: =SUM(F6:F14) -> 164.77 | G5: =SUM(G6:G14) -> 0 | H5: =SUM(H6:H14) -> 0 | I5: =SUM(I6:I14) -> 0 | ... N5: =SUM(N6:N14) -> 0 | O5: =SUM(C5:N5) -> 674.86 | P5: =IFERROR(O5/B5,) -> 0.31411629
A6: 固定工资 | B6: 1455.16 | C6: 114.53 | D6: 126.6 | E6: 109.93 | F6: 112.9 | O6: =SUM(C6:N6) -> 463.96 | P6: =IFERROR(O6/B6,) -> 0.31883779
A7: 奖金 | B7: 0 | C7: 0 | D7: 0 | E7: 0 | F7: 0 | O7: =SUM(C7:N7) -> 0 | P7: =IFERROR(O7/B7,) -> 0
A8: 福利费 | B8: 21.49 | C8: 0.8 | D8: 0.87 | E8: 0.74 | F8: 0.86 | O8: =SUM(C8:N8) -> 3.27 | P8: =IFERROR(O8/B8,) -> 0.1521638
A9: 五险一金 | B9: 552.13 | C9: 44.85 | D9: 44.85 | E9: 45.07 | F9: 44.25 | O9: =SUM(C9:N9) -> 179.02 | P9: =IFERROR(O9/B9,) -> 0.32423523
A10: 残疾人就业保障金 | B10: 0 | C10: 0 | D10: 0 | E10: 0 | F10: 0 | O10: =SUM(C10:N10) -> 0 | P10: =IFERROR(O10/B10,) -> 0
A11: 工会经费 | B11: 28.8 | C11: 2.4 | D11: 2.91 | E11: 2.4 | F11: 1.51 | O11: =SUM(C11:N11) -> 9.22 | P11: =IFERROR(O11/B11,) -> 0.32013889
A12: 辞退补偿 | B12: 16.9 | C12: 0 | D12: 0 | E12: 0 | F12: 0 | O12: =SUM(C12:N12) -> 0 | P12: =IFERROR(O12/B12,) -> 0
A13: 招聘费 | B13: 0.76 | C13: 0 | D13: 0 | E13: 0 | F13: 0 | O13: =SUM(C13:N13) -> 0 | P13: =IFERROR(O13/B13,) -> 0
A14: 其他人力费用 | B14: 73.2 | C14: 5.39 | D14: 3.07 | E14: 5.68 | F14: 5.25 | O14: =SUM(C14:N14) -> 19.39 | P14: =IFERROR(O14/B14,) -> 0.26489071
A15: 日常费用支出合计 | B15: =B16+B22 -> 663.963 | C15: =C16+C22 -> 28.87 | D15: =D16+D22 -> 28.16 | E15: =E16+E22 -> 44.41 | F15: =F16+F22 -> 39.2 | G15: =G16+G22 -> 0 | H15: =H16+H22 -> 0 | I15: =I16+I22 -> 0 | ... N15: =N16+N22 -> 0 | O15: =SUM(C15:N15) -> 140.64 | P15: =IFERROR(O15/B15,) -> 0.21181903
A16: 职场费用合计 | B16: =SUM(B17:B21) -> 99.25 | C16: =SUM(C17:C21) -> 9.38 | D16: =SUM(D17:D21) -> 10.45 | E16: =SUM(E17:E21) -> 6.88 | F16: =SUM(F17:F21) -> 5.31 | G16: =SUM(G17:G21) -> 0 | H16: =SUM(H17:H21) -> 0 | I16: =SUM(I17:I21) -> 0 | ... N16: =SUM(N17:N21) -> 0 | O16: =SUM(C16:N16) -> 32.02 | P16: =IFERROR(O16/B16,) -> 0.32261965
A17: 物业费 | B17: 19.24 | C17: 1.6 | D17: 1.61 | E17: 1.6 | F17: 1.6 | O17: =SUM(C17:N17) -> 6.41 | P17: =IFERROR(O17/B17,) -> 0.33316008
A18: 取暖供冷费 | B18: 0 | O18: =SUM(C18:N18) -> 0 | P18: =IFERROR(O18/B18,) -> 0
A19: 房屋租赁费 | B19: 0 | O19: =SUM(C19:N19) -> 0 | P19: =IFERROR(O19/B19,) -> 0
A20: 水电费 | B20: 70.23 | C20: 6.97 | D20: 8.03 | E20: 4.47 | F20: 2.9 | O20: =SUM(C20:N20) -> 22.37 | P20: =IFERROR(O20/B20,) -> 0.31852485
A21: 财产保险费 | B21: 9.78 | C21: 0.81 | D21: 0.81 | E21: 0.81 | F21: 0.81 | O21: =SUM(C21:N21) -> 3.24 | P21: =IFERROR(O21/B21,) -> 0.33128834
A22: 办公费用合计 | B22: =SUM(B23:B42) -> 564.713 | C22: =SUM(C23:C42) -> 19.49 | D22: =SUM(D23:D42) -> 17.71 | E22: =SUM(E23:E42) -> 37.53 | F22: =SUM(F23:F42) -> 33.89 | G22: =SUM(G23:G42) -> 0 | H22: =SUM(H23:H42) -> 0 | I22: =SUM(I23:I42) -> 0 | ... N22: =SUM(N23:N42) -> 0 | O22: =SUM(C22:N22) -> 108.62 | P22: =IFERROR(O22/B22,) -> 0.19234549
A23: 差旅费 | B23: 0 | O23: =SUM(C23:N23) -> 0 | P23: =IFERROR(O23/B23,) -> 0
A24: 业务招待费 | B24: 0 | O24: =SUM(C24:N24) -> 0 | P24: =IFERROR(O24/B24,) -> 0
A25: 邮寄费 | B25: 1.09 | C25: 0.08 | D25: 0.02 | E25: 0.05 | F25: 0.03 | O25: =SUM(C25:N25) -> 0.18 | P25: =IFERROR(O25/B25,) -> 0.16513761
A26: 汽车费 | B26: 3.9 | C26: 0.17 | D26: 0.17 | E26: 0.25 | F26: 0.29 | O26: =SUM(C26:N26) -> 0.88 | P26: =IFERROR(O26/B26,) -> 0.22564103
A27: 低值易耗品 | B27: 0 | O27: =SUM(C27:N27) -> 0 | P27: =IFERROR(O27/B27,) -> 0
A28: 设备修理费 | B28: 0 | O28: =SUM(C28:N28) -> 0 | P28: =IFERROR(O28/B28,) -> 0
A29: 通讯费 | B29: 0.063 | F29: 0.1 | O29: =SUM(C29:N29) -> 0.1 | P29: =IFERROR(O29/B29,) -> 1.5873016
A30: 市内交通费 | B30: 0 | O30: =SUM(C30:N30) -> 0 | P30: =IFERROR(O30/B30,) -> 0
A31: 办公杂费 | B31: 4.99 | C31: 0.16 | D31: 0.11 | E31: 0.27 | F31: 0.24 | O31: =SUM(C31:N31) -> 0.78 | P31: =IFERROR(O31/B31,) -> 0.15631263
A32: 会议费 | B32: 0 | O32: =SUM(C32:N32) -> 0 | P32: =IFERROR(O32/B32,) -> 0
A33: 培训费 | B33: 0 | O33: =SUM(C33:N33) -> 0 | P33: =IFERROR(O33/B33,) -> 0
A34: 广告宣传费 | B34: 0 | O34: =SUM(C34:N34) -> 0 | P34: =IFERROR(O34/B34,) -> 0
A35: 咨询服务费 | B35: 16.2 | C35: 1.51 | D35: 0.91 | E35: 0.67 | F35: =0.67+5.66 -> 6.33 | O35: =SUM(C35:N35) -> 9.42 | P35: =IFERROR(O35/B35,) -> 0.58148148
A36: 法律诉讼费 | B36: 0 | O36: =SUM(C36:N36) -> 0 | P36: =IFERROR(O36/B36,) -> 0
A37: 研究开发费 | B37: 0 | O37: =SUM(C37:N37) -> 0 | P37: =IFERROR(O37/B37,) -> 0
A38: 质检认证费 | B38: 0 | O38: =SUM(C38:N38) -> 0 | P38: =IFERROR(O38/B38,) -> 0
A39: 排污费 | B39: 0 | O39: =SUM(C39:N39) -> 0 | P39: =IFERROR(O39/B39,) -> 0
A40: 信息系统费 | B40: 76.64 | C40: 6.2 | D40: 6.19 | E40: 6.2 | F40: 6.2 | O40: =SUM(C40:N40) -> 24.79 | P40: =IFERROR(O40/B40,) -> 0.32346033
...

Sheet 资本性支出计划与执行
A1: 北京伯豪瑞廷酒店有限责任公司2026年资本性支出执行情况明细表
A2: 资产类别 | B2: 资产类型 | C2: 资产名称 | D2: 数量 | E2: 单价 | F2: 金额 | G2: 2026年预算 | H2: 2026年实际
A3: 固定资产 | B3: 办公、通讯及文字处理设备 | C3: 客房写字椅 | D3: 300 | E3: 700.66667 | F3: =D3*E3 -> 210200 | G3: =F3 -> 210200
B4: 电器设备 | C4: Honeyson客房小冰箱42L（带锁） | D4: 40 | E4: 615 | F4: =D4*E4 -> 24600 | G4: =F4 -> 24600
B5: 办公、通讯及文字处理设备 | C5: 定制保险柜（精工） | D5: 40 | E5: 530 | F5: =D5*E5 -> 21200 | G5: =F5 -> 21200
B6: 电器设备 | C6: 飞利浦液晶电视43寸 | D6: 5 | E6: 1400 | F6: =D6*E6 -> 7000 | G6: =F6 -> 7000
B7: 电器设备 | C7: 飞利浦液晶电视65寸 | D7: 5 | E7: 2660 | F7: =D7*E7 -> 13300 | G7: =F7 -> 13300
B8: 办公、通讯及文字处理设备 | C8: 惠普台式电脑 | D8: 3 | E8: 4300 | F8: =D8*E8 -> 12900 | G8: =F8 -> 12900
B9: 办公、通讯及文字处理设备 | C9: 笔记本电脑 | D9: 1 | E9: 4000 | F9: =D9*E9 -> 4000 | G9: =F9 -> 4000
B10: 办公、通讯及文字处理设备 | C10: 惠普打印、扫描、复印一体机 | D10: 1 | E10: 3500 | F10: =D10*E10 -> 3500 | G10: =F10 -> 3500
B11: 办公、通讯及文字处理设备 | C11: 打印机 | D11: 2 | E11: 3500 | F11: =D11*E11 -> 7000 | G11: =F11 -> 7000
B12: 电器设备 | C12: 吸水机 | D12: 1 | E12: 10000 | F12: =D12*E12 -> 10000 | G12: =F12 -> 10000
B13: 电器设备 | C13: 三合一地毯抽洗机 | D13: 1 | E13: 20000 | F13: =D13*E13 -> 20000 | G13: =F13 -> 20000
B14: 办公、通讯及文字处理设备 | C14: 台式电脑及显示屏 | D14: 4 | E14: 4300 | F14: =D14*E14 -> 17200 | G14: =F14 -> 17200
B15: 办公、通讯及文字处理设备 | C15: 打印+复印一体机 | D15: 2 | E15: 3500 | F15: =D15*E15 -> 7000 | G15: =F15 -> 7000
... B28: 安全防卫设备 | C28: 防火门 | D28: 1 | E28: 6000 | F28: =D28*E28 -> 6000 | G28: =F28 -> 6000
A29: 其他长期 | B29: 机械动力设备 | C29: 客房客控箱更换 | D29: 44 | E29: 4600 | F29: =D29*E29 -> 202400 | G29: =F29 -> 202400
B30: 机械动力设备 | C30: 宴会厅（瑞和）新风机组更换（变风量）电机 | D30: 1 | E30: 32000 | F30: =D30*E30 -> 32000 | G30: =F30 -> 32000
B31: 机械动力设备 | C31: 部分客房及竖井空调管道更换 | D31: 161 | E31: 9068.323 | F31: =D31*E31 -> 1460000 | G31: =F31 -> 1460000
B32: 机械动力设备 | C32: 消防应急照明（EPS）恢复改造 | D32: 1 | E32: 100000 | F32: =D32*E32 -> 100000 | G32: =F32 -> 100000
B33: 机械动力设备 | C33: 电梯机房加装5匹空调机组 | D33: 3 | E33: 8000 | F33: =D33*E33 -> 24000 | G33: =F33 -> 24000
B34: 机械动力设备 | C34: 原布草滑道封堵 | D34: 1 | E34: 90000 | F34: =D34*E34 -> 90000 | G34: =F34 -> 90000
B35: 机械动力设备 | C35: 酒店监控设备系统 | D35: 1 | E35: 450000 | F35: =D35*E35 -> 450000 | G35: =F35 -> 450000
B36: 机械动力设备 | C36: 可燃气体探测器 | D36: 25 | E36: 1000 | F36: =D36*E36 -> 25000 | G36: =F36 -> 25000
A37: 资本性支出合计 | G37: =SUM(G3:G36) -> 2945000 | H37: =SUM(H3:H36) -> 0
A39: 需填列
