Workbook

Sheet 指标统计
A1: 北京中言房地产开发有限公司2026年经营指标统计表
A2: 指标 | B2: 项目 | C2: 2026年预算 | D2: 2026年执行情况 | P2: 2026年实际 | Q2: 执行率 | R2: 指标说明
D3: 1月 | E3: 2月 | F3: 3月 | G3: 4月 | H3: 5月 | I3: 6月 | J3: 7月 | K3: 8月 | L3: 9月 | M3: 10月 | N3: 11月 | O3: 12月
A4: 经营指标 | B4: 营业收入 | C4: =预算执行汇总!B4 -> 8093.1731 | D4: {=预算执行汇总!C4:N4} -> 580.60931 | E4: 567.20524 | F4: 1148.0225 | G4: 769.80497 | H4: 0 | I4: 0 | J4: 0 | K4: 0 | L4: 0 | M4: 0 | N4: 0 | O4: 0 | P4: =SUM(D4:O4) -> 3065.642 | Q4: =IFERROR((P4-C4)/ABS(C4)+1,) -> 0.37879358
B5: EBITDA/GOP/扣非净利润 | C5: =预算执行汇总!B18 -> 3056.2075 | D5: =预算执行汇总!C18 -> 309.20647 | E5: =预算执行汇总!D18 -> 296.73437 | F5: =预算执行汇总!E18 -> 885.00292 | G5: =预算执行汇总!F18 -> 493.44928 | P5: =SUM(D5:O5) -> 1984.393 | Q5: =IFERROR(P5/C5,) -> 0.64929918 | R5: EBITDA（商写适用）/GOP（酒店适用）/扣非净利润（保险中介适用）
B6: 经营活动净现金流 | C6: 112.83542 | D6: 85.643994 | E6: =8832769.96/10000 -> 883.277 | F6: =-7155354.41/10000 -> -715.53544 | G6: =27193822.25/10000-370.52 -> 2348.8622 | P6: =SUM(D6:O6) -> 2602.2478 | Q6: =IFERROR(P6/C6,) -> 23.062332 | R6: 4月收到富泽人寿租金及保证金3115.37万元
A7: 财务指标 | B7: 经营支出小计 | C7: =预算执行汇总!B6 -> 637.27558 | D7: {=预算执行汇总!C5:N12} -> 46.856168 | E7: 43.40538 | F7: 50.429416 | G7: 56.655602 | H7: 0 | I7: 0 | J7: 0 | K7: 0 | L7: 0 | M7: 0 | N7: 0 | O7: 0 | P7: =SUM(D7:O7) -> 197.34657 | Q7: =IFERROR(P7/C7,) -> 0.30967225
B8: 固定费用 | C8: =预算执行汇总!B6 -> 637.27558 | D8: 32.585219 | E8: 39.025355 | F8: 37.531035 | G8: 37.76773 | H8: 0 | I8: 0 | J8: 0 | K8: 0 | L8: 0 | M8: 0 | N8: 0 | O8: 0 | P8: =SUM(D8:O8) -> 146.90934 | Q8: =IFERROR(P8/C8,) -> 0.23052717
B9: 人力费用 | C9: =预算执行汇总!B7 -> 484.75 | D9: 32.253202 | E9: 36.318083 | F9: 35.989898 | G9: 36.802752 | H9: 0 | I9: 0 | J9: 0 | K9: 0 | L9: 0 | M9: 0 | N9: 0 | O9: 0 | P9: =SUM(D9:O9) -> 141.36393 | Q9: =IFERROR(P9/C9,) -> 0.29162235
B10: 日常费用 | C10: =预算执行汇总!B8 -> 152.52558 | D10: 0.332017 | E10: 2.707272 | F10: 1.541137 | G10: 0.964978 | H10: 0 | I10: 0 | J10: 0 | K10: 0 | L10: 0 | M10: 0 | N10: 0 | O10: 0 | P10: =SUM(D10:O10) -> 5.545404 | Q10: =IFERROR(P10/C10,) -> 0.036357206
B11: 变动费用 | C11: =预算执行汇总!B9 -> 1626.69 | D11: 14.270949 | E11: 4.380025 | F11: 12.898381 | G11: 18.887872 | H11: 0 | I11: 0 | J11: 0 | K11: 0 | L11: 0 | M11: 0 | N11: 0 | O11: 0 | P11: =SUM(D11:O11) -> 50.437227 | Q11: =IFERROR(P11/C11,) -> 0.031006047
B12: 经营变动费用 | C12: =预算执行汇总!B10 -> 1626.69 | D12: 14.270949 | E12: 4.380025 | F12: 12.898381 | G12: 18.887872 | H12: 0 | I12: 0 | J12: 0 | K12: 0 | L12: 0 | M12: 0 | N12: 0 | O12: 0 | P12: =SUM(D12:O12) -> 50.437227 | Q12: =IFERROR(P12/C12,) -> 0.031006047
B13: 营业成本 | C13: 0 | D13: 0 | E13: 0 | F13: 0 | G13: 0 | H13: 0 | I13: 0 | J13: 0 | K13: 0 | L13: 0 | M13: 0 | N13: 0 | O13: 0 | P13: =SUM(D13:O13) -> 0 | Q13: =IFERROR(P13/C13,) -> 0
B14: 资本性支出 | C14: =预算执行汇总!B12 -> 842 | D14: 0 | E14: 0 | F14: 1.935942 | G14: 0 | H14: 0 | I14: 0 | J14: 0 | K14: 0 | L14: 0 | M14: 0 | N14: 0 | O14: 0 | P14: =SUM(D14:O14) -> 1.935942 | Q14: =IFERROR(P14/C14,) -> 0.0022992185
A15: 业务指标 | B15: 期末出租率/月均入住率 | C15: 0.65 | D15: 0.6413 | E15: 0.6413 | F15: 0.6774 | G15: 0.6694 | P15: =IFERROR(AVERAGE(D15:O15),) -> 0.65735 | Q15: =IFERROR(P15/C15,) -> 1.0113077 | R15: 期末出租率(商写适用)/月均入住率(酒店适用)
B16: 回款率 | C16: 0.95 | D16: 0.8 | E16: 0.85 | F16: 0.96 | G16: 0.98 | P16: =IFERROR(AVERAGE(D16:O16),) -> 0.8975 | Q16: =IFERROR(P16/C16,) -> 0.94473684 | R16: 商写及酒店适用
B17: OTA网络评价 | P17: {=IFERROR(INDEX(D17:O17,0,MATCH(9.99999999999999E+307,D17:O17)),)} -> 0 | Q17: =IFERROR(P17/C17,) -> 0 | R17: 酒店适用
B18: 期交规保 | P18: {=IFERROR(INDEX(D18:O18,0,MATCH(9.99999999999999E+307,D18:O18)),)} -> 0 | Q18: =IFERROR(P18/C18,) -> 0 | R18: 保险中介适用
B19: 13月继续率 | P19: {=IFERROR(INDEX(D19:O19,0,MATCH(9.99999999999999E+307,D19:O19)),)} -> 0 | Q19: =IFERROR(P19/C19,) -> 0 | R19: 保险中介适用
B20: 25月继续率 | P20: {=IFERROR(INDEX(D20:O20,0,MATCH(9.99999999999999E+307,D20:O20)),)} -> 0 | Q20: =IFERROR(P20/C20,) -> 0 | R20: 保险中介适用
A21: 备注 | B21: EBITDA=营业收入-固定费用-变动费用-税金及附加
B22: GOP=营业收入-固定费用-变动费用-财务费用（不含利息费用）
B23: 需填列单元格

Sheet 预算执行汇总
A1: 北京中言房地产开发有限公司2026年预算执行情况汇总表
A2: 项目 | B2: 2026年预算 | C2: 2026年执行情况 | O2: 2026年实际 | P2: 执行率
C3: 1月 | D3: 2月 | E3: 3月 | F3: 4月 | G3: 5月 | H3: 6月 | I3: 7月 | J3: 8月 | K3: 9月 | L3: 10月 | M3: 11月 | N3: 12月
A4: 营业收入 | B4: 8093.1731 | C4: 580.60931 | D4: =5672052.36/10000 -> 567.20524 | E4: =11480224.71/10000 -> 1148.0225 | F4: =(11097338.88-3399289.18)/10000 -> 769.80497 | O4: =SUM(C4:N4) -> 3065.642 | P4: =IFERROR(O4/B4,) -> 0.37879358
A5: 经营支出小计 | B5: 2263.9656 | C5: =C6+C9 -> 46.856168 | D5: =D6+D9 -> 43.40538 | E5: =E6+E9 -> 50.429416 | F5: =F6+F9 -> 56.655602 | G5: =G6+G9 -> 0 | H5: =H6+H9 -> 0 | I5: =I6+I9 -> 0 | J5: =J6+J9 -> 0 | ... N5: =N6+N9 -> 0 | O5: =SUM(C5:N5) -> 197.34657 | P5: =IFERROR(O5/B5,) -> 0.087168536
A6: 固定费用 | B6: 637.27558 | C6: =费用预算执行明细!C4 -> 32.585219 | D6: =费用预算执行明细!D4 -> 39.025355 | E6: =费用预算执行明细!E4 -> 37.531035 | F6: =费用预算执行明细!F4 -> 37.76773 | G6: =费用预算执行明细!G4 -> 0 | H6: =费用预算执行明细!H4 -> 0 | I6: =费用预算执行明细!I4 -> 0 | J6: =费用预算执行明细!J4 -> 0 | ... N6: =费用预算执行明细!N4 -> 0 | O6: =SUM(C6:N6) -> 146.90934 | P6: =IFERROR(O6/B6,) -> 0.23052717
A7: 人力费用 | B7: 484.75 | C7: =费用预算执行明细!C5 -> 32.253202 | D7: =费用预算执行明细!D5 -> 36.318083 | E7: =费用预算执行明细!E5 -> 35.989898 | F7: =费用预算执行明细!F5 -> 36.802752 | G7: =费用预算执行明细!G5 -> 0 | H7: =费用预算执行明细!H5 -> 0 | I7: =费用预算执行明细!I5 -> 0 | J7: =费用预算执行明细!J5 -> 0 | ... N7: =费用预算执行明细!N5 -> 0 | O7: =SUM(C7:N7) -> 141.36393 | P7: =IFERROR(O7/B7,) -> 0.29162235
A8: 日常费用 | B8: 152.52558 | C8: =费用预算执行明细!C15 -> 0.332017 | D8: =费用预算执行明细!D15 -> 2.707272 | E8: =费用预算执行明细!E15 -> 1.541137 | F8: =费用预算执行明细!F15 -> 0.964978 | G8: =费用预算执行明细!G15 -> 0 | H8: =费用预算执行明细!H15 -> 0 | I8: =费用预算执行明细!I15 -> 0 | J8: =费用预算执行明细!J15 -> 0 | ... N8: =费用预算执行明细!N15 -> 0 | O8: =SUM(C8:N8) -> 5.545404 | P8: =IFERROR(O8/B8,) -> 0.036357206
A9: 变动费用 | B9: 1626.69 | C9: =费用预算执行明细!C48 -> 14.270949 | D9: =费用预算执行明细!D48 -> 4.380025 | E9: =费用预算执行明细!E48 -> 12.898381 | F9: =费用预算执行明细!F48 -> 18.887872 | G9: =费用预算执行明细!G48 -> 0 | H9: =费用预算执行明细!H48 -> 0 | I9: =费用预算执行明细!I48 -> 0 | J9: =费用预算执行明细!J48 -> 0 | ... N9: =费用预算执行明细!N48 -> 0 | O9: =SUM(C9:N9) -> 50.437227 | P9: =IFERROR(O9/B9,) -> 0.031006047
A10: 经营变动费用支出 | B10: 1626.69 | C10: =费用预算执行明细!C49 -> 14.270949 | D10: =费用预算执行明细!D49 -> 4.380025 | E10: =费用预算执行明细!E49 -> 12.898381 | F10: =费用预算执行明细!F49 -> 18.887872 | G10: =费用预算执行明细!G49 -> 0 | H10: =费用预算执行明细!H49 -> 0 | I10: =费用预算执行明细!I49 -> 0 | J10: =费用预算执行明细!J49 -> 0 | ... N10: =费用预算执行明细!N49 -> 0 | O10: =SUM(C10:N10) -> 50.437227 | P10: =IFERROR(O10/B10,) -> 0.031006047
A11: 营业成本支出 | C11: =费用预算执行明细!C82 -> 0 | D11: =费用预算执行明细!D82 -> 0 | E11: =费用预算执行明细!E82 -> 0 | F11: =费用预算执行明细!F82 -> 0 | G11: =费用预算执行明细!G82 -> 0 | H11: =费用预算执行明细!H82 -> 0 | I11: =费用预算执行明细!I82 -> 0 | J11: =费用预算执行明细!J82 -> 0 | ... N11: =费用预算执行明细!N82 -> 0 | O11: =SUM(C11:N11) -> 0 | P11: =IFERROR(O11/B11,) -> 0
A12: 资本性支出 | B12: =资本性支出计划与执行!G21 -> 842 | C12: 0 | D12: 0 | E12: =资本性支出计划与执行!H21 -> 1.935942 | F12: 0 | O12: =SUM(C12:N12) -> 1.935942 | P12: =IFERROR(O12/B12,) -> 0.0022992185
A13: 折旧摊销 | B13: 7040.7201 | C13: =5757901.02/10000+1244.88/10000 -> 575.91459 | D13: =(5690413.94+62504.75+5367.73)/10000+1244.88/10000 -> 575.95313 | E13: =(62504.75+1244.88+5367.73+5690413.94)/10000 -> 575.95313 | F13: =(5690413.94+62504.75+5367.73+1244.88)/10000 -> 575.95313 | O13: =SUM(C13:N13) -> 2303.774 | P13: =IFERROR(O13/B13,) -> 0.32720715
A14: 财务费用 | B14: 1487.4 | C14: 0.324969 | D14: =680.43/10000 -> 0.068043 | E14: =3657547.43/10000 -> 365.75474 | F14: =534.76/10000 -> 0.053476 | O14: =SUM(C14:N14) -> 366.20123 | P14: =IFERROR(O14/B14,) -> 0.24620225
A15: 税金及附加 | B15: 2833 | C15: 224.54666 | D15: =2270654.88/10000 -> 227.06549 | E15: =2125901.35/10000 -> 212.59014 | F15: =2197000.88/10000 -> 219.70009 | O15: =SUM(C15:N15) -> 883.90237 | P15: =IFERROR(O15/B15,) -> 0.31200225
A16: 变动费用率 | C16: =IFERROR(C9/C4,) -> 0.024579263 | D16: =IFERROR(D9/D4,) -> 0.0077221167 | E16: =IFERROR(E9/E4,) -> 0.011235304 | F16: =IFERROR(F9/F4,) -> 0.024535918 | G16: =IFERROR(G9/G4,) -> 0 | H16: =IFERROR(H9/H4,) -> 0 | I16: =IFERROR(I9/I4,) -> 0 | J16: =IFERROR(J9/J4,) -> 0 | ... O16: =IFERROR(O9/O4,) -> 0.016452419
A18: EBITDA | B18: 3056.2075 | C18: =C4-C6-C9-C15 -> 309.20647 | D18: =D4-D6-D9-D15 -> 296.73437 | E18: =E4-E6-E9-E15 -> 885.00292 | F18: =F4-F6-F9-F15 -> 493.44928 | G18: =G4-G6-G9-G15 -> 0 | H18: =H4-H6-H9-H15 -> 0 | I18: =I4-I6-I9-I15 -> 0 | J18: =J4-J6-J9-J15 -> 0 | ... O18: =O4-O6-O9-O15 -> 1984.393 | P18: =IFERROR(O18/B18,) -> 0.64929918
A19: GOP | P19: =IFERROR(O19/B19,) -> 0
A21: 备注 | B21: EBITDA=营业收入-固定费用-变动费用-税金及附加
B22: GOP=营业收入-固定费用-变动费用-财务费用（不含利息费用）
B23: 需填列单元格

Sheet 费用预算执行明细
A1: 北京中言房地产开发有限公司2026年预算执行情况明细表
A2: 项目 | B2: 2026年预算 | C2: 2025年预算执行情况 | O2: 2025年实际 | P2: 执行率
C3: 1月 | D3: 2月 | E3: 3月 | F3: 4月 | G3: 5月 | H3: 6月 | I3: 7月 | J3: 8月 | K3: 9月 | L3: 10月 | M3: 11月 | N3: 12月
A4: 固定费用 | B4: =B5+B15 -> 637.27558 | C4: =C5+C15 -> 32.585219 | D4: =D5+D15 -> 39.025355 | E4: =E5+E15 -> 37.531035 | F4: =F5+F15 -> 37.76773 | G4: =G5+G15 -> 0 | H4: =H5+H15 -> 0 | I4: =I5+I15 -> 0 | ... N4: =N5+N15 -> 0 | O4: =SUM(C4:N4) -> 146.90934 | P4: =IFERROR(O4/B4,) -> 0.23052717
A5: 人力费用合计 | B5: =SUM(B6:B14) -> 484.75 | C5: =SUM(C6:C14) -> 32.253202 | D5: =SUM(D6:D14) -> 36.318083 | E5: =SUM(E6:E14) -> 35.989898 | F5: =SUM(F6:F14) -> 36.802752 | G5: =SUM(G6:G14) -> 0 | H5: =SUM(H6:H14) -> 0 | I5: =SUM(I6:I14) -> 0 | ... N5: =SUM(N6:N14) -> 0 | O5: =SUM(C5:N5) -> 141.36393 | P5: =IFERROR(O5/B5,) -> 0.29162235
A6: 固定工资 | B6: 297.72 | C6: =225310.64/10000 -> 22.531064 | D6: =247732.28/10000 -> 24.773228 | E6: =(250751.43)/10000 -> 25.075143 | F6: =260578.97/10000 -> 26.057897 | O6: =SUM(C6:N6) -> 98.437332 | P6: =IFERROR(O6/B6,) -> 0.33063728
A7: 绩效工资 | O7: =SUM(C7:N7) -> 0 | P7: =IFERROR(O7/B7,) -> 0
A8: 奖金 | O8: =SUM(C8:N8) -> 0 | P8: =IFERROR(O8/B8,) -> 0
A9: 福利费 | B9: 16.9 | C9: =3207.55/10000 -> 0.320755 | D9: =3886.79/10000+8000/10000 -> 1.188679 | E9: =(3886.79+1699)/10000 -> 0.558579 | F9: =3886.79/10000 -> 0.388679 | O9: =SUM(C9:N9) -> 2.456692 | P9: =IFERROR(O9/B9,) -> 0.14536639
A10: 五险一金 | B10: 130.06 | C10: =(29291+64722.83)/10000 -> 9.401383 | D10: =(32171+71390.76)/10000 -> 10.356176 | E10: =(32171+71390.76)/10000 -> 10.356176 | F10: =(32171+71390.76)/10000 -> 10.356176 | O10: =SUM(C10:N10) -> 40.469911 | P10: =IFERROR(O10/B10,) -> 0.31116339
A11: 工会经费 | B11: 5.95
A12: 辞退补偿 | B12: 25
A13: 招聘费 | B13: 3
A14: 其他人力费用 | B14: 6.12 | O14: =SUM(C14:N14) -> 0 | P14: =IFERROR(O14/B14,) -> 0
A15: 固定费用支出合计 | B15: =SUM(B16:B47) -> 152.52558 | C15: =SUM(C16:C47) -> 0.332017 | D15: =SUM(D16:D47) -> 2.707272 | E15: =SUM(E16:E47) -> 1.541137 | F15: =SUM(F16:F47) -> 0.964978 | G15: =SUM(G16:G47) -> 0 | H15: =SUM(H16:H47) -> 0 | I15: =SUM(I16:I47) -> 0 | ... N15: =SUM(N16:N47) -> 0 | O15: =SUM(C15:N15) -> 5.545404 | P15: =IFERROR(O15/B15,) -> 0.036357206
A16: 邮寄费 | B16: 0.5 | C16: =631.6/10000 -> 0.06316 | D16: =531.13/10000 -> 0.053113 | E16: =733.96/10000 -> 0.073396 | F16: =383.02/10000 -> 0.038302 | O16: =SUM(C16:N16) -> 0.227971 | P16: =IFERROR(O16/B16,) -> 0.455942
A17: 差旅费 | B17: 3.6 | C17: =1986.52/10000 -> 0.198652 | D17: =12371.6/10000 -> 1.23716 | E17: =2964.12/10000 -> 0.296412 | F17: =6511.5/10000 -> 0.65115 | O17: =SUM(C17:N17) -> 2.383374 | P17: =IFERROR(O17/B17,) -> 0.66204833
A18: 业务招待费 | B18: 2.4 | O18: =SUM(C18:N18) -> 0 | P18: =IFERROR(O18/B18,) -> 0
A19: 汽车费 | O19: =SUM(C19:N19) -> 0 | P19: =IFERROR(O19/B19,) -> 0
A20: 低值易耗品及修理费 | B20: 1.2 | C20: =532/10000 -> 0.0532 | E20: =2074.95/10000 -> 0.207495 | F20: =1718.9/10000 -> 0.17189 | O20: =SUM(C20:N20) -> 0.432585 | P20: =IFERROR(O20/B20,) -> 0.3604875
A21: 信息系统费 | B21: 4.39 | O21: =SUM(C21:N21) -> 0 | P21: =IFERROR(O21/B21,) -> 0
A22: 通讯费 | B22: 0.215583 | C22: =170.05/10000 -> 0.017005 | D22: =169.99/10000 -> 0.016999 | E22: =159.35/10000 -> 0.015935 | F22: =159.65/10000 -> 0.015965 | O22: =SUM(C22:N22) -> 0.065904 | P22: =IFERROR(O22/B22,) -> 0.30570128
A23: 交通费 | B23: 0.5 | E23: =63.9/10000 -> 0.00639 | F23: =282.8/10000+593.91/10000 -> 0.087671 | O23: =SUM(C23:N23) -> 0.094061 | P23: =IFERROR(O23/B23,) -> 0.188122
A24: 办公费 | O24: =SUM(C24:N24) -> 0 | P24: =IFERROR(O24/B24,) -> 0
A25: 会议费 | B25: 4 | O25: =SUM(C25:N25) -> 0 | P25: =IFERROR(O25/B25,) -> 0
A26: 水电费 | O26: =SUM(C26:N26) -> 0 | P26: =IFERROR(O26/B26,) -> 0
A27: 招聘费 | O27: =SUM(C27:N27) -> 0 | P27: =IFERROR(O27/B27,) -> 0
A28: 展览费 | O28: =SUM(C28:N28) -> 0 | P28: =IFERROR(O28/B28,) -> 0
A29: 培训费 | B29: 5.5
A30: 广告宣传费 | B30: 45 | O30: =SUM(C30:N30) -> 0 | P30: =IFERROR(O30/B30,) -> 0
A31: 咨询服务费 | B31: 13.22 | O31: =SUM(C31:N31) -> 0 | P31: =IFERROR(O31/B31,) -> 0
A32: 法律诉讼费 | B32: 9 | O32: =SUM(C32:N32) -> 0 | P32: =IFERROR(O32/B32,) -> 0
A33: 工作餐费 | O33: =SUM(C33:N33) -> 0 | P33: =IFERROR(O33/B33,) -> 0
A34: 报关及代理费 | O34: =SUM(C34:N34) -> 0 | P34: =IFERROR(O34/B34,) -> 0
A35: 研究开发费 | O35: =SUM(C35:N35) -> 0 | P35: =IFERROR(O35/B35,) -> 0
A36: 质检认证费 | B36: 10 | E36: =9415.09/10000 -> 0.941509 | O36: =SUM(C36:N36) -> 0.941509 | P36: =IFERROR(O36/B36,) -> 0.0941509
A37: 排污费 | O37: =SUM(C37:N37) -> 0 | P37: =IFERROR(O37/B37,) -> 0
A38: 社保服务费 | O38: =SUM(C38:N38) -> 0 | P38: =IFERROR(O38/B38,) -> 0
A39: 劳动保护费 | O39: =SUM(C39:N39) -> 0 | P39: =IFERROR(O39/B39,) -> 0
A40: 残疾人就业保障金 | O40: =SUM(C40:N40) -> 0 | P40: =IFERROR(O40/B40,) -> 0
...

Sheet 资本性支出计划与执行
A1: 北京中言房地产开发有限公司2026年资本性支出执行情况明细表
A2: 资产类别 | B2: 资产类型 | C2: 资产名称 | D2: 数量 | E2: 单价 | F2: 金额 | G2: 2026年预算 | H2: 2026年实际
A3: 无形资产 | B3: 办公软件 | C3: 办公软件 | H3: =F3 -> 0
A4: 其他长期支出 | B4: 长期待摊费用 | C4: 电动窗帘维保 | G4: 12 | H4: =F4 -> 0
B5: 长期待摊费用 | C5: 大堂钢结构防火喷涂更新 | G5: 80 | H5: =F5 -> 0
B6: 长期待摊费用 | C6: 新租客户精装交付装修费用 | G6: 60 | H6: =19359.42/10000 -> 1.935942
B7: 长期待摊费用 | C7: 高压配电室电容及直流屏电容更换 | G7: 20
B8: 长期待摊费用 | C8: 空调机组改造（君康VIP层） | G8: 15
B9: 长期待摊费用 | C9: IT机房用电改造 | G9: 60
B10: 长期待摊费用 | C10: 大厦结构漏水及外围石材维修 | G10: 80
B11: 长期待摊费用 | C11: 幕墙结构安全检测 | G11: 22
B12: 长期待摊费用 | C12: 28层改造费用 | G12: 10
B13: 长期待摊费用 | C13: 大堂增加大型LED宣传屏 | G13: 40
B14: 长期待摊费用 | C14: 高区智慧照明修复 | G14: 15
B15: 长期待摊费用 | C15: 地下停车场智能管理平台及照明节能改造等 | G15: 38
B16: 长期待摊费用 | C16: 大堂速通门人脸识别系统改造 | G16: 50 | H16: =F16 -> 0
B17: 长期待摊费用 | C17: 地下餐厅设施环境改造 | G17: 100 | H17: =F17 -> 0
B18: 长期待摊费用 | C18: 固定资产整理及管理系统 | G18: 15 | H18: =F18 -> 0
B19: 长期待摊费用 | C19: 空调系统板换清洗（冷热） | G19: 25 | H19: =F19 -> 0
B20: 在建工程 | C20: 历史遗留未决诉讼款（仅影响现金流量表期末余额） | G20: 200 | H20: =F20 -> 0
A21: 资本性支出合计 | G21: =SUM(G3:G20) -> 842 | H21: =SUM(H3:H20) -> 1.935942
A23: 需填列
