Workbook

Sheet 指标统计
A1: 大连君康凯丹置业有限公司2026年经营指标统计表
A2: 指标 | B2: 项目 | C2: 2026年预算 | D2: 2026年执行情况 | P2: 2025年实际 | Q2: 执行率 | R2: 指标说明
D3: 1月 | E3: 2月 | F3: 3月 | G3: 4月 | H3: 5月 | I3: 6月 | J3: 7月 | K3: 8月 | L3: 9月 | M3: 10月 | N3: 11月 | O3: 12月
A4: 经营指标 | B4: 营业收入 | C4: =预算执行汇总!B4 -> 0 | D4: 51.84 | E4: 52.73 | F4: 53.12 | G4: 63.87 | P4: =SUM(D4:O4) -> 221.56 | Q4: =IFERROR((P4-C4)/ABS(C4)+1,) -> 0
B5: EBITDA/GOP/扣非净利润 | D5: =预算执行汇总!C18 -> 27.46 | E5: =预算执行汇总!D18 -> 29.79 | F5: =预算执行汇总!E18 -> 26.62 | G5: =预算执行汇总!F18 -> 37.16 | P5: =SUM(D5:O5) -> 121.03 | Q5: =IFERROR(P5/C5,) -> 0 | R5: EBITDA（商写适用）/GOP（酒店适用）/扣非净利润（保险中介适用）
B6: 经营活动净现金流 | D6: 142.94 | E6: 51.65 | F6: 63.12 | G6: 4.81 | P6: =SUM(D6:O6) -> 262.52 | Q6: =IFERROR(P6/C6,) -> 0
A7: 财务指标 | B7: 经营支出小计 | D7: {=预算执行汇总!C5:N12} -> 10.86 | E7: 8.8 | F7: 10.79 | G7: 12.44 | H7: 0 | I7: 0 | J7: 0 | K7: 0 | L7: 0 | M7: 0 | N7: 0 | O7: 0 | P7: =SUM(D7:O7) -> 42.89 | Q7: =IFERROR(P7/C7,) -> 0
B8: 固定费用 | D8: 8.74 | E8: 8.8 | F8: 9.22 | G8: 12.36 | H8: 0 | I8: 0 | J8: 0 | K8: 0 | L8: 0 | M8: 0 | N8: 0 | O8: 0 | P8: =SUM(D8:O8) -> 39.12 | Q8: =IFERROR(P8/C8,) -> 0
B9: 人力费用 | D9: 6.35 | E9: 6.34 | F9: 6.4 | G9: 6.37 | H9: 0 | I9: 0 | J9: 0 | K9: 0 | L9: 0 | M9: 0 | N9: 0 | O9: 0 | P9: =SUM(D9:O9) -> 25.46 | Q9: =IFERROR(P9/C9,) -> 0
B10: 日常费用 | D10: 2.49 | E10: 2.46 | F10: 2.82 | G10: 5.99 | H10: 0 | I10: 0 | J10: 0 | K10: 0 | L10: 0 | M10: 0 | N10: 0 | O10: 0 | P10: =SUM(D10:O10) -> 13.76 | Q10: =IFERROR(P10/C10,) -> 0
B11: 变动费用 | D11: 2.12 | E11: 0 | F11: 1.57 | G11: 0.08 | H11: 0 | I11: 0 | J11: 0 | K11: 0 | L11: 0 | M11: 0 | N11: 0 | O11: 0 | P11: =SUM(D11:O11) -> 3.77 | Q11: =IFERROR(P11/C11,) -> 0
B12: 经营变动费用 | D12: 2.12 | E12: 0 | F12: 1.57 | G12: 0.08 | H12: 0 | I12: 0 | J12: 0 | K12: 0 | L12: 0 | M12: 0 | N12: 0 | O12: 0 | P12: =SUM(D12:O12) -> 3.77 | Q12: =IFERROR(P12/C12,) -> 0
B13: 营业成本 | D13: 0 | E13: 0 | F13: 0 | G13: 0 | H13: 0 | I13: 0 | J13: 0 | K13: 0 | L13: 0 | M13: 0 | N13: 0 | O13: 0 | P13: =SUM(D13:O13) -> 0 | Q13: =IFERROR(P13/C13,) -> 0
B14: 资本性支出 | D14: 4.72 | E14: 3.48 | F14: 0 | G14: 0 | H14: 0 | I14: 0 | J14: 0 | K14: 0 | L14: 0 | M14: 0 | N14: 0 | O14: 0 | P14: =SUM(D14:O14) -> 8.2 | Q14: =IFERROR(P14/C14,) -> 0
A15: 业务指标 | B15: 期末出租率/月均入住率 | D15: 0.715 | E15: 0.7308 | F15: 0.742 | G15: 0.7335 | P15: =E15 -> 0.7308 | Q15: =IFERROR(P15/C15,) -> 0 | R15: 期末出租率(商写适用)/月均入住率(酒店适用)
B16: 回款率 | D16: 1 | E16: 0.6565 | F16: 0.8889 | G16: 1 | Q16: =IFERROR(P16/C16,) -> 0 | R16: 商写及酒店适用
B17: OTA网络评价 | P17: {=IFERROR(INDEX(D17:O17,0,MATCH(9.99999999999999E+307,D17:O17)),)} -> 0 | Q17: =IFERROR(P17/C17,) -> 0 | R17: 酒店适用
B18: 期交规保 | P18: {=IFERROR(INDEX(D18:O18,0,MATCH(9.99999999999999E+307,D18:O18)),)} -> 0 | Q18: =IFERROR(P18/C18,) -> 0 | R18: 保险中介适用
B19: 13月继续率 | P19: {=IFERROR(INDEX(D19:O19,0,MATCH(9.99999999999999E+307,D19:O19)),)} -> 0 | Q19: =IFERROR(P19/C19,) -> 0 | R19: 保险中介适用
B20: 25月继续率 | P20: {=IFERROR(INDEX(D20:O20,0,MATCH(9.99999999999999E+307,D20:O20)),)} -> 0 | Q20: =IFERROR(P20/C20,) -> 0 | R20: 保险中介适用
A21: 备注 | B21: EBITDA=营业收入-固定费用-变动费用-税金及附加
B22: GOP=营业收入-固定费用-变动费用-财务费用（不含利息费用）
B23: 需填列单元格

Sheet 预算执行汇总
A1: 大连君康凯丹置业有限公司2026年预算执行情况汇总表
A2: 项目 | B2: 2026年预算 | C2: 2025年执行情况 | O2: 2025年实际 | P2: 执行率
C3: 1月 | D3: 2月 | E3: 3月 | F3: 4月 | G3: 5月 | H3: 6月 | I3: 7月 | J3: 8月 | K3: 9月 | L3: 10月 | M3: 11月 | N3: 12月
A4: 营业收入 | C4: 51.84 | D4: 52.73 | E4: 53.12 | F4: 63.87 | O4: =SUM(C4:N4) -> 221.56 | P4: =IFERROR(O4/B4,) -> 0
A5: 经营支出小计 | C5: =C6+C9 -> 10.86 | D5: =D6+D9 -> 8.8 | E5: =E6+E9 -> 10.79 | F5: =F6+F9 -> 12.44 | O5: =SUM(C5:N5) -> 42.89 | P5: =IFERROR(O5/B5,) -> 0
A6: 固定费用 | C6: =费用预算执行明细!C4 -> 8.74 | D6: =D7+D8 -> 8.8 | E6: 9.22 | F6: =费用预算执行明细!F4 -> 12.36 | O6: =SUM(C6:N6) -> 39.12 | P6: =IFERROR(O6/B6,) -> 0
A7: 人力费用 | C7: 6.35 | D7: 6.34 | E7: 6.4 | F7: =费用预算执行明细!F5 -> 6.37 | O7: =SUM(C7:N7) -> 25.46 | P7: =IFERROR(O7/B7,) -> 0
A8: 日常费用 | C8: =费用预算执行明细!C12 -> 2.49 | D8: 2.46 | E8: 2.82 | F8: =费用预算执行明细!F12 -> 5.99 | O8: =SUM(C8:N8) -> 13.76 | P8: =IFERROR(O8/B8,) -> 0
A9: 变动费用 | C9: 2.12 | E9: 1.57 | F9: =F10+F11 -> 0.08 | O9: =SUM(C9:N9) -> 3.77 | P9: =IFERROR(O9/B9,) -> 0
A10: 经营变动费用支出 | C10: =费用预算执行明细!C45 -> 2.12 | E10: 1.57 | F10: =费用预算执行明细!F44 -> 0.08 | O10: =SUM(C10:N10) -> 3.77 | P10: =IFERROR(O10/B10,) -> 0
A11: 营业成本支出 | B11: 0 | C11: =费用预算执行明细!C78 -> 0 | D11: =费用预算执行明细!D78 -> 0 | E11: =费用预算执行明细!E78 -> 0 | F11: =费用预算执行明细!F78 -> 0 | G11: =费用预算执行明细!G78 -> 0 | H11: =费用预算执行明细!H78 -> 0 | I11: =费用预算执行明细!I78 -> 0 | J11: =费用预算执行明细!J78 -> 0 | ... N11: =费用预算执行明细!N78 -> 0 | O11: =SUM(C11:N11) -> 0 | P11: =IFERROR(O11/B11,) -> 0
A12: 资本性支出 | C12: 4.72 | D12: 3.48 | O12: =SUM(C12:N12) -> 8.2 | P12: =IFERROR(O12/B12,) -> 0
A13: 折旧摊销 | C13: 0.88 | D13: 1.24 | E13: 1.43 | F13: 1.43 | O13: =SUM(C13:N13) -> 4.98 | P13: =IFERROR(O13/B13,) -> 0
A14: 财务费用 | C14: -1.19 | E14: 0.25 | O14: =SUM(C14:N14) -> -0.94 | P14: =IFERROR(O14/B14,) -> 0
A15: 税金及附加 | C15: 14.71 | D15: 14.14 | E15: 15.46 | F15: 14.27 | O15: =SUM(C15:N15) -> 58.58 | P15: =IFERROR(O15/B15,) -> 0
A16: 变动费用率 | B16: =B9/B4 -> #DIV/0! | C16: =IFERROR(C9/C4,) -> 0.040895062 | D16: =IFERROR(D9/D4,) -> 0 | E16: =IFERROR(E9/E4,) -> 0.029555723 | F16: =IFERROR(F9/F4,) -> 0.0012525442 | G16: =IFERROR(G9/G4,) -> 0 | H16: =IFERROR(H9/H4,) -> 0 | I16: =IFERROR(I9/I4,) -> 0 | J16: =IFERROR(J9/J4,) -> 0 | ... O16: =IFERROR(O9/O4,) -> 0.017015707
A18: EBITDA | C18: =C4-C6-C9-C15-C14 -> 27.46 | D18: =D4-D6-D9-D15-D14 -> 29.79 | E18: =E4-E6-E9-E15-E14 -> 26.62 | F18: =F4-F6-F9-F15-F14 -> 37.16 | G18: =G4-G6-G9-G15-G14 -> 0 | H18: =H4-H6-H9-H15-H14 -> 0 | I18: =I4-I6-I9-I15-I14 -> 0 | J18: =J4-J6-J9-J15-J14 -> 0 | ... O18: =O4-O6-O9-O15-O14 -> 121.03 | P18: =IFERROR(O18/B18,) -> 0
A19: GOP | P19: =IFERROR(O19/B19,) -> 0
A21: 备注 | B21: EBITDA=营业收入-固定费用-变动费用-税金及附加
B22: GOP=营业收入-固定费用-变动费用-财务费用（不含利息费用）
B23: 需填列单元格

Sheet 费用预算执行明细
A1: 大连君康凯丹置业有限公司2026年预算执行情况明细表
A2: 项目 | B2: 2026年预算 | C2: 2026年预算执行情况 | O2: 2025年实际 | P2: 执行率
C3: 1月 | D3: 2月 | E3: 3月 | F3: 4月 | G3: 5月 | H3: 6月 | I3: 7月 | J3: 8月 | K3: 9月 | L3: 10月 | M3: 11月 | N3: 12月
A4: 固定费用 | B4: =B5+B12 -> 0 | C4: =C5+C12 -> 8.74 | D4: =D5+D12 -> 8.85 | E4: =E5+E12 -> 8.9 | F4: =F5+F12 -> 12.36 | G4: =G5+G12 -> 0 | H4: =H5+H12 -> 0 | I4: =I5+I12 -> 0 | ... N4: =N5+N12 -> 0 | O4: =SUM(C4:N4) -> 38.85 | P4: =IFERROR(O4/B4,) -> 0
A5: 人力费用合计 | B5: =SUM(B6:B11) -> 0 | C5: =SUM(C6:C11) -> 6.25 | D5: =SUM(D6:D11) -> 6.39 | E5: =SUM(E6:E11) -> 6.4 | F5: =SUM(F6:F11) -> 6.37 | G5: =SUM(G6:G11) -> 0 | H5: =SUM(H6:H11) -> 0 | I5: =SUM(I6:I11) -> 0 | ... N5: =SUM(N6:N11) -> 0 | O5: =SUM(C5:N5) -> 25.41 | P5: =IFERROR(O5/B5,) -> 0
A6: 固定工资 | C6: 4.25 | D6: 4.23 | E6: 4.32 | F6: 4.3 | O6: =SUM(C6:N6) -> 17.1 | P6: =IFERROR(O6/B6,) -> 0
A7: 绩效工资 | O7: =SUM(C7:N7) -> 0 | P7: =IFERROR(O7/B7,) -> 0
A8: 奖金 | O8: =SUM(C8:N8) -> 0 | P8: =IFERROR(O8/B8,) -> 0
A9: 福利费 | C9: 0.1 | D9: 0.1 | E9: 0.1 | F9: 0.09 | O9: =SUM(C9:N9) -> 0.39 | P9: =IFERROR(O9/B9,) -> 0
A10: 社会保险费 | C10: 1.27 | D10: 1.43 | E10: 1.35 | F10: 1.35 | O10: =SUM(C10:N10) -> 5.4 | P10: =IFERROR(O10/B10,) -> 0
A11: 住房公积金 | C11: 0.63 | D11: 0.63 | E11: 0.63 | F11: 0.63 | O11: =SUM(C11:N11) -> 2.52 | P11: =IFERROR(O11/B11,) -> 0
A12: 固定费用支出合计 | B12: =SUM(B13:B43) -> 0 | C12: =SUM(C13:C43) -> 2.49 | D12: =SUM(D13:D43) -> 2.46 | E12: =SUM(E13:E43) -> 2.5 | F12: =SUM(F13:F43) -> 5.99 | G12: =SUM(G13:G43) -> 0 | H12: =SUM(H13:H43) -> 0 | I12: =SUM(I13:I43) -> 0 | ... N12: =SUM(N13:N43) -> 0 | O12: =SUM(C12:N12) -> 13.44 | P12: =IFERROR(O12/B12,) -> 0
A13: 邮寄费 | C13: 0.03 | E13: 0.04 | F13: 0.02 | O13: =SUM(C13:N13) -> 0.09 | P13: =IFERROR(O13/B13,) -> 0
A14: 差旅费 | O14: =SUM(C14:N14) -> 0 | P14: =IFERROR(O14/B14,) -> 0
A15: 业务招待费 | O15: =SUM(C15:N15) -> 0 | P15: =IFERROR(O15/B15,) -> 0
A16: 汽车费 | O16: =SUM(C16:N16) -> 0 | P16: =IFERROR(O16/B16,) -> 0
A17: 低值易耗品及修理费 | O17: =SUM(C17:N17) -> 0 | P17: =IFERROR(O17/B17,) -> 0
A18: 信息系统费 | O18: =SUM(C18:N18) -> 0 | P18: =IFERROR(O18/B18,) -> 0
A19: 通讯费 | O19: =SUM(C19:N19) -> 0 | P19: =IFERROR(O19/B19,) -> 0
A20: 交通费 | O20: =SUM(C20:N20) -> 0 | P20: =IFERROR(O20/B20,) -> 0
A21: 办公费 | O21: =SUM(C21:N21) -> 0 | P21: =IFERROR(O21/B21,) -> 0
A22: 会议费 | O22: =SUM(C22:N22) -> 0 | P22: =IFERROR(O22/B22,) -> 0
A23: 水电费 | O23: =SUM(C23:N23) -> 0 | P23: =IFERROR(O23/B23,) -> 0
A24: 招聘费 | O24: =SUM(C24:N24) -> 0 | P24: =IFERROR(O24/B24,) -> 0
A25: 展览费 | O25: =SUM(C25:N25) -> 0 | P25: =IFERROR(O25/B25,) -> 0
A26: 广告宣传费 | O26: =SUM(C26:N26) -> 0 | P26: =IFERROR(O26/B26,) -> 0
A27: 咨询服务费 | F27: 3.5 | O27: =SUM(C27:N27) -> 3.5 | P27: =IFERROR(O27/B27,) -> 0
A28: 法律诉讼费 | F28: 0.01 | O28: =SUM(C28:N28) -> 0.01 | P28: =IFERROR(O28/B28,) -> 0
A29: 工作餐费 | O29: =SUM(C29:N29) -> 0 | P29: =IFERROR(O29/B29,) -> 0
A30: 报关及代理费 | O30: =SUM(C30:N30) -> 0 | P30: =IFERROR(O30/B30,) -> 0
A31: 研究开发费 | O31: =SUM(C31:N31) -> 0 | P31: =IFERROR(O31/B31,) -> 0
A32: 质检认证费 | O32: =SUM(C32:N32) -> 0 | P32: =IFERROR(O32/B32,) -> 0
A33: 排污费 | O33: =SUM(C33:N33) -> 0 | P33: =IFERROR(O33/B33,) -> 0
A34: 社保服务费 | O34: =SUM(C34:N34) -> 0 | P34: =IFERROR(O34/B34,) -> 0
A35: 劳动保护费 | O35: =SUM(C35:N35) -> 0 | P35: =IFERROR(O35/B35,) -> 0
A36: 残疾人就业保障金 | O36: =SUM(C36:N36) -> 0 | P36: =IFERROR(O36/B36,) -> 0
A37: 财产保险费 | O37: =SUM(C37:N37) -> 0 | P37: =IFERROR(O37/B37,) -> 0
A38: 房租及物业费 | C38: 2.46 | D38: 2.46 | E38: 2.46 | F38: 2.46 | O38: =SUM(C38:N38) -> 9.84 | P38: =IFERROR(O38/B38,) -> 0
A39: 开办费 | O39: =SUM(C39:N39) -> 0 | P39: =IFERROR(O39/B39,) -> 0
A40: 存货盘存 | O40: =SUM(C40:N40) -> 0 | P40: =IFERROR(O40/B40,) -> 0
...

Sheet 资本性支出计划与执行
A1: 大连君康凯丹置业有限公司2026年资本性支出执行情况明细表
A2: 资产类别 | B2: 资产类型 | C2: 资产名称 | D2: 数量 | E2: 单价 | F2: 金额 | G2: 2026年预算 | H2: 2026年实际
A3: 固定资产
C4: 电梯维修 | D4: 1 | E4: 3.49 | F4: 3.49 | H4: 3.49
C5: 空调维修 | D5: 1 | E5: 1.23 | F5: 1.23 | H5: 1.23
C6: 电梯维修 | D6: 1 | E6: 3.48 | F6: 3.48 | H6: 3.48
A15: 资本性支出合计 | G15: =SUM(G4:G14) -> 0 | H15: =SUM(H4:H14) -> 8.2
A17: 需填列
