Workbook

Sheet 指标统计
A1: 重庆宜新商业管理有限公司2026年经营指标统计表
A2: 指标 | B2: 项目 | C2: 2026年预算 | D2: 2026年执行情况 | P2: 2026年实际 | Q2: 执行率 | R2: 指标说明
D3: 1月 | E3: 2月 | F3: 3月 | G3: 4月 | H3: 5月 | I3: 6月 | J3: 7月 | K3: 8月 | L3: 9月 | M3: 10月 | N3: 11月 | O3: 12月
A4: 经营指标 | B4: 营业收入 | C4: =预算执行汇总!B4 -> 709.51636 | D4: {=预算执行汇总!C4:N4} -> 51.121052 | E4: 28.623522 | F4: 50.833071 | G4: 31.674646 | H4: 0 | I4: 0 | J4: 0 | K4: 0 | L4: 0 | M4: 0 | N4: 0 | O4: 0 | P4: =SUM(D4:O4) -> 162.25229 | Q4: =IFERROR((P4-C4)/ABS(C4)+1,) -> 0.22868013
B5: EBITDA/GOP/扣非净利润 | C5: =预算执行汇总!B19 -> 190.72038 | D5: =预算执行汇总!C19 -> 45.562446 | E5: =预算执行汇总!D19 -> 23.283589 | F5: =预算执行汇总!E19 -> 3.393221 | G5: =预算执行汇总!F19 -> -116.28951 | P5: =SUM(D5:O5) -> -44.050255 | Q5: =IFERROR(P5/C5,) -> -0.23096774 | R5: EBITDA（商写适用）/GOP（酒店适用）/扣非净利润（保险中介适用）
B6: 经营活动净现金流 | C6: 259.62622 | D6: 27.423488 | E6: 11.955679 | F6: 66.988168 | G6: -115.15762 | P6: =SUM(D6:O6) -> -8.790282 | Q6: =IFERROR(P6/C6,) -> -0.033857451
A7: 财务指标 | B7: 经营支出小计 | C7: {=预算执行汇总!B5:B12} -> 268.66369 | D7: {=预算执行汇总!C5:N12} -> 5.135138 | E7: 5.14162 | F7: 47.184892 | G7: 5.15811 | H7: 0 | I7: 0 | J7: 0 | K7: 0 | L7: 0 | M7: 0 | N7: 0 | O7: 0 | P7: =SUM(D7:O7) -> 62.61976 | Q7: =IFERROR(P7/C7,) -> 0.23307861
B8: 固定费用 | C8: 89.223688 | D8: 5.135138 | E8: 5.133978 | F8: 5.119921 | G8: 5.15811 | H8: 0 | I8: 0 | J8: 0 | K8: 0 | L8: 0 | M8: 0 | N8: 0 | O8: 0 | P8: =SUM(D8:O8) -> 20.547147 | Q8: =IFERROR(P8/C8,) -> 0.23028803
B9: 人力费用 | C9: 56.812 | D9: 4.15351 | E9: 4.15751 | F9: 4.16351 | G9: 4.18151 | H9: 0 | I9: 0 | J9: 0 | K9: 0 | L9: 0 | M9: 0 | N9: 0 | O9: 0 | P9: =SUM(D9:O9) -> 16.65604 | Q9: =IFERROR(P9/C9,) -> 0.2931782
B10: 日常费用 | C10: 32.411688 | D10: 0.981628 | E10: 0.976468 | F10: 0.956411 | G10: 0.9766 | H10: 0 | I10: 0 | J10: 0 | K10: 0 | L10: 0 | M10: 0 | N10: 0 | O10: 0 | P10: =SUM(D10:O10) -> 3.891107 | Q10: =IFERROR(P10/C10,) -> 0.12005259
B11: 变动费用 | C11: 179.44 | D11: 0 | E11: 0.007642 | F11: 42.064971 | G11: 0 | H11: 0 | I11: 0 | J11: 0 | K11: 0 | L11: 0 | M11: 0 | N11: 0 | O11: 0 | P11: =SUM(D11:O11) -> 42.072613 | Q11: =IFERROR(P11/C11,) -> 0.23446619
B12: 经营变动费用 | C12: 179.44 | D12: 0 | E12: 0.007642 | F12: 42.064971 | G12: 0 | H12: 0 | I12: 0 | J12: 0 | K12: 0 | L12: 0 | M12: 0 | N12: 0 | O12: 0 | P12: =SUM(D12:O12) -> 42.072613 | Q12: =IFERROR(P12/C12,) -> 0.23446619
B13: 营业成本 | C13: 0 | D13: 0 | E13: 0 | F13: 0 | G13: 0 | H13: 0 | I13: 0 | J13: 0 | K13: 0 | L13: 0 | M13: 0 | N13: 0 | O13: 0 | P13: =SUM(D13:O13) -> 0 | Q13: =IFERROR(P13/C13,) -> 0
B14: 资本性支出 | C14: 0 | D14: 0 | E14: 0 | F14: 0 | G14: 0 | H14: 0 | I14: 0 | J14: 0 | K14: 0 | L14: 0 | M14: 0 | N14: 0 | O14: 0 | P14: =SUM(D14:O14) -> 0 | Q14: =IFERROR(P14/C14,) -> 0
A15: 业务指标 | B15: 期末出租率/月均入住率 | C15: 0.5805 | D15: 0.4458 | E15: 0.4458 | F15: 0.431 | G15: 0.43 | P15: =IFERROR(AVERAGE(D15:O15),) -> 0.43815 | Q15: =D15/C15 -> 0.76795866 | R15: 期末出租率(商写适用)/月均入住率(酒店适用)
B16: 回款率 | C16: 0.95 | D16: 0.55 | E16: 0.99 | F16: 7.94 | G16: 0.32 | P16: =IFERROR(AVERAGE(D16:O16),) -> 2.45 | Q16: =IFERROR(P16/C16,) -> 2.5789474 | R16: 商写及酒店适用
B17: OTA网络评价 | P17: {=IFERROR(INDEX(D17:O17,0,MATCH(9.99999999999999E+307,D17:O17)),)} -> 0 | Q17: =IFERROR(P17/C17,) -> 0 | R17: 酒店适用
B18: 期交规保 | P18: {=IFERROR(INDEX(D18:O18,0,MATCH(9.99999999999999E+307,D18:O18)),)} -> 0 | Q18: =IFERROR(P18/C18,) -> 0 | R18: 保险中介适用
B19: 13月继续率 | P19: {=IFERROR(INDEX(D19:O19,0,MATCH(9.99999999999999E+307,D19:O19)),)} -> 0 | Q19: =IFERROR(P19/C19,) -> 0 | R19: 保险中介适用
B20: 25月继续率 | P20: {=IFERROR(INDEX(D20:O20,0,MATCH(9.99999999999999E+307,D20:O20)),)} -> 0 | Q20: =IFERROR(P20/C20,) -> 0 | R20: 保险中介适用
A21: 备注 | B21: EBITDA=营业收入-固定费用-变动费用-税金及附加+利息收入
B22: GOP=营业收入-固定费用-变动费用-财务费用（不含利息费用）
B23: 需填列单元格

Sheet 预算执行汇总
A1: 重庆宜新商业管理有限公司2026年预算执行情况汇总表
A2: 项目 | B2: 2026年预算 | C2: 2026年执行情况 | O2: 2026年实际 | P2: 执行率
C3: 1月 | D3: 2月 | E3: 3月 | F3: 4月 | G3: 5月 | H3: 6月 | I3: 7月 | J3: 8月 | K3: 9月 | L3: 10月 | M3: 11月 | N3: 12月
A4: 营业收入 | B4: 709.51636 | C4: 51.121052 | D4: 28.623522 | E4: 50.833071 | F4: 31.674646 | O4: =SUM(C4:N4) -> 162.25229 | P4: =IFERROR(O4/B4,) -> 0.22868013
A5: 经营支出小计 | B5: =B6+B9 -> 268.66369 | C5: =C6+C9 -> 5.135138 | D5: =D6+D9 -> 5.14162 | E5: =E6+E9 -> 47.184892 | F5: =F6+F9 -> 5.15811 | G5: =G6+G9 -> 0 | H5: =H6+H9 -> 0 | I5: =I6+I9 -> 0 | ... N5: =N6+N9 -> 0 | O5: =SUM(C5:N5) -> 62.61976 | P5: =IFERROR(O5/B5,) -> 0.23307861
A6: 固定费用 | B6: =费用预算执行明细!B4 -> 89.223688 | C6: =费用预算执行明细!C4 -> 5.135138 | D6: =费用预算执行明细!D4 -> 5.133978 | E6: =费用预算执行明细!E4 -> 5.119921 | F6: =费用预算执行明细!F4 -> 5.15811 | G6: =费用预算执行明细!G4 -> 0 | H6: =费用预算执行明细!H4 -> 0 | I6: =费用预算执行明细!I4 -> 0 | ... N6: =费用预算执行明细!N4 -> 0 | O6: =SUM(C6:N6) -> 20.547147 | P6: =IFERROR(O6/B6,) -> 0.23028803
A7: 人力费用 | B7: =费用预算执行明细!B5 -> 56.812 | C7: =费用预算执行明细!C5 -> 4.15351 | D7: =费用预算执行明细!D5 -> 4.15751 | E7: =费用预算执行明细!E5 -> 4.16351 | F7: =费用预算执行明细!F5 -> 4.18151 | G7: =费用预算执行明细!G5 -> 0 | H7: =费用预算执行明细!H5 -> 0 | I7: =费用预算执行明细!I5 -> 0 | ... N7: =费用预算执行明细!N5 -> 0 | O7: =SUM(C7:N7) -> 16.65604 | P7: =IFERROR(O7/B7,) -> 0.2931782
A8: 日常费用 | B8: =费用预算执行明细!B12 -> 32.411688 | C8: =费用预算执行明细!C12 -> 0.981628 | D8: =费用预算执行明细!D12 -> 0.976468 | E8: =费用预算执行明细!E12 -> 0.956411 | F8: =费用预算执行明细!F12 -> 0.9766 | G8: =费用预算执行明细!G12 -> 0 | H8: =费用预算执行明细!H12 -> 0 | I8: =费用预算执行明细!I12 -> 0 | ... N8: =费用预算执行明细!N12 -> 0 | O8: =SUM(C8:N8) -> 3.891107 | P8: =IFERROR(O8/B8,) -> 0.12005259
A9: 变动费用 | B9: =费用预算执行明细!B44 -> 179.44 | C9: =费用预算执行明细!C44 -> 0 | D9: =费用预算执行明细!D44 -> 0.007642 | E9: =费用预算执行明细!E44 -> 42.064971 | F9: =费用预算执行明细!F44 -> 0 | G9: =费用预算执行明细!G44 -> 0 | H9: =费用预算执行明细!H44 -> 0 | I9: =费用预算执行明细!I44 -> 0 | ... N9: =费用预算执行明细!N44 -> 0 | O9: =SUM(C9:N9) -> 42.072613 | P9: =IFERROR(O9/B9,) -> 0.23446619
A10: 经营变动费用支出 | B10: =费用预算执行明细!B44 -> 179.44 | C10: =费用预算执行明细!C45 -> 0 | D10: =费用预算执行明细!D45 -> 0.007642 | E10: =费用预算执行明细!E45 -> 42.064971 | F10: =费用预算执行明细!F45 -> 0 | G10: =费用预算执行明细!G45 -> 0 | H10: =费用预算执行明细!H45 -> 0 | I10: =费用预算执行明细!I45 -> 0 | J10: =费用预算执行明细!J45 -> 0 | ... N10: =费用预算执行明细!N45 -> 0 | O10: =SUM(C10:N10) -> 42.072613 | P10: =IFERROR(O10/B10,) -> 0.23446619
A11: 营业成本支出 | C11: =费用预算执行明细!C78 -> 0 | D11: =费用预算执行明细!D78 -> 0 | E11: =费用预算执行明细!E78 -> 0 | F11: =费用预算执行明细!F78 -> 0 | G11: =费用预算执行明细!G78 -> 0 | H11: =费用预算执行明细!H78 -> 0 | I11: =费用预算执行明细!I78 -> 0 | J11: =费用预算执行明细!J78 -> 0 | ... N11: =费用预算执行明细!N78 -> 0 | O11: =SUM(C11:N11) -> 0 | P11: =IFERROR(O11/B11,) -> 0
A12: 资本性支出 | B12: =资本性支出计划与执行!G15 -> 0 | C12: 0 | D12: 0 | E12: 0 | F12: 0 | O12: =SUM(C12:N12) -> 0 | P12: =IFERROR(O12/B12,) -> 0
A13: 折旧摊销 | B13: 1269.43 | C13: 105.7862 | D13: 105.7862 | E13: 105.7862 | F13: 105.7862 | O13: =SUM(C13:N13) -> 423.14479 | P13: =IFERROR(O13/B13,) -> 0.33333448
A14: 财务费用 | B14: -22.96 | C14: 0.130051 | D14: 0.092127 | E14: 0.01561 | F14: 0.087507 | O14: =SUM(C14:N14) -> 0.325295 | P14: =IFERROR(O14/B14,) -> -0.014167901
A15: 利息收入 | B15: 23.2 | C15: 0 | D15: 0 | E15: 0.081542 | F15: 0 | O15: =SUM(C15:N15) -> 0.081542 | P15: =IFERROR(O15/B15,) -> 0.0035147414
A16: 税金及附加 | B16: 282.33229 | C16: 0.423468 | D16: 0.198313 | E16: 0.3365 | F16: 142.80605 | O16: =SUM(C16:N16) -> 143.76433 | P16: =IFERROR(O16/B16,) -> 0.50920257
A17: 变动费用率 | B17: =B9/B4 -> 0.25290467 | C17: =IFERROR(C9/C4,) -> 0 | D17: =IFERROR(D9/D4,) -> 0.00026698322 | E17: =IFERROR(E9/E4,) -> 0.8275119 | F17: =IFERROR(F9/F4,) -> 0 | G17: =IFERROR(G9/G4,) -> 0 | H17: =IFERROR(H9/H4,) -> 0 | I17: =IFERROR(I9/I4,) -> 0 | J17: =IFERROR(J9/J4,) -> 0 | ... O17: =IFERROR(O9/O4,) -> 0.25930366
A19: EBITDA | B19: =B4-B5-B16+B15+9 -> 190.72038 | C19: =C4-C6-C9-C16+C15 -> 45.562446 | D19: =D4-D6-D9-D16+D15 -> 23.283589 | E19: =E4-E6-E9-E16+E15 -> 3.393221 | F19: =F4-F6-F9-F16+F15 -> -116.28951 | G19: =G4-G6-G9-G16+G15 -> 0 | H19: =H4-H6-H9-H16+H15 -> 0 | I19: =I4-I6-I9-I16+I15 -> 0 | J19: =J4-J6-J9-J16+J15 -> 0 | ... O19: =O4-O6-O9-O16+O15 -> -44.050255 | P19: =IFERROR(O19/B19,) -> -0.23096774
A20: GOP | P20: =IFERROR(O20/B20,) -> 0
A22: 备注 | B22: EBITDA=营业收入-固定费用-变动费用-税金及附加+利息收入
B23: GOP=营业收入-固定费用-变动费用-财务费用（不含利息费用）
B24: 需填列单元格

Sheet 费用预算执行明细
A1: 重庆宜新商业管理有限公司2026年预算执行情况明细表
A2: 项目 | B2: 2026年预算 | C2: 2026年预算执行情况 | O2: 2026年实际 | P2: 执行率
C3: 1月 | D3: 2月 | E3: 3月 | F3: 4月 | G3: 5月 | H3: 6月 | I3: 7月 | J3: 8月 | K3: 9月 | L3: 10月 | M3: 11月 | N3: 12月
A4: 固定费用 | B4: =B5+B12 -> 89.223688 | C4: =C5+C12 -> 5.135138 | D4: =D5+D12 -> 5.133978 | E4: =E5+E12 -> 5.119921 | F4: =F5+F12 -> 5.15811 | G4: =G5+G12 -> 0 | H4: =H5+H12 -> 0 | I4: =I5+I12 -> 0 | ... N4: =N5+N12 -> 0 | O4: =SUM(C4:N4) -> 20.547147 | P4: =IFERROR(O4/B4,) -> 0.23028803
A5: 人力费用合计 | B5: =SUM(B6:B11) -> 56.812 | C5: =SUM(C6:C11) -> 4.15351 | D5: =SUM(D6:D11) -> 4.15751 | E5: =SUM(E6:E11) -> 4.16351 | F5: =SUM(F6:F11) -> 4.18151 | G5: =SUM(G6:G11) -> 0 | H5: =SUM(H6:H11) -> 0 | I5: =SUM(I6:I11) -> 0 | ... N5: =SUM(N6:N11) -> 0 | O5: =SUM(C5:N5) -> 16.65604 | P5: =IFERROR(O5/B5,) -> 0.2931782
A6: 固定工资 | B6: 40.8 | C6: 3.2 | D6: 3.2 | E6: 3.2 | F6: 3.2 | O6: =SUM(C6:N6) -> 12.8 | P6: =IFERROR(O6/B6,) -> 0.31372549
A7: 绩效工资 | O7: =SUM(C7:N7) -> 0 | P7: =IFERROR(O7/B7,) -> 0
A8: 奖金 | B8: 0.1 | O8: =SUM(C8:N8) -> 0 | P8: =IFERROR(O8/B8,) -> 0
A9: 福利费 | B9: 2.712 | C9: 0.148 | D9: 0.152 | E9: 0.158 | F9: 0.176 | O9: =SUM(C9:N9) -> 0.634 | P9: =IFERROR(O9/B9,) -> 0.23377581
A10: 五险一金 | B10: 10.2 | C10: 0.80551 | D10: 0.80551 | E10: 0.80551 | F10: 0.80551 | O10: =SUM(C10:N10) -> 3.22204 | P10: =IFERROR(O10/B10,) -> 0.31588627
A11: 其他人力费用 | B11: 3 | O11: =SUM(C11:N11) -> 0 | P11: =IFERROR(O11/B11,) -> 0
A12: 固定费用支出合计 | B12: =SUM(B13:B43) -> 32.411688 | C12: =SUM(C13:C43) -> 0.981628 | D12: =SUM(D13:D43) -> 0.976468 | E12: =SUM(E13:E43) -> 0.956411 | F12: =SUM(F13:F43) -> 0.9766 | G12: =SUM(G13:G43) -> 0 | H12: =SUM(H13:H43) -> 0 | I12: =SUM(I13:I43) -> 0 | ... N12: =SUM(N13:N43) -> 0 | O12: =SUM(C12:N12) -> 3.891107 | P12: =IFERROR(O12/B12,) -> 0.12005259
A13: 邮寄费 | B13: 0.48 | C13: 0.025217 | D13: 0.020057 | F13: 0.020189 | O13: =SUM(C13:N13) -> 0.065463 | P13: =IFERROR(O13/B13,) -> 0.13638125
A14: 差旅费 | B14: 0.9 | O14: =SUM(C14:N14) -> 0 | P14: =IFERROR(O14/B14,) -> 0
A15: 业务招待费 | O15: =SUM(C15:N15) -> 0 | P15: =IFERROR(O15/B15,) -> 0
A16: 汽车费 | O16: =SUM(C16:N16) -> 0 | P16: =IFERROR(O16/B16,) -> 0
A17: 低值易耗品及修理费 | O17: =SUM(C17:N17) -> 0 | P17: =IFERROR(O17/B17,) -> 0
A18: 信息系统费 | B18: 0.01 | O18: =SUM(C18:N18) -> 0 | P18: =IFERROR(O18/B18,) -> 0
A19: 通讯费 | O19: =SUM(C19:N19) -> 0 | P19: =IFERROR(O19/B19,) -> 0
A20: 交通费 | O20: =SUM(C20:N20) -> 0 | P20: =IFERROR(O20/B20,) -> 0
A21: 办公费 | B21: 0.24 | O21: =SUM(C21:N21) -> 0 | P21: =IFERROR(O21/B21,) -> 0
A22: 会议费 | O22: =SUM(C22:N22) -> 0 | P22: =IFERROR(O22/B22,) -> 0
A23: 水电费 | O23: =SUM(C23:N23) -> 0 | P23: =IFERROR(O23/B23,) -> 0
A24: 招聘费 | O24: =SUM(C24:N24) -> 0 | P24: =IFERROR(O24/B24,) -> 0
A25: 展览费 | O25: =SUM(C25:N25) -> 0 | P25: =IFERROR(O25/B25,) -> 0
A26: 广告宣传费 | O26: =SUM(C26:N26) -> 0 | P26: =IFERROR(O26/B26,) -> 0
A27: 咨询服务费 | B27: 13 | O27: =SUM(C27:N27) -> 0 | P27: =IFERROR(O27/B27,) -> 0
A28: 法律诉讼费 | O28: =SUM(C28:N28) -> 0 | P28: =IFERROR(O28/B28,) -> 0
A29: 工作餐费 | O29: =SUM(C29:N29) -> 0 | P29: =IFERROR(O29/B29,) -> 0
A30: 报关及代理费 | O30: =SUM(C30:N30) -> 0 | P30: =IFERROR(O30/B30,) -> 0
A31: 研究开发费 | O31: =SUM(C31:N31) -> 0 | P31: =IFERROR(O31/B31,) -> 0
A32: 质检认证费 | O32: =SUM(C32:N32) -> 0 | P32: =IFERROR(O32/B32,) -> 0
A33: 排污费 | O33: =SUM(C33:N33) -> 0 | P33: =IFERROR(O33/B33,) -> 0
A34: 社保服务费 | O34: =SUM(C34:N34) -> 0 | P34: =IFERROR(O34/B34,) -> 0
A35: 劳动保护费 | O35: =SUM(C35:N35) -> 0 | P35: =IFERROR(O35/B35,) -> 0
A36: 残疾人就业保障金 | O36: =SUM(C36:N36) -> 0 | P36: =IFERROR(O36/B36,) -> 0
A37: 财产保险费 | B37: 5.1 | O37: =SUM(C37:N37) -> 0 | P37: =IFERROR(O37/B37,) -> 0
A38: 房租及物业费 | B38: 12.681688 | C38: 0.956411 | D38: 0.956411 | E38: 0.956411 | F38: 0.956411 | O38: =SUM(C38:N38) -> 3.825644 | P38: =IFERROR(O38/B38,) -> 0.30166678
A39: 开办费 | O39: =SUM(C39:N39) -> 0 | P39: =IFERROR(O39/B39,) -> 0
A40: 存货盘存 | O40: =SUM(C40:N40) -> 0 | P40: =IFERROR(O40/B40,) -> 0
...

Sheet 资本性支出计划与执行
A1: 重庆宜新商业管理有限公司2026年资本性支出执行情况明细表
A2: 资产类别 | B2: 资产类型 | C2: 资产名称 | D2: 数量 | E2: 单价 | F2: 金额 | G2: 2026年预算 | H2: 2026年实际
A3: 固定资产 | B3: 家具用具 | H3: =F3 -> 0
H4: =F4 -> 0
H5: =F5 -> 0
H6: =F6 -> 0
H7: =F7 -> 0
H8: =F8 -> 0
H9: =F9 -> 0
H10: =F10 -> 0
H11: =F11 -> 0
H12: =F12 -> 0
A15: 资本性支出合计 | G15: =SUM(G3:G14) -> 0 | H15: =SUM(H3:H14) -> 0
A17: 需填列
